{"event_at":"2026-07-27T03:12:29.704000Z","event_fingerprint":"cd51bc38312f80c74cee463c8b0f11ee5ae9f54de966bcac5c6640165c417b71","payload":{"connection_id":"f95883f18d264834af91809e5f803e9f","event_at":"2026-07-27T03:12:29.704000Z","event_type":"price_change","frame_hash":"90e2d4d94ef74c299fbdf974a27bbfdb3ba8ffcfe0e86bb09f4ac6b270b49b58","frame_index":0,"kind":"data","monotonic_ns":223932940959291,"payload":{"event_type":"price_change","market":"0xf9d60bb033695053c4d1d8592e52171c1042f64b41a4b72e09dcc6f4852b6670","price_changes":[{"asset_id":"8698449539441374295770236407991735029336433231649246775082939325523552031992","best_ask":"0.61","best_bid":"0.6","hash":"ccd628bbd9d56e13389062a39dfd85f6be2c041c","price":"0.53","side":"BUY","size":"64.15"},{"asset_id":"96283536366176669581486355171583722558858323126916278856549586825357358273536","best_ask":"0.4","best_bid":"0.39","hash":"c1c609e571649969d0f64640ab70e7097d159353","price":"0.47","side":"SELL","size":"64.15"}],"timestamp":"1785121949704"},"payload_hash":"2233c0abbdb4099ca7b88d20ac8374a10fa663422c19c7d395d47cad8ff36510","raw_frame":"{\"market\":\"0xf9d60bb033695053c4d1d8592e52171c1042f64b41a4b72e09dcc6f4852b6670\", \"price_changes\":[{\"asset_id\":\"8698449539441374295770236407991735029336433231649246775082939325523552031992\", \"price\":\"0.53\", \"size\":\"64.15\", \"side\":\"BUY\", \"hash\":\"ccd628bbd9d56e13389062a39dfd85f6be2c041c\", \"best_bid\":\"0.6\", \"best_ask\":\"0.61\"}, {\"asset_id\":\"96283536366176669581486355171583722558858323126916278856549586825357358273536\", \"price\":\"0.47\", \"size\":\"64.15\", \"side\":\"SELL\", \"hash\":\"c1c609e571649969d0f64640ab70e7097d159353\", \"best_bid\":\"0.39\", \"best_ask\":\"0.4\"}], \"timestamp\":\"1785121949704\", \"event_type\":\"price_change\"}","received_at":"2026-07-27T03:12:29.609400Z","schema_version":"clob-market-ws.price_change.v1","sequence":null,"server_hash":null,"server_timestamp":"1785121949704","session_id":"ff6d21c8283948938400a32613abec2c","source":"clob_market_ws"},"received_at":"2026-07-27T03:12:29.609400Z","record_id":"e00bff76647bf40e784ed745a55a9a7b4ec0239707cf37698d18eac24f3dfc17","schema_fingerprint":"4aa3821a28b0b7c2400bc59aba4bcc0a76e971dadd19610d3ad38c768e124dc7","schema_version":"edge-lab-recorder.raw.v1","sequence":null,"source":"clob_market_ws"}
{"event_at":"2026-07-27T03:12:29.704000Z","event_fingerprint":"500da6f63fd9023cb03067fbf24aafe576c9cf3b634e8627eeaa1bf2ee91fa98","payload":{"connection_id":"f95883f18d264834af91809e5f803e9f","event_at":"2026-07-27T03:12:29.704000Z","event_type":"price_change","frame_hash":"584246a06b2cf931dd0d69dd802aefd16da04401de67e8c5e7c26b4b238d4d85","frame_index":0,"kind":"data","monotonic_ns":223932943193833,"payload":{"event_type":"price_change","market":"0xf9d60bb033695053c4d1d8592e52171c1042f64b41a4b72e09dcc6f4852b6670","price_changes":[{"asset_id":"8698449539441374295770236407991735029336433231649246775082939325523552031992","best_ask":"0.61","best_bid":"0.6","hash":"5cb80e0bd918a08d493a9c955928fcc84dcd1394","price":"0.51","side":"BUY","size":"61"},{"asset_id":"96283536366176669581486355171583722558858323126916278856549586825357358273536","best_ask":"0.4","best_bid":"0.39","hash":"ce4fe0de2a85b59aac1c7d6e8fa543e337b3cb02","price":"0.49","side":"SELL","size":"61"}],"timestamp":"1785121949704"},"payload_hash":"d1eab078271d9972dddfcdea085a5afa8e7677757fa6dc96f439776efd1ad88e","raw_frame":"{\"market\":\"0xf9d60bb033695053c4d1d8592e52171c1042f64b41a4b72e09dcc6f4852b6670\", \"price_changes\":[{\"asset_id\":\"8698449539441374295770236407991735029336433231649246775082939325523552031992\", \"price\":\"0.51\", \"size\":\"61\", \"side\":\"BUY\", \"hash\":\"5cb80e0bd918a08d493a9c955928fcc84dcd1394\", \"best_bid\":\"0.6\", \"best_ask\":\"0.61\"}, {\"asset_id\":\"96283536366176669581486355171583722558858323126916278856549586825357358273536\", \"price\":\"0.49\", \"size\":\"61\", \"side\":\"SELL\", \"hash\":\"ce4fe0de2a85b59aac1c7d6e8fa543e337b3cb02\", \"best_bid\":\"0.39\", \"best_ask\":\"0.4\"}], \"timestamp\":\"1785121949704\", \"event_type\":\"price_change\"}","received_at":"2026-07-27T03:12:29.611637Z","schema_version":"clob-market-ws.price_change.v1","sequence":null,"server_hash":null,"server_timestamp":"1785121949704","session_id":"ff6d21c8283948938400a32613abec2c","source":"clob_market_ws"},"received_at":"2026-07-27T03:12:29.611637Z","record_id":"56fe3f9507757dc5a0e510456ce0fa2112a89d0e4cbc5d39b37a3a23f2e4a08d","schema_fingerprint":"4aa3821a28b0b7c2400bc59aba4bcc0a76e971dadd19610d3ad38c768e124dc7","schema_version":"edge-lab-recorder.raw.v1","sequence":null,"source":"clob_market_ws"}
{"event_at":"2026-07-27T03:12:29.705000Z","event_fingerprint":"aa8d4fef0deeac5b2b6921d90326476e917e2e0779aacbaf5be8d6a0a33c89aa","payload":{"connection_id":"f95883f18d264834af91809e5f803e9f","event_at":"2026-07-27T03:12:29.705000Z","event_type":"price_change","frame_hash":"96716a31adf8deb42f92d63bfd6bff6d2e0e02d4bb78e0606da80dbac839b37c","frame_index":0,"kind":"data","monotonic_ns":223932944756208,"payload":{"event_type":"price_change","market":"0xf9d60bb033695053c4d1d8592e52171c1042f64b41a4b72e09dcc6f4852b6670","price_changes":[{"asset_id":"8698449539441374295770236407991735029336433231649246775082939325523552031992","best_ask":"0.61","best_bid":"0.6","hash":"a5db91cca7f8625c410325568f570e377812c19a","price":"0.54","side":"BUY","size":"95"},{"asset_id":"96283536366176669581486355171583722558858323126916278856549586825357358273536","best_ask":"0.4","best_bid":"0.39","hash":"a6f4cab7f092d8da312295953954553f6d98af69","price":"0.46","side":"SELL","size":"95"}],"timestamp":"1785121949705"},"payload_hash":"6a1fdf9fac1de5c76fd4c31c4f35150433c601c13832e34b68b871346e61f058","raw_frame":"{\"market\":\"0xf9d60bb033695053c4d1d8592e52171c1042f64b41a4b72e09dcc6f4852b6670\", \"price_changes\":[{\"asset_id\":\"8698449539441374295770236407991735029336433231649246775082939325523552031992\", \"price\":\"0.54\", \"size\":\"95\", \"side\":\"BUY\", \"hash\":\"a5db91cca7f8625c410325568f570e377812c19a\", \"best_bid\":\"0.6\", \"best_ask\":\"0.61\"}, {\"asset_id\":\"96283536366176669581486355171583722558858323126916278856549586825357358273536\", \"price\":\"0.46\", \"size\":\"95\", \"side\":\"SELL\", \"hash\":\"a6f4cab7f092d8da312295953954553f6d98af69\", \"best_bid\":\"0.39\", \"best_ask\":\"0.4\"}], \"timestamp\":\"1785121949705\", \"event_type\":\"price_change\"}","received_at":"2026-07-27T03:12:29.613200Z","schema_version":"clob-market-ws.price_change.v1","sequence":null,"server_hash":null,"server_timestamp":"1785121949705","session_id":"ff6d21c8283948938400a32613abec2c","source":"clob_market_ws"},"received_at":"2026-07-27T03:12:29.613200Z","record_id":"ef4cb8d885f1c4492a8170414ecb81c3e4fcdd5be5fbfeaead447f2a2fb4a4d3","schema_fingerprint":"4aa3821a28b0b7c2400bc59aba4bcc0a76e971dadd19610d3ad38c768e124dc7","schema_version":"edge-lab-recorder.raw.v1","sequence":null,"source":"clob_market_ws"}
{"event_at":"2026-07-27T03:12:29.706000Z","event_fingerprint":"d064d95ac6b9c5c74bc4699526676f7d78f39805c99b9325d4b2b9ec85e70de4","payload":{"connection_id":"f95883f18d264834af91809e5f803e9f","event_at":"2026-07-27T03:12:29.706000Z","event_type":"price_change","frame_hash":"252c8a4813a203b261bd5c04ce5048b9187e9b28947a286352a77ba43ed05b7b","frame_index":0,"kind":"data","monotonic_ns":223932946268916,"payload":{"event_type":"price_change","market":"0xf9d60bb033695053c4d1d8592e52171c1042f64b41a4b72e09dcc6f4852b6670","price_changes":[{"asset_id":"8698449539441374295770236407991735029336433231649246775082939325523552031992","best_ask":"0.61","best_bid":"0.6","hash":"2290d405b50cff1b177ac876344a67bdbcc981c1","price":"0.52","side":"BUY","size":"66"},{"asset_id":"96283536366176669581486355171583722558858323126916278856549586825357358273536","best_ask":"0.4","best_bid":"0.39","hash":"d0b0b17241dcb77b87b370fef30c34b6f7d33d42","price":"0.48","side":"SELL","size":"66"}],"timestamp":"1785121949706"},"payload_hash":"265b231f3c19227ea6df6bce7331c38b5ad3e97ad2b916e45794ec11f3cedafc","raw_frame":"{\"market\":\"0xf9d60bb033695053c4d1d8592e52171c1042f64b41a4b72e09dcc6f4852b6670\", \"price_changes\":[{\"asset_id\":\"8698449539441374295770236407991735029336433231649246775082939325523552031992\", \"price\":\"0.52\", \"size\":\"66\", \"side\":\"BUY\", \"hash\":\"2290d405b50cff1b177ac876344a67bdbcc981c1\", \"best_bid\":\"0.6\", \"best_ask\":\"0.61\"}, {\"asset_id\":\"96283536366176669581486355171583722558858323126916278856549586825357358273536\", \"price\":\"0.48\", \"size\":\"66\", \"side\":\"SELL\", \"hash\":\"d0b0b17241dcb77b87b370fef30c34b6f7d33d42\", \"best_bid\":\"0.39\", \"best_ask\":\"0.4\"}], \"timestamp\":\"1785121949706\", \"event_type\":\"price_change\"}","received_at":"2026-07-27T03:12:29.614713Z","schema_version":"clob-market-ws.price_change.v1","sequence":null,"server_hash":null,"server_timestamp":"1785121949706","session_id":"ff6d21c8283948938400a32613abec2c","source":"clob_market_ws"},"received_at":"2026-07-27T03:12:29.614713Z","record_id":"e9c2c3333d4d206913af1247a864bb2a2f3d5921d6edd8f10f6571b8a3bff1f9","schema_fingerprint":"4aa3821a28b0b7c2400bc59aba4bcc0a76e971dadd19610d3ad38c768e124dc7","schema_version":"edge-lab-recorder.raw.v1","sequence":null,"source":"clob_market_ws"}
{"event_at":"2026-07-27T03:12:29.724000Z","event_fingerprint":"b193540728629ec654b4403a7f5c20cdab8ac14b15172ada8785c7ba4930e89e","payload":{"connection_id":"f95883f18d264834af91809e5f803e9f","event_at":"2026-07-27T03:12:29.724000Z","event_type":"price_change","frame_hash":"88269d08779fcc3e94e40abeaf7977b99c6d70948a85d017f205a7a371756028","frame_index":0,"kind":"data","monotonic_ns":223932954454833,"payload":{"event_type":"price_change","market":"0xf9d60bb033695053c4d1d8592e52171c1042f64b41a4b72e09dcc6f4852b6670","price_changes":[{"asset_id":"8698449539441374295770236407991735029336433231649246775082939325523552031992","best_ask":"0.61","best_bid":"0.6","hash":"863911df901f3d031529b57afa5e531e6dd99ba9","price":"0.01","side":"BUY","size":"7937.52"},{"asset_id":"96283536366176669581486355171583722558858323126916278856549586825357358273536","best_ask":"0.4","best_bid":"0.39","hash":"29c3dca9eeb5c75f72bc90963741fb25a68faf82","price":"0.99","side":"SELL","size":"7937.52"}],"timestamp":"1785121949724"},"payload_hash":"ce0589a28aa8c06e9959fa6a8f654d2c7275705a20cc4718ef8f523c62c1aa2d","raw_frame":"{\"market\":\"0xf9d60bb033695053c4d1d8592e52171c1042f64b41a4b72e09dcc6f4852b6670\", \"price_changes\":[{\"asset_id\":\"8698449539441374295770236407991735029336433231649246775082939325523552031992\", \"price\":\"0.01\", \"size\":\"7937.52\", \"side\":\"BUY\", \"hash\":\"863911df901f3d031529b57afa5e531e6dd99ba9\", \"best_bid\":\"0.6\", \"best_ask\":\"0.61\"}, {\"asset_id\":\"96283536366176669581486355171583722558858323126916278856549586825357358273536\", \"price\":\"0.99\", \"size\":\"7937.52\", \"side\":\"SELL\", \"hash\":\"29c3dca9eeb5c75f72bc90963741fb25a68faf82\", \"best_bid\":\"0.39\", \"best_ask\":\"0.4\"}], \"timestamp\":\"1785121949724\", \"event_type\":\"price_change\"}","received_at":"2026-07-27T03:12:29.622893Z","schema_version":"clob-market-ws.price_change.v1","sequence":null,"server_hash":null,"server_timestamp":"1785121949724","session_id":"ff6d21c8283948938400a32613abec2c","source":"clob_market_ws"},"received_at":"2026-07-27T03:12:29.622893Z","record_id":"437712cf5fe98190cb1237ed687ffb911c4dc38cc02161ec3958abe3d684fa43","schema_fingerprint":"4aa3821a28b0b7c2400bc59aba4bcc0a76e971dadd19610d3ad38c768e124dc7","schema_version":"edge-lab-recorder.raw.v1","sequence":null,"source":"clob_market_ws"}
{"event_at":"2026-07-27T03:12:29.739000Z","event_fingerprint":"17e7c0a3db27c74b43280c46eea19c0a30527c294d534b5af079d47beab4263f","payload":{"connection_id":"f95883f18d264834af91809e5f803e9f","event_at":"2026-07-27T03:12:29.739000Z","event_type":"price_change","frame_hash":"d103c1d2832bdcf01efe30055ba2bf6ca3103b252a39a73e8969e4b8f3d9792f","frame_index":0,"kind":"data","monotonic_ns":223932970693916,"payload":{"event_type":"price_change","market":"0xf9d60bb033695053c4d1d8592e52171c1042f64b41a4b72e09dcc6f4852b6670","price_changes":[{"asset_id":"8698449539441374295770236407991735029336433231649246775082939325523552031992","best_ask":"0.61","best_bid":"0.6","hash":"9dea3345cc03006a1735ac6201490c1b45677f40","price":"0.27","side":"BUY","size":"65.89"},{"asset_id":"96283536366176669581486355171583722558858323126916278856549586825357358273536","best_ask":"0.4","best_bid":"0.39","hash":"5aae6dc6771ff66513f70b2ff2e74e481ab29c89","price":"0.73","side":"SELL","size":"65.89"}],"timestamp":"1785121949739"},"payload_hash":"89ebb005a2b38d68acad9879fe06d5df2c18f8b23e7ed88ead2eaa0e31859964","raw_frame":"{\"market\":\"0xf9d60bb033695053c4d1d8592e52171c1042f64b41a4b72e09dcc6f4852b6670\", \"price_changes\":[{\"asset_id\":\"8698449539441374295770236407991735029336433231649246775082939325523552031992\", \"price\":\"0.27\", \"size\":\"65.89\", \"side\":\"BUY\", \"hash\":\"9dea3345cc03006a1735ac6201490c1b45677f40\", \"best_bid\":\"0.6\", \"best_ask\":\"0.61\"}, {\"asset_id\":\"96283536366176669581486355171583722558858323126916278856549586825357358273536\", \"price\":\"0.73\", \"size\":\"65.89\", \"side\":\"SELL\", \"hash\":\"5aae6dc6771ff66513f70b2ff2e74e481ab29c89\", \"best_bid\":\"0.39\", \"best_ask\":\"0.4\"}], \"timestamp\":\"1785121949739\", \"event_type\":\"price_change\"}","received_at":"2026-07-27T03:12:29.639129Z","schema_version":"clob-market-ws.price_change.v1","sequence":null,"server_hash":null,"server_timestamp":"1785121949739","session_id":"ff6d21c8283948938400a32613abec2c","source":"clob_market_ws"},"received_at":"2026-07-27T03:12:29.639129Z","record_id":"76fa8a2ba0755f040ddee850c053c314b5cfcbf5b3bdf9dd6f4a7f1b22bca603","schema_fingerprint":"4aa3821a28b0b7c2400bc59aba4bcc0a76e971dadd19610d3ad38c768e124dc7","schema_version":"edge-lab-recorder.raw.v1","sequence":null,"source":"clob_market_ws"}
{"event_at":"2026-07-27T03:12:29.748000Z","event_fingerprint":"ea232051768e912a6c898eeeca3e3f13d7456bf53fc5f339f9eb31b814bae2bb","payload":{"connection_id":"f95883f18d264834af91809e5f803e9f","event_at":"2026-07-27T03:12:29.748000Z","event_type":"price_change","frame_hash":"5b8b96199ef2cb0ae7663b557347d56910ff9cd2346bc74d3601053ead83e85c","frame_index":0,"kind":"data","monotonic_ns":223932979124875,"payload":{"event_type":"price_change","market":"0xf9d60bb033695053c4d1d8592e52171c1042f64b41a4b72e09dcc6f4852b6670","price_changes":[{"asset_id":"8698449539441374295770236407991735029336433231649246775082939325523552031992","best_ask":"0.61","best_bid":"0.6","hash":"0cf117b60cad05e6ef1e1060d556b4c4f755de81","price":"0.04","side":"BUY","size":"1086.5"},{"asset_id":"96283536366176669581486355171583722558858323126916278856549586825357358273536","best_ask":"0.4","best_bid":"0.39","hash":"9f74c56aab182b440e0f8e6dd4c850d3af447a61","price":"0.96","side":"SELL","size":"1086.5"}],"timestamp":"1785121949748"},"payload_hash":"2099ccbcbc7c283587bdf8a323c7bf9a9795eb0044c8c435b6b9d28bd079db45","raw_frame":"{\"market\":\"0xf9d60bb033695053c4d1d8592e52171c1042f64b41a4b72e09dcc6f4852b6670\", \"price_changes\":[{\"asset_id\":\"8698449539441374295770236407991735029336433231649246775082939325523552031992\", \"price\":\"0.04\", \"size\":\"1086.5\", \"side\":\"BUY\", \"hash\":\"0cf117b60cad05e6ef1e1060d556b4c4f755de81\", \"best_bid\":\"0.6\", \"best_ask\":\"0.61\"}, {\"asset_id\":\"96283536366176669581486355171583722558858323126916278856549586825357358273536\", \"price\":\"0.96\", \"size\":\"1086.5\", \"side\":\"SELL\", \"hash\":\"9f74c56aab182b440e0f8e6dd4c850d3af447a61\", \"best_bid\":\"0.39\", \"best_ask\":\"0.4\"}], \"timestamp\":\"1785121949748\", \"event_type\":\"price_change\"}","received_at":"2026-07-27T03:12:29.647567Z","schema_version":"clob-market-ws.price_change.v1","sequence":null,"server_hash":null,"server_timestamp":"1785121949748","session_id":"ff6d21c8283948938400a32613abec2c","source":"clob_market_ws"},"received_at":"2026-07-27T03:12:29.647567Z","record_id":"cfff0c9f877d3e657cf446800c1fb04fc931d98cdef73391da28a990c272c62d","schema_fingerprint":"4aa3821a28b0b7c2400bc59aba4bcc0a76e971dadd19610d3ad38c768e124dc7","schema_version":"edge-lab-recorder.raw.v1","sequence":null,"source":"clob_market_ws"}
{"event_at":"2026-07-27T03:12:29.753000Z","event_fingerprint":"e1ecda16ea225f55915edf151de428842111f6a9cf652eef6a13179c00545b3e","payload":{"connection_id":"f95883f18d264834af91809e5f803e9f","event_at":"2026-07-27T03:12:29.753000Z","event_type":"price_change","frame_hash":"20e0b9d0c15efdd12c12455194b62ded41169cf050c0ef8390f4d2c6abeca083","frame_index":0,"kind":"data","monotonic_ns":223932985340500,"payload":{"event_type":"price_change","market":"0xf9d60bb033695053c4d1d8592e52171c1042f64b41a4b72e09dcc6f4852b6670","price_changes":[{"asset_id":"8698449539441374295770236407991735029336433231649246775082939325523552031992","best_ask":"0.61","best_bid":"0.6","hash":"a3b581ceb0724e9fa36f55593e850b8c1a645168","price":"0.27","side":"BUY","size":"59.3"},{"asset_id":"96283536366176669581486355171583722558858323126916278856549586825357358273536","best_ask":"0.4","best_bid":"0.39","hash":"ca9cae5ac2c86046ab9284b1e0d2a318120a4d1b","price":"0.73","side":"SELL","size":"59.3"}],"timestamp":"1785121949753"},"payload_hash":"6cf40af0ea71ea42866808b73bcb4911c4ef1f6962af84988ad041bbde0661e3","raw_frame":"{\"market\":\"0xf9d60bb033695053c4d1d8592e52171c1042f64b41a4b72e09dcc6f4852b6670\", \"price_changes\":[{\"asset_id\":\"8698449539441374295770236407991735029336433231649246775082939325523552031992\", \"price\":\"0.27\", \"size\":\"59.3\", \"side\":\"BUY\", \"hash\":\"a3b581ceb0724e9fa36f55593e850b8c1a645168\", \"best_bid\":\"0.6\", \"best_ask\":\"0.61\"}, {\"asset_id\":\"96283536366176669581486355171583722558858323126916278856549586825357358273536\", \"price\":\"0.73\", \"size\":\"59.3\", \"side\":\"SELL\", \"hash\":\"ca9cae5ac2c86046ab9284b1e0d2a318120a4d1b\", \"best_bid\":\"0.39\", \"best_ask\":\"0.4\"}], \"timestamp\":\"1785121949753\", \"event_type\":\"price_change\"}","received_at":"2026-07-27T03:12:29.653785Z","schema_version":"clob-market-ws.price_change.v1","sequence":null,"server_hash":null,"server_timestamp":"1785121949753","session_id":"ff6d21c8283948938400a32613abec2c","source":"clob_market_ws"},"received_at":"2026-07-27T03:12:29.653785Z","record_id":"9700e280f8e789738cfeae8866ea5586813e5cbf89f6c606228d3fdab52e40f5","schema_fingerprint":"4aa3821a28b0b7c2400bc59aba4bcc0a76e971dadd19610d3ad38c768e124dc7","schema_version":"edge-lab-recorder.raw.v1","sequence":null,"source":"clob_market_ws"}
{"event_at":"2026-07-27T03:12:29.780000Z","event_fingerprint":"73a4e22216b8604be602fe61f90deb404aa19d07c15ec3ae368f7c5accbce177","payload":{"connection_id":"f95883f18d264834af91809e5f803e9f","event_at":"2026-07-27T03:12:29.780000Z","event_type":"price_change","frame_hash":"3303e85675d869e66025ec21582651dd34718fd705c3f03660a298c4c39af708","frame_index":0,"kind":"data","monotonic_ns":223933011179375,"payload":{"event_type":"price_change","market":"0xf9d60bb033695053c4d1d8592e52171c1042f64b41a4b72e09dcc6f4852b6670","price_changes":[{"asset_id":"8698449539441374295770236407991735029336433231649246775082939325523552031992","best_ask":"0.61","best_bid":"0.6","hash":"6784da8f6257b94d55319561267614d7a8367051","price":"0.01","side":"BUY","size":"7942.52"},{"asset_id":"96283536366176669581486355171583722558858323126916278856549586825357358273536","best_ask":"0.4","best_bid":"0.39","hash":"6f2fc63a3e809a985868815ab4b2c1e88e369f9c","price":"0.99","side":"SELL","size":"7942.52"}],"timestamp":"1785121949780"},"payload_hash":"9304cc18248cb6cc2e3586843df4699e884c92d94ae130baa42dc5cf71552997","raw_frame":"{\"market\":\"0xf9d60bb033695053c4d1d8592e52171c1042f64b41a4b72e09dcc6f4852b6670\", \"price_changes\":[{\"asset_id\":\"8698449539441374295770236407991735029336433231649246775082939325523552031992\", \"price\":\"0.01\", \"size\":\"7942.52\", \"side\":\"BUY\", \"hash\":\"6784da8f6257b94d55319561267614d7a8367051\", \"best_bid\":\"0.6\", \"best_ask\":\"0.61\"}, {\"asset_id\":\"96283536366176669581486355171583722558858323126916278856549586825357358273536\", \"price\":\"0.99\", \"size\":\"7942.52\", \"side\":\"SELL\", \"hash\":\"6f2fc63a3e809a985868815ab4b2c1e88e369f9c\", \"best_bid\":\"0.39\", \"best_ask\":\"0.4\"}], \"timestamp\":\"1785121949780\", \"event_type\":\"price_change\"}","received_at":"2026-07-27T03:12:29.679616Z","schema_version":"clob-market-ws.price_change.v1","sequence":null,"server_hash":null,"server_timestamp":"1785121949780","session_id":"ff6d21c8283948938400a32613abec2c","source":"clob_market_ws"},"received_at":"2026-07-27T03:12:29.679616Z","record_id":"addc2bb5caf8934a2c2b0c5ee5978631491cb13081fb88622de2dbf5d4d115d5","schema_fingerprint":"4aa3821a28b0b7c2400bc59aba4bcc0a76e971dadd19610d3ad38c768e124dc7","schema_version":"edge-lab-recorder.raw.v1","sequence":null,"source":"clob_market_ws"}
{"event_at":"2026-07-27T03:12:29.805000Z","event_fingerprint":"c7f2af5afbf7d09c78167cbecbcd80739c6f98a2e56137db37e069ee3bd422fa","payload":{"connection_id":"f95883f18d264834af91809e5f803e9f","event_at":"2026-07-27T03:12:29.805000Z","event_type":"price_change","frame_hash":"8ecf0d7b99faf7bf1ce4c3f024b7ddd1491dc230e36dfeb6f83c2a4012418bd6","frame_index":0,"kind":"data","monotonic_ns":223933037472208,"payload":{"event_type":"price_change","market":"0xf9d60bb033695053c4d1d8592e52171c1042f64b41a4b72e09dcc6f4852b6670","price_changes":[{"asset_id":"8698449539441374295770236407991735029336433231649246775082939325523552031992","best_ask":"0.61","best_bid":"0.6","hash":"a5be26e9c5bd9d4c73454c3352172da121473ba7","price":"0.01","side":"BUY","size":"7937.52"},{"asset_id":"96283536366176669581486355171583722558858323126916278856549586825357358273536","best_ask":"0.4","best_bid":"0.39","hash":"3c2f8a90f1fff4149f138f1490cb1df425b051ec","price":"0.99","side":"SELL","size":"7937.52"}],"timestamp":"1785121949805"},"payload_hash":"8f181c4401947837d2e19aaa3cb6c6f79b70b13e714311581cc08c551c4ffb8b","raw_frame":"{\"market\":\"0xf9d60bb033695053c4d1d8592e52171c1042f64b41a4b72e09dcc6f4852b6670\", \"price_changes\":[{\"asset_id\":\"8698449539441374295770236407991735029336433231649246775082939325523552031992\", \"price\":\"0.01\", \"size\":\"7937.52\", \"side\":\"BUY\", \"hash\":\"a5be26e9c5bd9d4c73454c3352172da121473ba7\", \"best_bid\":\"0.6\", \"best_ask\":\"0.61\"}, {\"asset_id\":\"96283536366176669581486355171583722558858323126916278856549586825357358273536\", \"price\":\"0.99\", \"size\":\"7937.52\", \"side\":\"SELL\", \"hash\":\"3c2f8a90f1fff4149f138f1490cb1df425b051ec\", \"best_bid\":\"0.39\", \"best_ask\":\"0.4\"}], \"timestamp\":\"1785121949805\", \"event_type\":\"price_change\"}","received_at":"2026-07-27T03:12:29.705902Z","schema_version":"clob-market-ws.price_change.v1","sequence":null,"server_hash":null,"server_timestamp":"1785121949805","session_id":"ff6d21c8283948938400a32613abec2c","source":"clob_market_ws"},"received_at":"2026-07-27T03:12:29.705902Z","record_id":"df8840512d7c2ddca33d4a7b3ae58cc081460893e577c789209afee2e440c15f","schema_fingerprint":"4aa3821a28b0b7c2400bc59aba4bcc0a76e971dadd19610d3ad38c768e124dc7","schema_version":"edge-lab-recorder.raw.v1","sequence":null,"source":"clob_market_ws"}
{"event_at":"2026-07-27T03:12:29.807000Z","event_fingerprint":"e166fcbc507213c070a7b7e1e851fee9f65f597520546805dc1bb94b597c269b","payload":{"connection_id":"f95883f18d264834af91809e5f803e9f","event_at":"2026-07-27T03:12:29.807000Z","event_type":"price_change","frame_hash":"f592486c2ab5d68735fea7c730c8d6786bd5b35d2818ed0d59bfb52a81ab2f5b","frame_index":0,"kind":"data","monotonic_ns":223933039264750,"payload":{"event_type":"price_change","market":"0xf9d60bb033695053c4d1d8592e52171c1042f64b41a4b72e09dcc6f4852b6670","price_changes":[{"asset_id":"8698449539441374295770236407991735029336433231649246775082939325523552031992","best_ask":"0.61","best_bid":"0.6","hash":"98f247dbe765a1e8f5642b240fd9283fedfd07dd","price":"0.04","side":"BUY","size":"1081.5"},{"asset_id":"96283536366176669581486355171583722558858323126916278856549586825357358273536","best_ask":"0.4","best_bid":"0.39","hash":"2dc27a4d53d97c9f1a92e03b4871a75c1721c6f2","price":"0.96","side":"SELL","size":"1081.5"}],"timestamp":"1785121949807"},"payload_hash":"00e9a5b2ca4f963d5190db3726af14c0b132262498462b53a93ae5902a1a91f9","raw_frame":"{\"market\":\"0xf9d60bb033695053c4d1d8592e52171c1042f64b41a4b72e09dcc6f4852b6670\", \"price_changes\":[{\"asset_id\":\"8698449539441374295770236407991735029336433231649246775082939325523552031992\", \"price\":\"0.04\", \"size\":\"1081.5\", \"side\":\"BUY\", \"hash\":\"98f247dbe765a1e8f5642b240fd9283fedfd07dd\", \"best_bid\":\"0.6\", \"best_ask\":\"0.61\"}, {\"asset_id\":\"96283536366176669581486355171583722558858323126916278856549586825357358273536\", \"price\":\"0.96\", \"size\":\"1081.5\", \"side\":\"SELL\", \"hash\":\"2dc27a4d53d97c9f1a92e03b4871a75c1721c6f2\", \"best_bid\":\"0.39\", \"best_ask\":\"0.4\"}], \"timestamp\":\"1785121949807\", \"event_type\":\"price_change\"}","received_at":"2026-07-27T03:12:29.707710Z","schema_version":"clob-market-ws.price_change.v1","sequence":null,"server_hash":null,"server_timestamp":"1785121949807","session_id":"ff6d21c8283948938400a32613abec2c","source":"clob_market_ws"},"received_at":"2026-07-27T03:12:29.707710Z","record_id":"5a4ec3e980e495330a26354473376de00a6e467fa3019de24995b4f2d5578311","schema_fingerprint":"4aa3821a28b0b7c2400bc59aba4bcc0a76e971dadd19610d3ad38c768e124dc7","schema_version":"edge-lab-recorder.raw.v1","sequence":null,"source":"clob_market_ws"}
{"event_at":"2026-07-27T03:12:29.843000Z","event_fingerprint":"65d0fc43ff7d7950925d3dda24e426bab30641ff1a63d39d429171fd50f35a34","payload":{"connection_id":"f95883f18d264834af91809e5f803e9f","event_at":"2026-07-27T03:12:29.843000Z","event_type":"price_change","frame_hash":"0f3cde560418a7ffc8d4e8cc02451d6419f1aea3cd7ea4228932dd854420a2f5","frame_index":0,"kind":"data","monotonic_ns":223933076137791,"payload":{"event_type":"price_change","market":"0xf9d60bb033695053c4d1d8592e52171c1042f64b41a4b72e09dcc6f4852b6670","price_changes":[{"asset_id":"96283536366176669581486355171583722558858323126916278856549586825357358273536","best_ask":"0.4","best_bid":"0.39","hash":"100cea8a2cb9f45263e15d5f5250684d2db34d72","price":"0.25","side":"BUY","size":"69.93"},{"asset_id":"8698449539441374295770236407991735029336433231649246775082939325523552031992","best_ask":"0.61","best_bid":"0.6","hash":"69fcb924ab21e68b5fb38ff9a412d862083bd007","price":"0.75","side":"SELL","size":"69.93"}],"timestamp":"1785121949843"},"payload_hash":"1fe9a4acf4fb1b5ccb8cd8a89bccb7f0eb896e11e21f05531da2f5a473e771d4","raw_frame":"{\"market\":\"0xf9d60bb033695053c4d1d8592e52171c1042f64b41a4b72e09dcc6f4852b6670\", \"price_changes\":[{\"asset_id\":\"96283536366176669581486355171583722558858323126916278856549586825357358273536\", \"price\":\"0.25\", \"size\":\"69.93\", \"side\":\"BUY\", \"hash\":\"100cea8a2cb9f45263e15d5f5250684d2db34d72\", \"best_bid\":\"0.39\", \"best_ask\":\"0.4\"}, {\"asset_id\":\"8698449539441374295770236407991735029336433231649246775082939325523552031992\", \"price\":\"0.75\", \"size\":\"69.93\", \"side\":\"SELL\", \"hash\":\"69fcb924ab21e68b5fb38ff9a412d862083bd007\", \"best_bid\":\"0.6\", \"best_ask\":\"0.61\"}], \"timestamp\":\"1785121949843\", \"event_type\":\"price_change\"}","received_at":"2026-07-27T03:12:29.744568Z","schema_version":"clob-market-ws.price_change.v1","sequence":null,"server_hash":null,"server_timestamp":"1785121949843","session_id":"ff6d21c8283948938400a32613abec2c","source":"clob_market_ws"},"received_at":"2026-07-27T03:12:29.744568Z","record_id":"ccdcfdaa1f9a8493bc595dbc15cc813891268f17309250a66815009522264ace","schema_fingerprint":"4aa3821a28b0b7c2400bc59aba4bcc0a76e971dadd19610d3ad38c768e124dc7","schema_version":"edge-lab-recorder.raw.v1","sequence":null,"source":"clob_market_ws"}
{"event_at":"2026-07-27T03:12:29.860000Z","event_fingerprint":"4f28ffa0a815295533fd2f673a23add64388c4abe89532739248446b35dee568","payload":{"connection_id":"f95883f18d264834af91809e5f803e9f","event_at":"2026-07-27T03:12:29.860000Z","event_type":"price_change","frame_hash":"4970348c89651a13fd2bda047bac22e989849f9e323e4399b4dc02b7ee5b01d7","frame_index":0,"kind":"data","monotonic_ns":223933091088458,"payload":{"event_type":"price_change","market":"0xf9d60bb033695053c4d1d8592e52171c1042f64b41a4b72e09dcc6f4852b6670","price_changes":[{"asset_id":"96283536366176669581486355171583722558858323126916278856549586825357358273536","best_ask":"0.4","best_bid":"0.39","hash":"c1d925c0ea1e5c284e6acf600ef3b282bff212eb","price":"0.26","side":"BUY","size":"165.6"},{"asset_id":"8698449539441374295770236407991735029336433231649246775082939325523552031992","best_ask":"0.61","best_bid":"0.6","hash":"e44d793065c53f76babaf049933f87eda20a70a1","price":"0.74","side":"SELL","size":"165.6"}],"timestamp":"1785121949860"},"payload_hash":"7790330350ab914c990aeacbb621df2ce61a0272fde58205d1bcf42238fdaf4a","raw_frame":"{\"market\":\"0xf9d60bb033695053c4d1d8592e52171c1042f64b41a4b72e09dcc6f4852b6670\", \"price_changes\":[{\"asset_id\":\"96283536366176669581486355171583722558858323126916278856549586825357358273536\", \"price\":\"0.26\", \"size\":\"165.6\", \"side\":\"BUY\", \"hash\":\"c1d925c0ea1e5c284e6acf600ef3b282bff212eb\", \"best_bid\":\"0.39\", \"best_ask\":\"0.4\"}, {\"asset_id\":\"8698449539441374295770236407991735029336433231649246775082939325523552031992\", \"price\":\"0.74\", \"size\":\"165.6\", \"side\":\"SELL\", \"hash\":\"e44d793065c53f76babaf049933f87eda20a70a1\", \"best_bid\":\"0.6\", \"best_ask\":\"0.61\"}], \"timestamp\":\"1785121949860\", \"event_type\":\"price_change\"}","received_at":"2026-07-27T03:12:29.759525Z","schema_version":"clob-market-ws.price_change.v1","sequence":null,"server_hash":null,"server_timestamp":"1785121949860","session_id":"ff6d21c8283948938400a32613abec2c","source":"clob_market_ws"},"received_at":"2026-07-27T03:12:29.759525Z","record_id":"75bd24427c0ec9575ba1c737bfe8ae1759bde2ad98cdf3c9150f5a802bc73474","schema_fingerprint":"4aa3821a28b0b7c2400bc59aba4bcc0a76e971dadd19610d3ad38c768e124dc7","schema_version":"edge-lab-recorder.raw.v1","sequence":null,"source":"clob_market_ws"}
{"event_at":"2026-07-27T03:12:29.868000Z","event_fingerprint":"0d95c0a635ab599db5b17f9a0e3114d9a463360e2818f03f8ad62becae23ec6f","payload":{"connection_id":"f95883f18d264834af91809e5f803e9f","event_at":"2026-07-27T03:12:29.868000Z","event_type":"price_change","frame_hash":"17fffbe8dc4497d9662494bbb10149f6ef9bd83d9cdf8652e6b83baefec68ae8","frame_index":0,"kind":"data","monotonic_ns":223933100396750,"payload":{"event_type":"price_change","market":"0xf9d60bb033695053c4d1d8592e52171c1042f64b41a4b72e09dcc6f4852b6670","price_changes":[{"asset_id":"8698449539441374295770236407991735029336433231649246775082939325523552031992","best_ask":"0.61","best_bid":"0.6","hash":"dbc6abd3200653fd2c0b98f079c39b37d496d3ba","price":"0.45","side":"BUY","size":"133.5"},{"asset_id":"96283536366176669581486355171583722558858323126916278856549586825357358273536","best_ask":"0.4","best_bid":"0.39","hash":"51fbaf06b4fc7b48b2f26986923e4cb97443214e","price":"0.55","side":"SELL","size":"133.5"}],"timestamp":"1785121949868"},"payload_hash":"c5698b156e8cdfe7a5662989b298ac26f0eb4fbc4279d5b9ccf4a64ac3f52093","raw_frame":"{\"market\":\"0xf9d60bb033695053c4d1d8592e52171c1042f64b41a4b72e09dcc6f4852b6670\", \"price_changes\":[{\"asset_id\":\"8698449539441374295770236407991735029336433231649246775082939325523552031992\", \"price\":\"0.45\", \"size\":\"133.5\", \"side\":\"BUY\", \"hash\":\"dbc6abd3200653fd2c0b98f079c39b37d496d3ba\", \"best_bid\":\"0.6\", \"best_ask\":\"0.61\"}, {\"asset_id\":\"96283536366176669581486355171583722558858323126916278856549586825357358273536\", \"price\":\"0.55\", \"size\":\"133.5\", \"side\":\"SELL\", \"hash\":\"51fbaf06b4fc7b48b2f26986923e4cb97443214e\", \"best_bid\":\"0.39\", \"best_ask\":\"0.4\"}], \"timestamp\":\"1785121949868\", \"event_type\":\"price_change\"}","received_at":"2026-07-27T03:12:29.768835Z","schema_version":"clob-market-ws.price_change.v1","sequence":null,"server_hash":null,"server_timestamp":"1785121949868","session_id":"ff6d21c8283948938400a32613abec2c","source":"clob_market_ws"},"received_at":"2026-07-27T03:12:29.768835Z","record_id":"74ff49ca452e6dedf14959dd972d4901f7ba996c3d272244d782befa8c3b003a","schema_fingerprint":"4aa3821a28b0b7c2400bc59aba4bcc0a76e971dadd19610d3ad38c768e124dc7","schema_version":"edge-lab-recorder.raw.v1","sequence":null,"source":"clob_market_ws"}
{"event_at":"2026-07-27T03:12:29.885000Z","event_fingerprint":"40cbf6f7ed9bf0a0ebc8c85d55e3a8e586ec1e16d76a29b4d6a1a182a94f8c69","payload":{"connection_id":"f95883f18d264834af91809e5f803e9f","event_at":"2026-07-27T03:12:29.885000Z","event_type":"price_change","frame_hash":"86d4255ab0a6bcaeea67391af325c84678eca438a170c65f673fd59dc09449af","frame_index":0,"kind":"data","monotonic_ns":223933119776291,"payload":{"event_type":"price_change","market":"0xf9d60bb033695053c4d1d8592e52171c1042f64b41a4b72e09dcc6f4852b6670","price_changes":[{"asset_id":"96283536366176669581486355171583722558858323126916278856549586825357358273536","best_ask":"0.4","best_bid":"0.39","hash":"2521a0b5f5c52ee7be703af48708c80dcd41942f","price":"0.34","side":"BUY","size":"63.39"},{"asset_id":"8698449539441374295770236407991735029336433231649246775082939325523552031992","best_ask":"0.61","best_bid":"0.6","hash":"304b7b84806088fdeeccfc61ff55b3b81f9f6368","price":"0.66","side":"SELL","size":"63.39"}],"timestamp":"1785121949885"},"payload_hash":"2c20fe1e0b49b43413bc175d0e90ea01bdd38fe203e20ce4bd4f838e31a43a14","raw_frame":"{\"market\":\"0xf9d60bb033695053c4d1d8592e52171c1042f64b41a4b72e09dcc6f4852b6670\", \"price_changes\":[{\"asset_id\":\"96283536366176669581486355171583722558858323126916278856549586825357358273536\", \"price\":\"0.34\", \"size\":\"63.39\", \"side\":\"BUY\", \"hash\":\"2521a0b5f5c52ee7be703af48708c80dcd41942f\", \"best_bid\":\"0.39\", \"best_ask\":\"0.4\"}, {\"asset_id\":\"8698449539441374295770236407991735029336433231649246775082939325523552031992\", \"price\":\"0.66\", \"size\":\"63.39\", \"side\":\"SELL\", \"hash\":\"304b7b84806088fdeeccfc61ff55b3b81f9f6368\", \"best_bid\":\"0.6\", \"best_ask\":\"0.61\"}], \"timestamp\":\"1785121949885\", \"event_type\":\"price_change\"}","received_at":"2026-07-27T03:12:29.788214Z","schema_version":"clob-market-ws.price_change.v1","sequence":null,"server_hash":null,"server_timestamp":"1785121949885","session_id":"ff6d21c8283948938400a32613abec2c","source":"clob_market_ws"},"received_at":"2026-07-27T03:12:29.788214Z","record_id":"d4e16a2f1ab0e5f99161c1f8c13497e51127588a04fbf6b04e76e8f78b660ebe","schema_fingerprint":"4aa3821a28b0b7c2400bc59aba4bcc0a76e971dadd19610d3ad38c768e124dc7","schema_version":"edge-lab-recorder.raw.v1","sequence":null,"source":"clob_market_ws"}
{"event_at":"2026-07-27T03:12:29.886000Z","event_fingerprint":"c86e114675b2420dc7543e95c526fd5334fee300caf985faae3e94b817f137ea","payload":{"connection_id":"f95883f18d264834af91809e5f803e9f","event_at":"2026-07-27T03:12:29.886000Z","event_type":"price_change","frame_hash":"ae5976592e6e4eaf7aaf83ce0d6c73e4c190eb982e0f5218bd4cbd6945281613","frame_index":0,"kind":"data","monotonic_ns":223933121472250,"payload":{"event_type":"price_change","market":"0xf9d60bb033695053c4d1d8592e52171c1042f64b41a4b72e09dcc6f4852b6670","price_changes":[{"asset_id":"8698449539441374295770236407991735029336433231649246775082939325523552031992","best_ask":"0.61","best_bid":"0.6","hash":"b385d994a7e3031395807d0ad15683eeff77c0d0","price":"0.02","side":"BUY","size":"1350.79"},{"asset_id":"96283536366176669581486355171583722558858323126916278856549586825357358273536","best_ask":"0.4","best_bid":"0.39","hash":"e1efa8d6077349f1f8597fa750ceef2d936a91ff","price":"0.98","side":"SELL","size":"1350.79"}],"timestamp":"1785121949886"},"payload_hash":"09dcb03d567d487cfd45bd87b6e6ff31f1a0f59c44e7cc360de27ae25e6de49a","raw_frame":"{\"market\":\"0xf9d60bb033695053c4d1d8592e52171c1042f64b41a4b72e09dcc6f4852b6670\", \"price_changes\":[{\"asset_id\":\"8698449539441374295770236407991735029336433231649246775082939325523552031992\", \"price\":\"0.02\", \"size\":\"1350.79\", \"side\":\"BUY\", \"hash\":\"b385d994a7e3031395807d0ad15683eeff77c0d0\", \"best_bid\":\"0.6\", \"best_ask\":\"0.61\"}, {\"asset_id\":\"96283536366176669581486355171583722558858323126916278856549586825357358273536\", \"price\":\"0.98\", \"size\":\"1350.79\", \"side\":\"SELL\", \"hash\":\"e1efa8d6077349f1f8597fa750ceef2d936a91ff\", \"best_bid\":\"0.39\", \"best_ask\":\"0.4\"}], \"timestamp\":\"1785121949886\", \"event_type\":\"price_change\"}","received_at":"2026-07-27T03:12:29.789909Z","schema_version":"clob-market-ws.price_change.v1","sequence":null,"server_hash":null,"server_timestamp":"1785121949886","session_id":"ff6d21c8283948938400a32613abec2c","source":"clob_market_ws"},"received_at":"2026-07-27T03:12:29.789909Z","record_id":"0e1558f8de69ff28344debe10b73131858d454e7d95a0abbe451cee9987f89d7","schema_fingerprint":"4aa3821a28b0b7c2400bc59aba4bcc0a76e971dadd19610d3ad38c768e124dc7","schema_version":"edge-lab-recorder.raw.v1","sequence":null,"source":"clob_market_ws"}
{"event_at":"2026-07-27T03:12:29.887000Z","event_fingerprint":"9df85965dc9a1b2987e6b879cf142804fd8278ee5862474ce25fb43595f1599f","payload":{"connection_id":"f95883f18d264834af91809e5f803e9f","event_at":"2026-07-27T03:12:29.887000Z","event_type":"price_change","frame_hash":"4c7c49d17ac8534b2dc9d3cf0087f25c6ee42786753fe126a175c37ff53333cc","frame_index":0,"kind":"data","monotonic_ns":223933123100750,"payload":{"event_type":"price_change","market":"0xf9d60bb033695053c4d1d8592e52171c1042f64b41a4b72e09dcc6f4852b6670","price_changes":[{"asset_id":"8698449539441374295770236407991735029336433231649246775082939325523552031992","best_ask":"0.61","best_bid":"0.6","hash":"8b1c3a3b7563e2d7587000cf07020a9a500338bc","price":"0.51","side":"BUY","size":"86"},{"asset_id":"96283536366176669581486355171583722558858323126916278856549586825357358273536","best_ask":"0.4","best_bid":"0.39","hash":"7c0d425cf99f334a32d48afb0339f19290a44d80","price":"0.49","side":"SELL","size":"86"}],"timestamp":"1785121949887"},"payload_hash":"686231dc6d783c69c66df7b9825981a9c48990f5aa0d28ac12e292f5f253a8e8","raw_frame":"{\"market\":\"0xf9d60bb033695053c4d1d8592e52171c1042f64b41a4b72e09dcc6f4852b6670\", \"price_changes\":[{\"asset_id\":\"8698449539441374295770236407991735029336433231649246775082939325523552031992\", \"price\":\"0.51\", \"size\":\"86\", \"side\":\"BUY\", \"hash\":\"8b1c3a3b7563e2d7587000cf07020a9a500338bc\", \"best_bid\":\"0.6\", \"best_ask\":\"0.61\"}, {\"asset_id\":\"96283536366176669581486355171583722558858323126916278856549586825357358273536\", \"price\":\"0.49\", \"size\":\"86\", \"side\":\"SELL\", \"hash\":\"7c0d425cf99f334a32d48afb0339f19290a44d80\", \"best_bid\":\"0.39\", \"best_ask\":\"0.4\"}], \"timestamp\":\"1785121949887\", \"event_type\":\"price_change\"}","received_at":"2026-07-27T03:12:29.791540Z","schema_version":"clob-market-ws.price_change.v1","sequence":null,"server_hash":null,"server_timestamp":"1785121949887","session_id":"ff6d21c8283948938400a32613abec2c","source":"clob_market_ws"},"received_at":"2026-07-27T03:12:29.791540Z","record_id":"56800326904f4da6569fc72edfb8e7585ebfc9ba24ffaca38f61594b453563ae","schema_fingerprint":"4aa3821a28b0b7c2400bc59aba4bcc0a76e971dadd19610d3ad38c768e124dc7","schema_version":"edge-lab-recorder.raw.v1","sequence":null,"source":"clob_market_ws"}
{"event_at":"2026-07-27T03:12:29.887000Z","event_fingerprint":"bd7b601ebba8f0bb67f3862582c460fb22383bbf2a9f48395daeb25d35509732","payload":{"connection_id":"f95883f18d264834af91809e5f803e9f","event_at":"2026-07-27T03:12:29.887000Z","event_type":"price_change","frame_hash":"2c60ba0535efe02d892a1bf9bdca66bc41081594b6b96a44f757cc2895ff56f0","frame_index":0,"kind":"data","monotonic_ns":223933124782291,"payload":{"event_type":"price_change","market":"0xf9d60bb033695053c4d1d8592e52171c1042f64b41a4b72e09dcc6f4852b6670","price_changes":[{"asset_id":"96283536366176669581486355171583722558858323126916278856549586825357358273536","best_ask":"0.4","best_bid":"0.39","hash":"0e198d5cb29b8d22688ff0dcba8d7fdf392a3b1f","price":"0.35","side":"BUY","size":"56.1"},{"asset_id":"8698449539441374295770236407991735029336433231649246775082939325523552031992","best_ask":"0.61","best_bid":"0.6","hash":"eeb87dbd7f0d530d35c5af5dcc0cab957d0ebfdb","price":"0.65","side":"SELL","size":"56.1"}],"timestamp":"1785121949887"},"payload_hash":"ab1469e43aa1e76656591f2eea7dff28fad7fb9b45d1cb6721c6a7eeb30ef225","raw_frame":"{\"market\":\"0xf9d60bb033695053c4d1d8592e52171c1042f64b41a4b72e09dcc6f4852b6670\", \"price_changes\":[{\"asset_id\":\"96283536366176669581486355171583722558858323126916278856549586825357358273536\", \"price\":\"0.35\", \"size\":\"56.1\", \"side\":\"BUY\", \"hash\":\"0e198d5cb29b8d22688ff0dcba8d7fdf392a3b1f\", \"best_bid\":\"0.39\", \"best_ask\":\"0.4\"}, {\"asset_id\":\"8698449539441374295770236407991735029336433231649246775082939325523552031992\", \"price\":\"0.65\", \"size\":\"56.1\", \"side\":\"SELL\", \"hash\":\"eeb87dbd7f0d530d35c5af5dcc0cab957d0ebfdb\", \"best_bid\":\"0.6\", \"best_ask\":\"0.61\"}], \"timestamp\":\"1785121949887\", \"event_type\":\"price_change\"}","received_at":"2026-07-27T03:12:29.793220Z","schema_version":"clob-market-ws.price_change.v1","sequence":null,"server_hash":null,"server_timestamp":"1785121949887","session_id":"ff6d21c8283948938400a32613abec2c","source":"clob_market_ws"},"received_at":"2026-07-27T03:12:29.793220Z","record_id":"2d8b84084fdceee40e4fc3ffb676dca83f77d26c4185998e1f5152e22e066ba0","schema_fingerprint":"4aa3821a28b0b7c2400bc59aba4bcc0a76e971dadd19610d3ad38c768e124dc7","schema_version":"edge-lab-recorder.raw.v1","sequence":null,"source":"clob_market_ws"}
{"event_at":"2026-07-27T03:12:29.888000Z","event_fingerprint":"7c33ffb18813c10e447e89e5cf21af68226c837df0db241d02187e5efab2ea7a","payload":{"connection_id":"f95883f18d264834af91809e5f803e9f","event_at":"2026-07-27T03:12:29.888000Z","event_type":"price_change","frame_hash":"e8020f7fc107530d039d63e22bee005329f870e9133179fef30055ae77be0c1f","frame_index":0,"kind":"data","monotonic_ns":223933126365416,"payload":{"event_type":"price_change","market":"0xf9d60bb033695053c4d1d8592e52171c1042f64b41a4b72e09dcc6f4852b6670","price_changes":[{"asset_id":"8698449539441374295770236407991735029336433231649246775082939325523552031992","best_ask":"0.61","best_bid":"0.6","hash":"2b881fcbb24a9f300391c4924fa233f3e39e57a2","price":"0.51","side":"BUY","size":"111"},{"asset_id":"96283536366176669581486355171583722558858323126916278856549586825357358273536","best_ask":"0.4","best_bid":"0.39","hash":"16f2fb1f11479ebbbdbfc5677a0a9662a5f92d70","price":"0.49","side":"SELL","size":"111"}],"timestamp":"1785121949888"},"payload_hash":"845d1567f3d862ff2bf2789e32a98f245efa338437bed52e0d4070c81658a8d2","raw_frame":"{\"market\":\"0xf9d60bb033695053c4d1d8592e52171c1042f64b41a4b72e09dcc6f4852b6670\", \"price_changes\":[{\"asset_id\":\"8698449539441374295770236407991735029336433231649246775082939325523552031992\", \"price\":\"0.51\", \"size\":\"111\", \"side\":\"BUY\", \"hash\":\"2b881fcbb24a9f300391c4924fa233f3e39e57a2\", \"best_bid\":\"0.6\", \"best_ask\":\"0.61\"}, {\"asset_id\":\"96283536366176669581486355171583722558858323126916278856549586825357358273536\", \"price\":\"0.49\", \"size\":\"111\", \"side\":\"SELL\", \"hash\":\"16f2fb1f11479ebbbdbfc5677a0a9662a5f92d70\", \"best_bid\":\"0.39\", \"best_ask\":\"0.4\"}], \"timestamp\":\"1785121949888\", \"event_type\":\"price_change\"}","received_at":"2026-07-27T03:12:29.794805Z","schema_version":"clob-market-ws.price_change.v1","sequence":null,"server_hash":null,"server_timestamp":"1785121949888","session_id":"ff6d21c8283948938400a32613abec2c","source":"clob_market_ws"},"received_at":"2026-07-27T03:12:29.794805Z","record_id":"340fa48ab520fa2b65e4783e20c31a0ddd77be3e81a26e5f804811c0a3293c3f","schema_fingerprint":"4aa3821a28b0b7c2400bc59aba4bcc0a76e971dadd19610d3ad38c768e124dc7","schema_version":"edge-lab-recorder.raw.v1","sequence":null,"source":"clob_market_ws"}
{"event_at":"2026-07-27T03:12:29.892000Z","event_fingerprint":"dafa9e779ad1fb37cb87689bcf00112d9228f1153039c13ab798cd22531ef0cf","payload":{"connection_id":"f95883f18d264834af91809e5f803e9f","event_at":"2026-07-27T03:12:29.892000Z","event_type":"price_change","frame_hash":"95cf73e7a5d8c9c9b0bc3f66ae6f85b8ea61cb1805f9d33dde8c28a4adf7f697","frame_index":0,"kind":"data","monotonic_ns":223933127900083,"payload":{"event_type":"price_change","market":"0xf9d60bb033695053c4d1d8592e52171c1042f64b41a4b72e09dcc6f4852b6670","price_changes":[{"asset_id":"96283536366176669581486355171583722558858323126916278856549586825357358273536","best_ask":"0.4","best_bid":"0.39","hash":"79d619d5f34dfa451c918b4431f160fae3909d5e","price":"0.36","side":"BUY","size":"60.89"},{"asset_id":"8698449539441374295770236407991735029336433231649246775082939325523552031992","best_ask":"0.61","best_bid":"0.6","hash":"1976f507c03256209c71f5e0284a940de7aea8ef","price":"0.64","side":"SELL","size":"60.89"}],"timestamp":"1785121949892"},"payload_hash":"7c4f81699022d867d7ee8cc66e9648087864fd658c5b56b57c9428828f5e2dc8","raw_frame":"{\"market\":\"0xf9d60bb033695053c4d1d8592e52171c1042f64b41a4b72e09dcc6f4852b6670\", \"price_changes\":[{\"asset_id\":\"96283536366176669581486355171583722558858323126916278856549586825357358273536\", \"price\":\"0.36\", \"size\":\"60.89\", \"side\":\"BUY\", \"hash\":\"79d619d5f34dfa451c918b4431f160fae3909d5e\", \"best_bid\":\"0.39\", \"best_ask\":\"0.4\"}, {\"asset_id\":\"8698449539441374295770236407991735029336433231649246775082939325523552031992\", \"price\":\"0.64\", \"size\":\"60.89\", \"side\":\"SELL\", \"hash\":\"1976f507c03256209c71f5e0284a940de7aea8ef\", \"best_bid\":\"0.6\", \"best_ask\":\"0.61\"}], \"timestamp\":\"1785121949892\", \"event_type\":\"price_change\"}","received_at":"2026-07-27T03:12:29.796340Z","schema_version":"clob-market-ws.price_change.v1","sequence":null,"server_hash":null,"server_timestamp":"1785121949892","session_id":"ff6d21c8283948938400a32613abec2c","source":"clob_market_ws"},"received_at":"2026-07-27T03:12:29.796340Z","record_id":"d9f6b3d462ff0007969e58cee962c6135c33ffd16c98a780221688efd0db5f2e","schema_fingerprint":"4aa3821a28b0b7c2400bc59aba4bcc0a76e971dadd19610d3ad38c768e124dc7","schema_version":"edge-lab-recorder.raw.v1","sequence":null,"source":"clob_market_ws"}
{"event_at":"2026-07-27T03:12:29.903000Z","event_fingerprint":"711cfc20b62d142eb49f8265564c604984da0a3d56eb84a8ade59ee4cf5eec1a","payload":{"connection_id":"f95883f18d264834af91809e5f803e9f","event_at":"2026-07-27T03:12:29.903000Z","event_type":"price_change","frame_hash":"bd3d30d364135db9069d24ff19ba586e99c4022ab3885031e6909af454c141fb","frame_index":0,"kind":"data","monotonic_ns":223933134521458,"payload":{"event_type":"price_change","market":"0xf9d60bb033695053c4d1d8592e52171c1042f64b41a4b72e09dcc6f4852b6670","price_changes":[{"asset_id":"8698449539441374295770236407991735029336433231649246775082939325523552031992","best_ask":"0.61","best_bid":"0.6","hash":"6d20c68fe9e218bbb1fd3e6f66d628f2b0a63a2c","price":"0.01","side":"BUY","size":"7932.52"},{"asset_id":"96283536366176669581486355171583722558858323126916278856549586825357358273536","best_ask":"0.4","best_bid":"0.39","hash":"8f05c3fd63ebc1cc0b8d753b6110d5ca982bb2f3","price":"0.99","side":"SELL","size":"7932.52"}],"timestamp":"1785121949903"},"payload_hash":"e6861c9e90a741fb79109a38c71368582aab2cf27e98baf9aca61b907406da53","raw_frame":"{\"market\":\"0xf9d60bb033695053c4d1d8592e52171c1042f64b41a4b72e09dcc6f4852b6670\", \"price_changes\":[{\"asset_id\":\"8698449539441374295770236407991735029336433231649246775082939325523552031992\", \"price\":\"0.01\", \"size\":\"7932.52\", \"side\":\"BUY\", \"hash\":\"6d20c68fe9e218bbb1fd3e6f66d628f2b0a63a2c\", \"best_bid\":\"0.6\", \"best_ask\":\"0.61\"}, {\"asset_id\":\"96283536366176669581486355171583722558858323126916278856549586825357358273536\", \"price\":\"0.99\", \"size\":\"7932.52\", \"side\":\"SELL\", \"hash\":\"8f05c3fd63ebc1cc0b8d753b6110d5ca982bb2f3\", \"best_bid\":\"0.39\", \"best_ask\":\"0.4\"}], \"timestamp\":\"1785121949903\", \"event_type\":\"price_change\"}","received_at":"2026-07-27T03:12:29.802959Z","schema_version":"clob-market-ws.price_change.v1","sequence":null,"server_hash":null,"server_timestamp":"1785121949903","session_id":"ff6d21c8283948938400a32613abec2c","source":"clob_market_ws"},"received_at":"2026-07-27T03:12:29.802959Z","record_id":"785f6143a9fa55db45da2bf6ab806e2020eaf4ed562dff58562480b13149685b","schema_fingerprint":"4aa3821a28b0b7c2400bc59aba4bcc0a76e971dadd19610d3ad38c768e124dc7","schema_version":"edge-lab-recorder.raw.v1","sequence":null,"source":"clob_market_ws"}
{"event_at":"2026-07-27T03:12:29.904000Z","event_fingerprint":"d8b2ece5bc76ec7e1a4245648de882f35f3fffce8def260b1de70221f638d1b6","payload":{"connection_id":"f95883f18d264834af91809e5f803e9f","event_at":"2026-07-27T03:12:29.904000Z","event_type":"price_change","frame_hash":"0dea2f38fe0a5f315bd5703d6f98bb1e819d1281e7adf767a6c92a339a4d9bec","frame_index":0,"kind":"data","monotonic_ns":223933136662708,"payload":{"event_type":"price_change","market":"0xf9d60bb033695053c4d1d8592e52171c1042f64b41a4b72e09dcc6f4852b6670","price_changes":[{"asset_id":"8698449539441374295770236407991735029336433231649246775082939325523552031992","best_ask":"0.61","best_bid":"0.6","hash":"096c7a0fdc33e24ef914459093f92638b4a31e83","price":"0.01","side":"BUY","size":"7927.52"},{"asset_id":"96283536366176669581486355171583722558858323126916278856549586825357358273536","best_ask":"0.4","best_bid":"0.39","hash":"38e6df15f9f0258b48d668a6a0664ed0bc52e792","price":"0.99","side":"SELL","size":"7927.52"}],"timestamp":"1785121949904"},"payload_hash":"2b325b968175fc278e731a4d0a2d68ef08df2090613909309335716eca5cb716","raw_frame":"{\"market\":\"0xf9d60bb033695053c4d1d8592e52171c1042f64b41a4b72e09dcc6f4852b6670\", \"price_changes\":[{\"asset_id\":\"8698449539441374295770236407991735029336433231649246775082939325523552031992\", \"price\":\"0.01\", \"size\":\"7927.52\", \"side\":\"BUY\", \"hash\":\"096c7a0fdc33e24ef914459093f92638b4a31e83\", \"best_bid\":\"0.6\", \"best_ask\":\"0.61\"}, {\"asset_id\":\"96283536366176669581486355171583722558858323126916278856549586825357358273536\", \"price\":\"0.99\", \"size\":\"7927.52\", \"side\":\"SELL\", \"hash\":\"38e6df15f9f0258b48d668a6a0664ed0bc52e792\", \"best_bid\":\"0.39\", \"best_ask\":\"0.4\"}], \"timestamp\":\"1785121949904\", \"event_type\":\"price_change\"}","received_at":"2026-07-27T03:12:29.805102Z","schema_version":"clob-market-ws.price_change.v1","sequence":null,"server_hash":null,"server_timestamp":"1785121949904","session_id":"ff6d21c8283948938400a32613abec2c","source":"clob_market_ws"},"received_at":"2026-07-27T03:12:29.805102Z","record_id":"fed762942e3be1f32ed12240ba13ad39800f53e67605541369ebfa74e3e16828","schema_fingerprint":"4aa3821a28b0b7c2400bc59aba4bcc0a76e971dadd19610d3ad38c768e124dc7","schema_version":"edge-lab-recorder.raw.v1","sequence":null,"source":"clob_market_ws"}
{"event_at":"2026-07-27T03:12:29.907000Z","event_fingerprint":"a2ccfccb68ba7195af20e1a69b344c4222d7ba259aa7963baa02052661903919","payload":{"connection_id":"f95883f18d264834af91809e5f803e9f","event_at":"2026-07-27T03:12:29.907000Z","event_type":"price_change","frame_hash":"53021674d6eb221d4bca4491b63bc62e6a5315988305d6a6ceac106f4fdf856b","frame_index":0,"kind":"data","monotonic_ns":223933139448500,"payload":{"event_type":"price_change","market":"0xf9d60bb033695053c4d1d8592e52171c1042f64b41a4b72e09dcc6f4852b6670","price_changes":[{"asset_id":"96283536366176669581486355171583722558858323126916278856549586825357358273536","best_ask":"0.4","best_bid":"0.39","hash":"b1ef61ee133a99b3eac4bb294488b97cbe9bbd8c","price":"0.36","side":"BUY","size":"55.89"},{"asset_id":"8698449539441374295770236407991735029336433231649246775082939325523552031992","best_ask":"0.61","best_bid":"0.6","hash":"e0a46c414c150f089c168cf79d32e9bb3e8a4478","price":"0.64","side":"SELL","size":"55.89"}],"timestamp":"1785121949907"},"payload_hash":"cf77f75d54deeea0ac38aa0e34e7e148e477f747c7750cf84e712a219b266f85","raw_frame":"{\"market\":\"0xf9d60bb033695053c4d1d8592e52171c1042f64b41a4b72e09dcc6f4852b6670\", \"price_changes\":[{\"asset_id\":\"96283536366176669581486355171583722558858323126916278856549586825357358273536\", \"price\":\"0.36\", \"size\":\"55.89\", \"side\":\"BUY\", \"hash\":\"b1ef61ee133a99b3eac4bb294488b97cbe9bbd8c\", \"best_bid\":\"0.39\", \"best_ask\":\"0.4\"}, {\"asset_id\":\"8698449539441374295770236407991735029336433231649246775082939325523552031992\", \"price\":\"0.64\", \"size\":\"55.89\", \"side\":\"SELL\", \"hash\":\"e0a46c414c150f089c168cf79d32e9bb3e8a4478\", \"best_bid\":\"0.6\", \"best_ask\":\"0.61\"}], \"timestamp\":\"1785121949907\", \"event_type\":\"price_change\"}","received_at":"2026-07-27T03:12:29.807888Z","schema_version":"clob-market-ws.price_change.v1","sequence":null,"server_hash":null,"server_timestamp":"1785121949907","session_id":"ff6d21c8283948938400a32613abec2c","source":"clob_market_ws"},"received_at":"2026-07-27T03:12:29.807888Z","record_id":"043adf9e4ec0330f66724c0d344e3006d70598668ec839edc839e9a89b8a94af","schema_fingerprint":"4aa3821a28b0b7c2400bc59aba4bcc0a76e971dadd19610d3ad38c768e124dc7","schema_version":"edge-lab-recorder.raw.v1","sequence":null,"source":"clob_market_ws"}
{"event_at":"2026-07-27T03:12:29.911000Z","event_fingerprint":"3bff994c4358e411ef6e87637316b9ab802e78e58a074fee8915e4e9595489cf","payload":{"connection_id":"f95883f18d264834af91809e5f803e9f","event_at":"2026-07-27T03:12:29.911000Z","event_type":"price_change","frame_hash":"fe9a6796229e9fba289664dee7f88ee8ee223b67962e6931371a53d4bd74a230","frame_index":0,"kind":"data","monotonic_ns":223933142151375,"payload":{"event_type":"price_change","market":"0xf9d60bb033695053c4d1d8592e52171c1042f64b41a4b72e09dcc6f4852b6670","price_changes":[{"asset_id":"96283536366176669581486355171583722558858323126916278856549586825357358273536","best_ask":"0.4","best_bid":"0.39","hash":"933cd355ea9828de9012e3dca8841254c1d2a187","price":"0.01","side":"BUY","size":"8299.52"},{"asset_id":"8698449539441374295770236407991735029336433231649246775082939325523552031992","best_ask":"0.61","best_bid":"0.6","hash":"e0a5211c1ad598116f76fc33a92fb62b1bdb37ac","price":"0.99","side":"SELL","size":"8299.52"}],"timestamp":"1785121949911"},"payload_hash":"e547448d977e7a45840ef0f61bab5d93da4f4fed12238b6b7ff16682ab9810f4","raw_frame":"{\"market\":\"0xf9d60bb033695053c4d1d8592e52171c1042f64b41a4b72e09dcc6f4852b6670\", \"price_changes\":[{\"asset_id\":\"96283536366176669581486355171583722558858323126916278856549586825357358273536\", \"price\":\"0.01\", \"size\":\"8299.52\", \"side\":\"BUY\", \"hash\":\"933cd355ea9828de9012e3dca8841254c1d2a187\", \"best_bid\":\"0.39\", \"best_ask\":\"0.4\"}, {\"asset_id\":\"8698449539441374295770236407991735029336433231649246775082939325523552031992\", \"price\":\"0.99\", \"size\":\"8299.52\", \"side\":\"SELL\", \"hash\":\"e0a5211c1ad598116f76fc33a92fb62b1bdb37ac\", \"best_bid\":\"0.6\", \"best_ask\":\"0.61\"}], \"timestamp\":\"1785121949911\", \"event_type\":\"price_change\"}","received_at":"2026-07-27T03:12:29.810590Z","schema_version":"clob-market-ws.price_change.v1","sequence":null,"server_hash":null,"server_timestamp":"1785121949911","session_id":"ff6d21c8283948938400a32613abec2c","source":"clob_market_ws"},"received_at":"2026-07-27T03:12:29.810590Z","record_id":"7a193122eb318191ee4f548608663f7945fcb7200b9131e7afbddc10016b9390","schema_fingerprint":"4aa3821a28b0b7c2400bc59aba4bcc0a76e971dadd19610d3ad38c768e124dc7","schema_version":"edge-lab-recorder.raw.v1","sequence":null,"source":"clob_market_ws"}
{"event_at":"2026-07-27T03:12:29.913000Z","event_fingerprint":"4a90078143f1752d7705ec7e5e60157b46c8b72ed5bddcbbd762670d778a72af","payload":{"connection_id":"f95883f18d264834af91809e5f803e9f","event_at":"2026-07-27T03:12:29.913000Z","event_type":"price_change","frame_hash":"72a6d56ebfa004b21ab626da0d34d85e241a9d463606dec6d082607d3e118fe2","frame_index":0,"kind":"data","monotonic_ns":223933144831541,"payload":{"event_type":"price_change","market":"0xf9d60bb033695053c4d1d8592e52171c1042f64b41a4b72e09dcc6f4852b6670","price_changes":[{"asset_id":"96283536366176669581486355171583722558858323126916278856549586825357358273536","best_ask":"0.4","best_bid":"0.39","hash":"e3d186a384def2fc6688090c0323c3ee89714f24","price":"0.01","side":"BUY","size":"8304.52"},{"asset_id":"8698449539441374295770236407991735029336433231649246775082939325523552031992","best_ask":"0.61","best_bid":"0.6","hash":"861b6de538ecddb4a48fcda768c6581452a9b8cf","price":"0.99","side":"SELL","size":"8304.52"}],"timestamp":"1785121949913"},"payload_hash":"d732af7c9bcabfce327f8701c1deb3b5c776e8988e1877472e870b2f024ec66d","raw_frame":"{\"market\":\"0xf9d60bb033695053c4d1d8592e52171c1042f64b41a4b72e09dcc6f4852b6670\", \"price_changes\":[{\"asset_id\":\"96283536366176669581486355171583722558858323126916278856549586825357358273536\", \"price\":\"0.01\", \"size\":\"8304.52\", \"side\":\"BUY\", \"hash\":\"e3d186a384def2fc6688090c0323c3ee89714f24\", \"best_bid\":\"0.39\", \"best_ask\":\"0.4\"}, {\"asset_id\":\"8698449539441374295770236407991735029336433231649246775082939325523552031992\", \"price\":\"0.99\", \"size\":\"8304.52\", \"side\":\"SELL\", \"hash\":\"861b6de538ecddb4a48fcda768c6581452a9b8cf\", \"best_bid\":\"0.6\", \"best_ask\":\"0.61\"}], \"timestamp\":\"1785121949913\", \"event_type\":\"price_change\"}","received_at":"2026-07-27T03:12:29.813277Z","schema_version":"clob-market-ws.price_change.v1","sequence":null,"server_hash":null,"server_timestamp":"1785121949913","session_id":"ff6d21c8283948938400a32613abec2c","source":"clob_market_ws"},"received_at":"2026-07-27T03:12:29.813277Z","record_id":"3551b4b2cc3c81b9f1100de0f7eef9ed00693de1576c87c063ba7708594635dd","schema_fingerprint":"4aa3821a28b0b7c2400bc59aba4bcc0a76e971dadd19610d3ad38c768e124dc7","schema_version":"edge-lab-recorder.raw.v1","sequence":null,"source":"clob_market_ws"}
{"event_at":"2026-07-27T03:12:29.915000Z","event_fingerprint":"aac9bf8c116548f756020d6444495c0feb5424663bae57393fd63e2337522ce9","payload":{"connection_id":"f95883f18d264834af91809e5f803e9f","event_at":"2026-07-27T03:12:29.915000Z","event_type":"price_change","frame_hash":"7bc887bb2ffe1ba0a82ed75eb727df98339f582f925ca354aef1518ff675837c","frame_index":0,"kind":"data","monotonic_ns":223933147819166,"payload":{"event_type":"price_change","market":"0xf9d60bb033695053c4d1d8592e52171c1042f64b41a4b72e09dcc6f4852b6670","price_changes":[{"asset_id":"8698449539441374295770236407991735029336433231649246775082939325523552031992","best_ask":"0.61","best_bid":"0.6","hash":"31daae53656d6b78356f94d39f2cfe3e1f36d132","price":"0.01","side":"BUY","size":"7922.52"},{"asset_id":"96283536366176669581486355171583722558858323126916278856549586825357358273536","best_ask":"0.4","best_bid":"0.39","hash":"dc3d2f582a6f28a15a61d8e1effab9c4068571cd","price":"0.99","side":"SELL","size":"7922.52"}],"timestamp":"1785121949915"},"payload_hash":"0a3feaf4006299b7f230065587362c7e703cf89fb20035139b7137087d9c80cc","raw_frame":"{\"market\":\"0xf9d60bb033695053c4d1d8592e52171c1042f64b41a4b72e09dcc6f4852b6670\", \"price_changes\":[{\"asset_id\":\"8698449539441374295770236407991735029336433231649246775082939325523552031992\", \"price\":\"0.01\", \"size\":\"7922.52\", \"side\":\"BUY\", \"hash\":\"31daae53656d6b78356f94d39f2cfe3e1f36d132\", \"best_bid\":\"0.6\", \"best_ask\":\"0.61\"}, {\"asset_id\":\"96283536366176669581486355171583722558858323126916278856549586825357358273536\", \"price\":\"0.99\", \"size\":\"7922.52\", \"side\":\"SELL\", \"hash\":\"dc3d2f582a6f28a15a61d8e1effab9c4068571cd\", \"best_bid\":\"0.39\", \"best_ask\":\"0.4\"}], \"timestamp\":\"1785121949915\", \"event_type\":\"price_change\"}","received_at":"2026-07-27T03:12:29.816262Z","schema_version":"clob-market-ws.price_change.v1","sequence":null,"server_hash":null,"server_timestamp":"1785121949915","session_id":"ff6d21c8283948938400a32613abec2c","source":"clob_market_ws"},"received_at":"2026-07-27T03:12:29.816262Z","record_id":"6166d355953c5c85d447656e27af95295561367634580c6b109f987b8a136c1b","schema_fingerprint":"4aa3821a28b0b7c2400bc59aba4bcc0a76e971dadd19610d3ad38c768e124dc7","schema_version":"edge-lab-recorder.raw.v1","sequence":null,"source":"clob_market_ws"}
{"event_at":"2026-07-27T03:12:29.916000Z","event_fingerprint":"b97433d36dcd7f7399b85fa388548f19784b9ee3951db0e8bbf75cb6aefc5e49","payload":{"connection_id":"f95883f18d264834af91809e5f803e9f","event_at":"2026-07-27T03:12:29.916000Z","event_type":"price_change","frame_hash":"7ea900471266a41c8576959ca314677997b5336e84ddd138db91f4e602e89597","frame_index":0,"kind":"data","monotonic_ns":223933148470083,"payload":{"event_type":"price_change","market":"0xf9d60bb033695053c4d1d8592e52171c1042f64b41a4b72e09dcc6f4852b6670","price_changes":[{"asset_id":"96283536366176669581486355171583722558858323126916278856549586825357358273536","best_ask":"0.4","best_bid":"0.39","hash":"5e5bde91673d22c9e7aca2fe4ae3658d32825bfe","price":"0.01","side":"BUY","size":"8309.52"},{"asset_id":"8698449539441374295770236407991735029336433231649246775082939325523552031992","best_ask":"0.61","best_bid":"0.6","hash":"2fc559510f7a18806d382d0f16373e8460c1c1ec","price":"0.99","side":"SELL","size":"8309.52"}],"timestamp":"1785121949916"},"payload_hash":"0e976febabff97b00cdd8d27fc25d87da7289b2436264be56105b116dd1143f5","raw_frame":"{\"market\":\"0xf9d60bb033695053c4d1d8592e52171c1042f64b41a4b72e09dcc6f4852b6670\", \"price_changes\":[{\"asset_id\":\"96283536366176669581486355171583722558858323126916278856549586825357358273536\", \"price\":\"0.01\", \"size\":\"8309.52\", \"side\":\"BUY\", \"hash\":\"5e5bde91673d22c9e7aca2fe4ae3658d32825bfe\", \"best_bid\":\"0.39\", \"best_ask\":\"0.4\"}, {\"asset_id\":\"8698449539441374295770236407991735029336433231649246775082939325523552031992\", \"price\":\"0.99\", \"size\":\"8309.52\", \"side\":\"SELL\", \"hash\":\"2fc559510f7a18806d382d0f16373e8460c1c1ec\", \"best_bid\":\"0.6\", \"best_ask\":\"0.61\"}], \"timestamp\":\"1785121949916\", \"event_type\":\"price_change\"}","received_at":"2026-07-27T03:12:29.816917Z","schema_version":"clob-market-ws.price_change.v1","sequence":null,"server_hash":null,"server_timestamp":"1785121949916","session_id":"ff6d21c8283948938400a32613abec2c","source":"clob_market_ws"},"received_at":"2026-07-27T03:12:29.816917Z","record_id":"fb9ff866bb55cf2f02e93e9585bedc898a9cd93644f4b9ef1bdf02a82b702ebf","schema_fingerprint":"4aa3821a28b0b7c2400bc59aba4bcc0a76e971dadd19610d3ad38c768e124dc7","schema_version":"edge-lab-recorder.raw.v1","sequence":null,"source":"clob_market_ws"}
{"event_at":"2026-07-27T03:12:29.932000Z","event_fingerprint":"4ddfa4398aa0c3cc10d94dd67380cee2754d53f6a724b692bed3119dc51d5ea8","payload":{"connection_id":"f95883f18d264834af91809e5f803e9f","event_at":"2026-07-27T03:12:29.932000Z","event_type":"price_change","frame_hash":"9374f61771535e47a1fb7b29671bdbc6b9f4e5629f5c2c0655f98b97bd2df283","frame_index":0,"kind":"data","monotonic_ns":223933185391333,"payload":{"event_type":"price_change","market":"0xf9d60bb033695053c4d1d8592e52171c1042f64b41a4b72e09dcc6f4852b6670","price_changes":[{"asset_id":"96283536366176669581486355171583722558858323126916278856549586825357358273536","best_ask":"0.4","best_bid":"0.39","hash":"6c2eaaaf41954b1a0b1fc8c2acdc7ac64ca18cdb","price":"0.26","side":"BUY","size":"170.6"},{"asset_id":"8698449539441374295770236407991735029336433231649246775082939325523552031992","best_ask":"0.61","best_bid":"0.6","hash":"28e358da9472faa02b01d030786d88d47e799a25","price":"0.74","side":"SELL","size":"170.6"}],"timestamp":"1785121949932"},"payload_hash":"4f2536c683b32d7f912eb98b39500a85c0e0b80a33826f39be0c7e73dea568d7","raw_frame":"{\"market\":\"0xf9d60bb033695053c4d1d8592e52171c1042f64b41a4b72e09dcc6f4852b6670\", \"price_changes\":[{\"asset_id\":\"96283536366176669581486355171583722558858323126916278856549586825357358273536\", \"price\":\"0.26\", \"size\":\"170.6\", \"side\":\"BUY\", \"hash\":\"6c2eaaaf41954b1a0b1fc8c2acdc7ac64ca18cdb\", \"best_bid\":\"0.39\", \"best_ask\":\"0.4\"}, {\"asset_id\":\"8698449539441374295770236407991735029336433231649246775082939325523552031992\", \"price\":\"0.74\", \"size\":\"170.6\", \"side\":\"SELL\", \"hash\":\"28e358da9472faa02b01d030786d88d47e799a25\", \"best_bid\":\"0.6\", \"best_ask\":\"0.61\"}], \"timestamp\":\"1785121949932\", \"event_type\":\"price_change\"}","received_at":"2026-07-27T03:12:29.853823Z","schema_version":"clob-market-ws.price_change.v1","sequence":null,"server_hash":null,"server_timestamp":"1785121949932","session_id":"ff6d21c8283948938400a32613abec2c","source":"clob_market_ws"},"received_at":"2026-07-27T03:12:29.853823Z","record_id":"7b9130bcb58ab96b36134e63367d9f33ea15b20d41413006e9ac95ebf6e13594","schema_fingerprint":"4aa3821a28b0b7c2400bc59aba4bcc0a76e971dadd19610d3ad38c768e124dc7","schema_version":"edge-lab-recorder.raw.v1","sequence":null,"source":"clob_market_ws"}
{"event_at":"2026-07-27T03:12:29.939000Z","event_fingerprint":"e329ce85851566fba423162c8c38db4237073d9283d51dc8be1a7b9d24948dbb","payload":{"connection_id":"f95883f18d264834af91809e5f803e9f","event_at":"2026-07-27T03:12:29.939000Z","event_type":"price_change","frame_hash":"c70d9ad7285e54f7f93cfb5203ba7ba149fd089ca661e64580c9d9335e67eb38","frame_index":0,"kind":"data","monotonic_ns":223933187056666,"payload":{"event_type":"price_change","market":"0xf9d60bb033695053c4d1d8592e52171c1042f64b41a4b72e09dcc6f4852b6670","price_changes":[{"asset_id":"8698449539441374295770236407991735029336433231649246775082939325523552031992","best_ask":"0.61","best_bid":"0.6","hash":"144042602778c23f2dd479d7b3c0fd8c1629e21e","price":"0.02","side":"BUY","size":"1345.79"},{"asset_id":"96283536366176669581486355171583722558858323126916278856549586825357358273536","best_ask":"0.4","best_bid":"0.39","hash":"363e190e1455e4457703f7867fa43d2e5ebb5b9e","price":"0.98","side":"SELL","size":"1345.79"}],"timestamp":"1785121949939"},"payload_hash":"4824a0d5262cb23038e5810652b10e30b366674813effe83986c4cffe0e21dcc","raw_frame":"{\"market\":\"0xf9d60bb033695053c4d1d8592e52171c1042f64b41a4b72e09dcc6f4852b6670\", \"price_changes\":[{\"asset_id\":\"8698449539441374295770236407991735029336433231649246775082939325523552031992\", \"price\":\"0.02\", \"size\":\"1345.79\", \"side\":\"BUY\", \"hash\":\"144042602778c23f2dd479d7b3c0fd8c1629e21e\", \"best_bid\":\"0.6\", \"best_ask\":\"0.61\"}, {\"asset_id\":\"96283536366176669581486355171583722558858323126916278856549586825357358273536\", \"price\":\"0.98\", \"size\":\"1345.79\", \"side\":\"SELL\", \"hash\":\"363e190e1455e4457703f7867fa43d2e5ebb5b9e\", \"best_bid\":\"0.39\", \"best_ask\":\"0.4\"}], \"timestamp\":\"1785121949939\", \"event_type\":\"price_change\"}","received_at":"2026-07-27T03:12:29.855495Z","schema_version":"clob-market-ws.price_change.v1","sequence":null,"server_hash":null,"server_timestamp":"1785121949939","session_id":"ff6d21c8283948938400a32613abec2c","source":"clob_market_ws"},"received_at":"2026-07-27T03:12:29.855495Z","record_id":"39dcdcde11ab6a53d6f8c9656b56afe78e30e6c857356e95e71abc711ce39c37","schema_fingerprint":"4aa3821a28b0b7c2400bc59aba4bcc0a76e971dadd19610d3ad38c768e124dc7","schema_version":"edge-lab-recorder.raw.v1","sequence":null,"source":"clob_market_ws"}
{"event_at":"2026-07-27T03:12:29.952000Z","event_fingerprint":"aed6a84d722f1ec9ecfcc99321b600df837fae3635f6a21efbdfbc2f3d3574b7","payload":{"connection_id":"f95883f18d264834af91809e5f803e9f","event_at":"2026-07-27T03:12:29.952000Z","event_type":"price_change","frame_hash":"a9961905b775cdb51c80c4b767055234a76bf15a6004f5a1594aa011d8bf942b","frame_index":0,"kind":"data","monotonic_ns":223933188606791,"payload":{"event_type":"price_change","market":"0xf9d60bb033695053c4d1d8592e52171c1042f64b41a4b72e09dcc6f4852b6670","price_changes":[{"asset_id":"96283536366176669581486355171583722558858323126916278856549586825357358273536","best_ask":"0.4","best_bid":"0.39","hash":"b423843ca627e9d40e22c1a11571a15fe9c4616a","price":"0.26","side":"BUY","size":"165.6"},{"asset_id":"8698449539441374295770236407991735029336433231649246775082939325523552031992","best_ask":"0.61","best_bid":"0.6","hash":"1e8b0c588d1dbca2266fb56228921de0a7b89282","price":"0.74","side":"SELL","size":"165.6"}],"timestamp":"1785121949952"},"payload_hash":"1ab429910bc9e2a6ddba6d2aba4245d01c9e72bb51c142ad211d21c8312d346e","raw_frame":"{\"market\":\"0xf9d60bb033695053c4d1d8592e52171c1042f64b41a4b72e09dcc6f4852b6670\", \"price_changes\":[{\"asset_id\":\"96283536366176669581486355171583722558858323126916278856549586825357358273536\", \"price\":\"0.26\", \"size\":\"165.6\", \"side\":\"BUY\", \"hash\":\"b423843ca627e9d40e22c1a11571a15fe9c4616a\", \"best_bid\":\"0.39\", \"best_ask\":\"0.4\"}, {\"asset_id\":\"8698449539441374295770236407991735029336433231649246775082939325523552031992\", \"price\":\"0.74\", \"size\":\"165.6\", \"side\":\"SELL\", \"hash\":\"1e8b0c588d1dbca2266fb56228921de0a7b89282\", \"best_bid\":\"0.6\", \"best_ask\":\"0.61\"}], \"timestamp\":\"1785121949952\", \"event_type\":\"price_change\"}","received_at":"2026-07-27T03:12:29.857046Z","schema_version":"clob-market-ws.price_change.v1","sequence":null,"server_hash":null,"server_timestamp":"1785121949952","session_id":"ff6d21c8283948938400a32613abec2c","source":"clob_market_ws"},"received_at":"2026-07-27T03:12:29.857046Z","record_id":"1c15e345cd1a7823e42974bbf5fda585ff3af3fe489d49fa6000e18c83ae04af","schema_fingerprint":"4aa3821a28b0b7c2400bc59aba4bcc0a76e971dadd19610d3ad38c768e124dc7","schema_version":"edge-lab-recorder.raw.v1","sequence":null,"source":"clob_market_ws"}
{"event_at":"2026-07-27T03:12:29.965000Z","event_fingerprint":"0ea4a1690aeda3e1db086bea62ed5aeddbaf0bb064ee2f574be2a111727ec12c","payload":{"connection_id":"f95883f18d264834af91809e5f803e9f","event_at":"2026-07-27T03:12:29.965000Z","event_type":"best_bid_ask","frame_hash":"d77e83eaa298e8325342afe4d75fcd4c8afdb468bc865f8ce277fb6534fe0215","frame_index":0,"kind":"data","monotonic_ns":223933195534291,"payload":{"asset_id":"8698449539441374295770236407991735029336433231649246775082939325523552031992","best_ask":"0.61","best_bid":"0.6","event_type":"best_bid_ask","market":"0xf9d60bb033695053c4d1d8592e52171c1042f64b41a4b72e09dcc6f4852b6670","spread":"0.01","timestamp":"1785121949965"},"payload_hash":"362dd573c99910a2c53a3a326406327457ccde0023a48ba6c638a629634304f8","raw_frame":"{\"market\":\"0xf9d60bb033695053c4d1d8592e52171c1042f64b41a4b72e09dcc6f4852b6670\", \"asset_id\":\"8698449539441374295770236407991735029336433231649246775082939325523552031992\", \"best_bid\":\"0.6\", \"best_ask\":\"0.61\", \"spread\":\"0.01\", \"timestamp\":\"1785121949965\", \"event_type\":\"best_bid_ask\"}","received_at":"2026-07-27T03:12:29.863973Z","schema_version":"clob-market-ws.best_bid_ask.v1","sequence":null,"server_hash":null,"server_timestamp":"1785121949965","session_id":"ff6d21c8283948938400a32613abec2c","source":"clob_market_ws"},"received_at":"2026-07-27T03:12:29.863973Z","record_id":"7e0e8a08e8de7f85302e4ed715a0abfcda51f5780db32211c281fe49329a40ca","schema_fingerprint":"8488399f31b0337811b13b266be932db7062827c2470b78bd8e9e99bab51d17d","schema_version":"edge-lab-recorder.raw.v1","sequence":null,"source":"clob_market_ws"}
{"event_at":"2026-07-27T03:12:29.965000Z","event_fingerprint":"e3480bcf03639073f5a7a4a63254e1a62215475a8790c3225babf8dc37361e40","payload":{"connection_id":"f95883f18d264834af91809e5f803e9f","event_at":"2026-07-27T03:12:29.965000Z","event_type":"best_bid_ask","frame_hash":"67cf27eef5d464d4093d60d91c47a7a2a0961a6765cccfa7ef655a3792c24494","frame_index":0,"kind":"data","monotonic_ns":223933196784041,"payload":{"asset_id":"96283536366176669581486355171583722558858323126916278856549586825357358273536","best_ask":"0.4","best_bid":"0.39","event_type":"best_bid_ask","market":"0xf9d60bb033695053c4d1d8592e52171c1042f64b41a4b72e09dcc6f4852b6670","spread":"0.01","timestamp":"1785121949965"},"payload_hash":"ca492eb42d3e5c0cb914086203ad2141f100cb6bd19ec27993d007dceeefc684","raw_frame":"{\"market\":\"0xf9d60bb033695053c4d1d8592e52171c1042f64b41a4b72e09dcc6f4852b6670\", \"asset_id\":\"96283536366176669581486355171583722558858323126916278856549586825357358273536\", \"best_bid\":\"0.39\", \"best_ask\":\"0.4\", \"spread\":\"0.01\", \"timestamp\":\"1785121949965\", \"event_type\":\"best_bid_ask\"}","received_at":"2026-07-27T03:12:29.865220Z","schema_version":"clob-market-ws.best_bid_ask.v1","sequence":null,"server_hash":null,"server_timestamp":"1785121949965","session_id":"ff6d21c8283948938400a32613abec2c","source":"clob_market_ws"},"received_at":"2026-07-27T03:12:29.865220Z","record_id":"5d4ee4af22f2fea8dc18753448ac0ba69423b2b6682d8a9bbcdb1e539c7aadd2","schema_fingerprint":"8488399f31b0337811b13b266be932db7062827c2470b78bd8e9e99bab51d17d","schema_version":"edge-lab-recorder.raw.v1","sequence":null,"source":"clob_market_ws"}
{"event_at":"2026-07-27T03:12:29.964000Z","event_fingerprint":"4edd7a08631173feb75933d6cbca72d576ac66fb96a5a1c90f750102600b0255","payload":{"connection_id":"f95883f18d264834af91809e5f803e9f","event_at":"2026-07-27T03:12:29.964000Z","event_type":"price_change","frame_hash":"3f94b3d32b95a60f4937c045b1b12f148746a67bff1750201d78161bacc3812c","frame_index":0,"kind":"data","monotonic_ns":223933198120791,"payload":{"event_type":"price_change","market":"0xf9d60bb033695053c4d1d8592e52171c1042f64b41a4b72e09dcc6f4852b6670","price_changes":[{"asset_id":"8698449539441374295770236407991735029336433231649246775082939325523552031992","best_ask":"0.61","best_bid":"0.6","hash":"76ebe34c311a469a6c53ec4cfceb27ff8f779935","price":"0.6","side":"BUY","size":"50.57"},{"asset_id":"96283536366176669581486355171583722558858323126916278856549586825357358273536","best_ask":"0.4","best_bid":"0.39","hash":"edd17142d998a7b2a5f4fe246058cfb2c1995c0e","price":"0.4","side":"SELL","size":"50.57"}],"timestamp":"1785121949964"},"payload_hash":"c0af74d9abbe128e99661197f4dd878d065e7147ab7844b2fd0f66a8dcf8ab8a","raw_frame":"{\"market\":\"0xf9d60bb033695053c4d1d8592e52171c1042f64b41a4b72e09dcc6f4852b6670\", \"price_changes\":[{\"asset_id\":\"8698449539441374295770236407991735029336433231649246775082939325523552031992\", \"price\":\"0.6\", \"size\":\"50.57\", \"side\":\"BUY\", \"hash\":\"76ebe34c311a469a6c53ec4cfceb27ff8f779935\", \"best_bid\":\"0.6\", \"best_ask\":\"0.61\"}, {\"asset_id\":\"96283536366176669581486355171583722558858323126916278856549586825357358273536\", \"price\":\"0.4\", \"size\":\"50.57\", \"side\":\"SELL\", \"hash\":\"edd17142d998a7b2a5f4fe246058cfb2c1995c0e\", \"best_bid\":\"0.39\", \"best_ask\":\"0.4\"}], \"timestamp\":\"1785121949964\", \"event_type\":\"price_change\"}","received_at":"2026-07-27T03:12:29.866559Z","schema_version":"clob-market-ws.price_change.v1","sequence":null,"server_hash":null,"server_timestamp":"1785121949964","session_id":"ff6d21c8283948938400a32613abec2c","source":"clob_market_ws"},"received_at":"2026-07-27T03:12:29.866559Z","record_id":"294598b94f4967cb2864189affb799271f77aa6206bce84d725f5644364cb997","schema_fingerprint":"4aa3821a28b0b7c2400bc59aba4bcc0a76e971dadd19610d3ad38c768e124dc7","schema_version":"edge-lab-recorder.raw.v1","sequence":null,"source":"clob_market_ws"}
{"event_at":null,"event_fingerprint":"c999f67fe0a9c8165c7095c75dae24117fef7b5508f4f7af2e18aa37be6a6678","payload":{"connection_id":"f95883f18d264834af91809e5f803e9f","detail":{"current_server_timestamp":"1785121949964","entity":"clob_market_ws:8698449539441374295770236407991735029336433231649246775082939325523552031992","previous_server_timestamp":"1785121949965"},"event_type":"anomaly.time_regression","kind":"diagnostic","monotonic_ns":223933200170208,"received_at":"2026-07-27T03:12:29.868610Z","schema_version":"edge-lab-recorder.anomaly.v1","session_id":"ff6d21c8283948938400a32613abec2c","source":"clob_market_ws","trigger_frame_hash":"c28f1655a22b7bde6c5673c135e8152c8b85eb9f5e399e1687e8a4454780744e","trigger_server_hash":"76ebe34c311a469a6c53ec4cfceb27ff8f779935"},"received_at":"2026-07-27T03:12:29.868610Z","record_id":"67ccb042983d52328d381713f754120d812a3b3a8845260495e4637416c07333","schema_fingerprint":"cb1780324c96914017c24d4692a681315845f9745a5a4a3a289c5a43388b35c3","schema_version":"edge-lab-recorder.raw.v1","sequence":null,"source":"clob_market_ws"}
{"event_at":"2026-07-27T03:12:29.964000Z","event_fingerprint":"151d1bccaf3f768070d922de625ce5081c7347678b0ca6e0a190bf46b0a30d4a","payload":{"connection_id":"f95883f18d264834af91809e5f803e9f","event_at":"2026-07-27T03:12:29.964000Z","event_type":"book","frame_hash":"c28f1655a22b7bde6c5673c135e8152c8b85eb9f5e399e1687e8a4454780744e","frame_index":0,"kind":"data","monotonic_ns":223933199752375,"payload":{"asks":[{"price":"0.99","size":"8309.52"},{"price":"0.98","size":"1345.79"},{"price":"0.97","size":"1154.13"},{"price":"0.96","size":"973.5"},{"price":"0.95","size":"921"},{"price":"0.94","size":"716.09"},{"price":"0.93","size":"661.2"},{"price":"0.92","size":"642.59"},{"price":"0.91","size":"658.1"},{"price":"0.9","size":"130.6"},{"price":"0.89","size":"120.29"},{"price":"0.88","size":"141.4"},{"price":"0.87","size":"103.9"},{"price":"0.86","size":"97.2"},{"price":"0.85","size":"122.39"},{"price":"0.84","size":"92.1"},{"price":"0.83","size":"83.29"},{"price":"0.82","size":"109.1"},{"price":"0.81","size":"76.19"},{"price":"0.8","size":"78.6"},{"price":"0.79","size":"115.82"},{"price":"0.78","size":"82.28"},{"price":"0.77","size":"79.99"},{"price":"0.76","size":"182.97"},{"price":"0.75","size":"69.93"},{"price":"0.74","size":"165.6"},{"price":"0.73","size":"164.3"},{"price":"0.72","size":"93"},{"price":"0.71","size":"66.88"},{"price":"0.7","size":"223"},{"price":"0.69","size":"146.1"},{"price":"0.68","size":"120.88"},{"price":"0.67","size":"96.1"},{"price":"0.66","size":"63.39"},{"price":"0.65","size":"56.1"},{"price":"0.64","size":"55.89"},{"price":"0.63","size":"40.7"},{"price":"0.62","size":"39.6"},{"price":"0.61","size":"43"}],"asset_id":"8698449539441374295770236407991735029336433231649246775082939325523552031992","bids":[{"price":"0.01","size":"7922.52"},{"price":"0.02","size":"1345.79"},{"price":"0.03","size":"1070.8"},{"price":"0.04","size":"1081.5"},{"price":"0.05","size":"987"},{"price":"0.06","size":"908.09"},{"price":"0.07","size":"456.2"},{"price":"0.08","size":"168.65"},{"price":"0.09","size":"343.1"},{"price":"0.1","size":"403.6"},{"price":"0.11","size":"120.29"},{"price":"0.12","size":"139.4"},{"price":"0.13","size":"133.9"},{"price":"0.14","size":"97.2"},{"price":"0.15","size":"116.39"},{"price":"0.16","size":"117.1"},{"price":"0.17","size":"104.29"},{"price":"0.18","size":"83.89"},{"price":"0.19","size":"106.19"},{"price":"0.2","size":"120.6"},{"price":"0.21","size":"71.3"},{"price":"0.22","size":"115.2"},{"price":"0.23","size":"71.3"},{"price":"0.24","size":"85.6"},{"price":"0.25","size":"93"},{"price":"0.26","size":"96.6"},{"price":"0.27","size":"59.3"},{"price":"0.28","size":"103"},{"price":"0.29","size":"56.88"},{"price":"0.3","size":"56"},{"price":"0.31","size":"99.1"},{"price":"0.32","size":"54.18"},{"price":"0.33","size":"53.5"},{"price":"0.34","size":"95.79"},{"price":"0.35","size":"51.1"},{"price":"0.36","size":"50.58"},{"price":"0.37","size":"80.1"},{"price":"0.38","size":"49.6"},{"price":"0.39","size":"49.09"},{"price":"0.4","size":"99.7"},{"price":"0.41","size":"150.3"},{"price":"0.42","size":"147.09"},{"price":"0.43","size":"164.8"},{"price":"0.44","size":"133.6"},{"price":"0.45","size":"133.5"},{"price":"0.46","size":"77.6"},{"price":"0.47","size":"47.5"},{"price":"0.48","size":"41.02"},{"price":"0.49","size":"71"},{"price":"0.5","size":"41"},{"price":"0.51","size":"111"},{"price":"0.52","size":"66"},{"price":"0.53","size":"64.15"},{"price":"0.54","size":"95"},{"price":"0.55","size":"59.05"},{"price":"0.57","size":"10.71"},{"price":"0.58","size":"90"},{"price":"0.59","size":"103.93"},{"price":"0.6","size":"50.57"}],"event_type":"book","hash":"76ebe34c311a469a6c53ec4cfceb27ff8f779935","market":"0xf9d60bb033695053c4d1d8592e52171c1042f64b41a4b72e09dcc6f4852b6670","timestamp":"1785121949964"},"payload_hash":"e6514798edb68db5f65710e65e03fa395b5b11bc00533fd86692ea1546e0b90d","raw_frame":"{\"market\":\"0xf9d60bb033695053c4d1d8592e52171c1042f64b41a4b72e09dcc6f4852b6670\", \"asset_id\":\"8698449539441374295770236407991735029336433231649246775082939325523552031992\", \"bids\":[{\"price\":\"0.01\", \"size\":\"7922.52\"}, {\"price\":\"0.02\", \"size\":\"1345.79\"}, {\"price\":\"0.03\", \"size\":\"1070.8\"}, {\"price\":\"0.04\", \"size\":\"1081.5\"}, {\"price\":\"0.05\", \"size\":\"987\"}, {\"price\":\"0.06\", \"size\":\"908.09\"}, {\"price\":\"0.07\", \"size\":\"456.2\"}, {\"price\":\"0.08\", \"size\":\"168.65\"}, {\"price\":\"0.09\", \"size\":\"343.1\"}, {\"price\":\"0.1\", \"size\":\"403.6\"}, {\"price\":\"0.11\", \"size\":\"120.29\"}, {\"price\":\"0.12\", \"size\":\"139.4\"}, {\"price\":\"0.13\", \"size\":\"133.9\"}, {\"price\":\"0.14\", \"size\":\"97.2\"}, {\"price\":\"0.15\", \"size\":\"116.39\"}, {\"price\":\"0.16\", \"size\":\"117.1\"}, {\"price\":\"0.17\", \"size\":\"104.29\"}, {\"price\":\"0.18\", \"size\":\"83.89\"}, {\"price\":\"0.19\", \"size\":\"106.19\"}, {\"price\":\"0.2\", \"size\":\"120.6\"}, {\"price\":\"0.21\", \"size\":\"71.3\"}, {\"price\":\"0.22\", \"size\":\"115.2\"}, {\"price\":\"0.23\", \"size\":\"71.3\"}, {\"price\":\"0.24\", \"size\":\"85.6\"}, {\"price\":\"0.25\", \"size\":\"93\"}, {\"price\":\"0.26\", \"size\":\"96.6\"}, {\"price\":\"0.27\", \"size\":\"59.3\"}, {\"price\":\"0.28\", \"size\":\"103\"}, {\"price\":\"0.29\", \"size\":\"56.88\"}, {\"price\":\"0.3\", \"size\":\"56\"}, {\"price\":\"0.31\", \"size\":\"99.1\"}, {\"price\":\"0.32\", \"size\":\"54.18\"}, {\"price\":\"0.33\", \"size\":\"53.5\"}, {\"price\":\"0.34\", \"size\":\"95.79\"}, {\"price\":\"0.35\", \"size\":\"51.1\"}, {\"price\":\"0.36\", \"size\":\"50.58\"}, {\"price\":\"0.37\", \"size\":\"80.1\"}, {\"price\":\"0.38\", \"size\":\"49.6\"}, {\"price\":\"0.39\", \"size\":\"49.09\"}, {\"price\":\"0.4\", \"size\":\"99.7\"}, {\"price\":\"0.41\", \"size\":\"150.3\"}, {\"price\":\"0.42\", \"size\":\"147.09\"}, {\"price\":\"0.43\", \"size\":\"164.8\"}, {\"price\":\"0.44\", \"size\":\"133.6\"}, {\"price\":\"0.45\", \"size\":\"133.5\"}, {\"price\":\"0.46\", \"size\":\"77.6\"}, {\"price\":\"0.47\", \"size\":\"47.5\"}, {\"price\":\"0.48\", \"size\":\"41.02\"}, {\"price\":\"0.49\", \"size\":\"71\"}, {\"price\":\"0.5\", \"size\":\"41\"}, {\"price\":\"0.51\", \"size\":\"111\"}, {\"price\":\"0.52\", \"size\":\"66\"}, {\"price\":\"0.53\", \"size\":\"64.15\"}, {\"price\":\"0.54\", \"size\":\"95\"}, {\"price\":\"0.55\", \"size\":\"59.05\"}, {\"price\":\"0.57\", \"size\":\"10.71\"}, {\"price\":\"0.58\", \"size\":\"90\"}, {\"price\":\"0.59\", \"size\":\"103.93\"}, {\"price\":\"0.6\", \"size\":\"50.57\"}], \"asks\":[{\"price\":\"0.99\", \"size\":\"8309.52\"}, {\"price\":\"0.98\", \"size\":\"1345.79\"}, {\"price\":\"0.97\", \"size\":\"1154.13\"}, {\"price\":\"0.96\", \"size\":\"973.5\"}, {\"price\":\"0.95\", \"size\":\"921\"}, {\"price\":\"0.94\", \"size\":\"716.09\"}, {\"price\":\"0.93\", \"size\":\"661.2\"}, {\"price\":\"0.92\", \"size\":\"642.59\"}, {\"price\":\"0.91\", \"size\":\"658.1\"}, {\"price\":\"0.9\", \"size\":\"130.6\"}, {\"price\":\"0.89\", \"size\":\"120.29\"}, {\"price\":\"0.88\", \"size\":\"141.4\"}, {\"price\":\"0.87\", \"size\":\"103.9\"}, {\"price\":\"0.86\", \"size\":\"97.2\"}, {\"price\":\"0.85\", \"size\":\"122.39\"}, {\"price\":\"0.84\", \"size\":\"92.1\"}, {\"price\":\"0.83\", \"size\":\"83.29\"}, {\"price\":\"0.82\", \"size\":\"109.1\"}, {\"price\":\"0.81\", \"size\":\"76.19\"}, {\"price\":\"0.8\", \"size\":\"78.6\"}, {\"price\":\"0.79\", \"size\":\"115.82\"}, {\"price\":\"0.78\", \"size\":\"82.28\"}, {\"price\":\"0.77\", \"size\":\"79.99\"}, {\"price\":\"0.76\", \"size\":\"182.97\"}, {\"price\":\"0.75\", \"size\":\"69.93\"}, {\"price\":\"0.74\", \"size\":\"165.6\"}, {\"price\":\"0.73\", \"size\":\"164.3\"}, {\"price\":\"0.72\", \"size\":\"93\"}, {\"price\":\"0.71\", \"size\":\"66.88\"}, {\"price\":\"0.7\", \"size\":\"223\"}, {\"price\":\"0.69\", \"size\":\"146.1\"}, {\"price\":\"0.68\", \"size\":\"120.88\"}, {\"price\":\"0.67\", \"size\":\"96.1\"}, {\"price\":\"0.66\", \"size\":\"63.39\"}, {\"price\":\"0.65\", \"size\":\"56.1\"}, {\"price\":\"0.64\", \"size\":\"55.89\"}, {\"price\":\"0.63\", \"size\":\"40.7\"}, {\"price\":\"0.62\", \"size\":\"39.6\"}, {\"price\":\"0.61\", \"size\":\"43\"}], \"hash\":\"76ebe34c311a469a6c53ec4cfceb27ff8f779935\", \"timestamp\":\"1785121949964\", \"event_type\":\"book\"}","received_at":"2026-07-27T03:12:29.868192Z","schema_version":"clob-market-ws.book.v1","sequence":null,"server_hash":"76ebe34c311a469a6c53ec4cfceb27ff8f779935","server_timestamp":"1785121949964","session_id":"ff6d21c8283948938400a32613abec2c","source":"clob_market_ws"},"received_at":"2026-07-27T03:12:29.868192Z","record_id":"d77baabd7ba130a0ef5301d2cf054e0783994a2f6f245dcb082863739e76941a","schema_fingerprint":"dc2caa1c89c6a7426e2e07ff925910cd4d0a8a223a515d4092d91d6d127aacb6","schema_version":"edge-lab-recorder.raw.v1","sequence":null,"source":"clob_market_ws"}
{"event_at":null,"event_fingerprint":"c593049e982691bdaadf3f860fce0b02477c01c6b4894c94eaafa0f25e266ac2","payload":{"connection_id":"f95883f18d264834af91809e5f803e9f","detail":{"current_server_timestamp":"1785121949964","entity":"clob_market_ws:96283536366176669581486355171583722558858323126916278856549586825357358273536","previous_server_timestamp":"1785121949965"},"event_type":"anomaly.time_regression","kind":"diagnostic","monotonic_ns":223933210519416,"received_at":"2026-07-27T03:12:29.878960Z","schema_version":"edge-lab-recorder.anomaly.v1","session_id":"ff6d21c8283948938400a32613abec2c","source":"clob_market_ws","trigger_frame_hash":"43854d8a315c804fc65c7fadd23ad32325906a15726f2fd664246b3d7a0098ce","trigger_server_hash":"edd17142d998a7b2a5f4fe246058cfb2c1995c0e"},"received_at":"2026-07-27T03:12:29.878960Z","record_id":"eed2fc683d2c531dc1748b84d22632a9a18b38c34144db01902b7ec94d67e328","schema_fingerprint":"cb1780324c96914017c24d4692a681315845f9745a5a4a3a289c5a43388b35c3","schema_version":"edge-lab-recorder.raw.v1","sequence":null,"source":"clob_market_ws"}
{"event_at":"2026-07-27T03:12:29.964000Z","event_fingerprint":"b09e15c4e07ca105cc108f3295badcdf3069f447aab42e9ed59cab28097e09b6","payload":{"connection_id":"f95883f18d264834af91809e5f803e9f","event_at":"2026-07-27T03:12:29.964000Z","event_type":"book","frame_hash":"43854d8a315c804fc65c7fadd23ad32325906a15726f2fd664246b3d7a0098ce","frame_index":0,"kind":"data","monotonic_ns":223933210162500,"payload":{"asks":[{"price":"0.99","size":"7922.52"},{"price":"0.98","size":"1345.79"},{"price":"0.97","size":"1070.8"},{"price":"0.96","size":"1081.5"},{"price":"0.95","size":"987"},{"price":"0.94","size":"908.09"},{"price":"0.93","size":"456.2"},{"price":"0.92","size":"168.65"},{"price":"0.91","size":"343.1"},{"price":"0.9","size":"403.6"},{"price":"0.89","size":"120.29"},{"price":"0.88","size":"139.4"},{"price":"0.87","size":"133.9"},{"price":"0.86","size":"97.2"},{"price":"0.85","size":"116.39"},{"price":"0.84","size":"117.1"},{"price":"0.83","size":"104.29"},{"price":"0.82","size":"83.89"},{"price":"0.81","size":"106.19"},{"price":"0.8","size":"120.6"},{"price":"0.79","size":"71.3"},{"price":"0.78","size":"115.2"},{"price":"0.77","size":"71.3"},{"price":"0.76","size":"85.6"},{"price":"0.75","size":"93"},{"price":"0.74","size":"96.6"},{"price":"0.73","size":"59.3"},{"price":"0.72","size":"103"},{"price":"0.71","size":"56.88"},{"price":"0.7","size":"56"},{"price":"0.69","size":"99.1"},{"price":"0.68","size":"54.18"},{"price":"0.67","size":"53.5"},{"price":"0.66","size":"95.79"},{"price":"0.65","size":"51.1"},{"price":"0.64","size":"50.58"},{"price":"0.63","size":"80.1"},{"price":"0.62","size":"49.6"},{"price":"0.61","size":"49.09"},{"price":"0.6","size":"99.7"},{"price":"0.59","size":"150.3"},{"price":"0.58","size":"147.09"},{"price":"0.57","size":"164.8"},{"price":"0.56","size":"133.6"},{"price":"0.55","size":"133.5"},{"price":"0.54","size":"77.6"},{"price":"0.53","size":"47.5"},{"price":"0.52","size":"41.02"},{"price":"0.51","size":"71"},{"price":"0.5","size":"41"},{"price":"0.49","size":"111"},{"price":"0.48","size":"66"},{"price":"0.47","size":"64.15"},{"price":"0.46","size":"95"},{"price":"0.45","size":"59.05"},{"price":"0.43","size":"10.71"},{"price":"0.42","size":"90"},{"price":"0.41","size":"103.93"},{"price":"0.4","size":"50.57"}],"asset_id":"96283536366176669581486355171583722558858323126916278856549586825357358273536","bids":[{"price":"0.01","size":"8309.52"},{"price":"0.02","size":"1345.79"},{"price":"0.03","size":"1154.13"},{"price":"0.04","size":"973.5"},{"price":"0.05","size":"921"},{"price":"0.06","size":"716.09"},{"price":"0.07","size":"661.2"},{"price":"0.08","size":"642.59"},{"price":"0.09","size":"658.1"},{"price":"0.1","size":"130.6"},{"price":"0.11","size":"120.29"},{"price":"0.12","size":"141.4"},{"price":"0.13","size":"103.9"},{"price":"0.14","size":"97.2"},{"price":"0.15","size":"122.39"},{"price":"0.16","size":"92.1"},{"price":"0.17","size":"83.29"},{"price":"0.18","size":"109.1"},{"price":"0.19","size":"76.19"},{"price":"0.2","size":"78.6"},{"price":"0.21","size":"115.82"},{"price":"0.22","size":"82.28"},{"price":"0.23","size":"79.99"},{"price":"0.24","size":"182.97"},{"price":"0.25","size":"69.93"},{"price":"0.26","size":"165.6"},{"price":"0.27","size":"164.3"},{"price":"0.28","size":"93"},{"price":"0.29","size":"66.88"},{"price":"0.3","size":"223"},{"price":"0.31","size":"146.1"},{"price":"0.32","size":"120.88"},{"price":"0.33","size":"96.1"},{"price":"0.34","size":"63.39"},{"price":"0.35","size":"56.1"},{"price":"0.36","size":"55.89"},{"price":"0.37","size":"40.7"},{"price":"0.38","size":"39.6"},{"price":"0.39","size":"43"}],"event_type":"book","hash":"edd17142d998a7b2a5f4fe246058cfb2c1995c0e","market":"0xf9d60bb033695053c4d1d8592e52171c1042f64b41a4b72e09dcc6f4852b6670","timestamp":"1785121949964"},"payload_hash":"859605018f186d6de3cf71cf13a4740ce07de33a518c03aaaed215ad30e85ba1","raw_frame":"{\"market\":\"0xf9d60bb033695053c4d1d8592e52171c1042f64b41a4b72e09dcc6f4852b6670\", \"asset_id\":\"96283536366176669581486355171583722558858323126916278856549586825357358273536\", \"bids\":[{\"price\":\"0.01\", \"size\":\"8309.52\"}, {\"price\":\"0.02\", \"size\":\"1345.79\"}, {\"price\":\"0.03\", \"size\":\"1154.13\"}, {\"price\":\"0.04\", \"size\":\"973.5\"}, {\"price\":\"0.05\", \"size\":\"921\"}, {\"price\":\"0.06\", \"size\":\"716.09\"}, {\"price\":\"0.07\", \"size\":\"661.2\"}, {\"price\":\"0.08\", \"size\":\"642.59\"}, {\"price\":\"0.09\", \"size\":\"658.1\"}, {\"price\":\"0.1\", \"size\":\"130.6\"}, {\"price\":\"0.11\", \"size\":\"120.29\"}, {\"price\":\"0.12\", \"size\":\"141.4\"}, {\"price\":\"0.13\", \"size\":\"103.9\"}, {\"price\":\"0.14\", \"size\":\"97.2\"}, {\"price\":\"0.15\", \"size\":\"122.39\"}, {\"price\":\"0.16\", \"size\":\"92.1\"}, {\"price\":\"0.17\", \"size\":\"83.29\"}, {\"price\":\"0.18\", \"size\":\"109.1\"}, {\"price\":\"0.19\", \"size\":\"76.19\"}, {\"price\":\"0.2\", \"size\":\"78.6\"}, {\"price\":\"0.21\", \"size\":\"115.82\"}, {\"price\":\"0.22\", \"size\":\"82.28\"}, {\"price\":\"0.23\", \"size\":\"79.99\"}, {\"price\":\"0.24\", \"size\":\"182.97\"}, {\"price\":\"0.25\", \"size\":\"69.93\"}, {\"price\":\"0.26\", \"size\":\"165.6\"}, {\"price\":\"0.27\", \"size\":\"164.3\"}, {\"price\":\"0.28\", \"size\":\"93\"}, {\"price\":\"0.29\", \"size\":\"66.88\"}, {\"price\":\"0.3\", \"size\":\"223\"}, {\"price\":\"0.31\", \"size\":\"146.1\"}, {\"price\":\"0.32\", \"size\":\"120.88\"}, {\"price\":\"0.33\", \"size\":\"96.1\"}, {\"price\":\"0.34\", \"size\":\"63.39\"}, {\"price\":\"0.35\", \"size\":\"56.1\"}, {\"price\":\"0.36\", \"size\":\"55.89\"}, {\"price\":\"0.37\", \"size\":\"40.7\"}, {\"price\":\"0.38\", \"size\":\"39.6\"}, {\"price\":\"0.39\", \"size\":\"43\"}], \"asks\":[{\"price\":\"0.99\", \"size\":\"7922.52\"}, {\"price\":\"0.98\", \"size\":\"1345.79\"}, {\"price\":\"0.97\", \"size\":\"1070.8\"}, {\"price\":\"0.96\", \"size\":\"1081.5\"}, {\"price\":\"0.95\", \"size\":\"987\"}, {\"price\":\"0.94\", \"size\":\"908.09\"}, {\"price\":\"0.93\", \"size\":\"456.2\"}, {\"price\":\"0.92\", \"size\":\"168.65\"}, {\"price\":\"0.91\", \"size\":\"343.1\"}, {\"price\":\"0.9\", \"size\":\"403.6\"}, {\"price\":\"0.89\", \"size\":\"120.29\"}, {\"price\":\"0.88\", \"size\":\"139.4\"}, {\"price\":\"0.87\", \"size\":\"133.9\"}, {\"price\":\"0.86\", \"size\":\"97.2\"}, {\"price\":\"0.85\", \"size\":\"116.39\"}, {\"price\":\"0.84\", \"size\":\"117.1\"}, {\"price\":\"0.83\", \"size\":\"104.29\"}, {\"price\":\"0.82\", \"size\":\"83.89\"}, {\"price\":\"0.81\", \"size\":\"106.19\"}, {\"price\":\"0.8\", \"size\":\"120.6\"}, {\"price\":\"0.79\", \"size\":\"71.3\"}, {\"price\":\"0.78\", \"size\":\"115.2\"}, {\"price\":\"0.77\", \"size\":\"71.3\"}, {\"price\":\"0.76\", \"size\":\"85.6\"}, {\"price\":\"0.75\", \"size\":\"93\"}, {\"price\":\"0.74\", \"size\":\"96.6\"}, {\"price\":\"0.73\", \"size\":\"59.3\"}, {\"price\":\"0.72\", \"size\":\"103\"}, {\"price\":\"0.71\", \"size\":\"56.88\"}, {\"price\":\"0.7\", \"size\":\"56\"}, {\"price\":\"0.69\", \"size\":\"99.1\"}, {\"price\":\"0.68\", \"size\":\"54.18\"}, {\"price\":\"0.67\", \"size\":\"53.5\"}, {\"price\":\"0.66\", \"size\":\"95.79\"}, {\"price\":\"0.65\", \"size\":\"51.1\"}, {\"price\":\"0.64\", \"size\":\"50.58\"}, {\"price\":\"0.63\", \"size\":\"80.1\"}, {\"price\":\"0.62\", \"size\":\"49.6\"}, {\"price\":\"0.61\", \"size\":\"49.09\"}, {\"price\":\"0.6\", \"size\":\"99.7\"}, {\"price\":\"0.59\", \"size\":\"150.3\"}, {\"price\":\"0.58\", \"size\":\"147.09\"}, {\"price\":\"0.57\", \"size\":\"164.8\"}, {\"price\":\"0.56\", \"size\":\"133.6\"}, {\"price\":\"0.55\", \"size\":\"133.5\"}, {\"price\":\"0.54\", \"size\":\"77.6\"}, {\"price\":\"0.53\", \"size\":\"47.5\"}, {\"price\":\"0.52\", \"size\":\"41.02\"}, {\"price\":\"0.51\", \"size\":\"71\"}, {\"price\":\"0.5\", \"size\":\"41\"}, {\"price\":\"0.49\", \"size\":\"111\"}, {\"price\":\"0.48\", \"size\":\"66\"}, {\"price\":\"0.47\", \"size\":\"64.15\"}, {\"price\":\"0.46\", \"size\":\"95\"}, {\"price\":\"0.45\", \"size\":\"59.05\"}, {\"price\":\"0.43\", \"size\":\"10.71\"}, {\"price\":\"0.42\", \"size\":\"90\"}, {\"price\":\"0.41\", \"size\":\"103.93\"}, {\"price\":\"0.4\", \"size\":\"50.57\"}], \"hash\":\"edd17142d998a7b2a5f4fe246058cfb2c1995c0e\", \"timestamp\":\"1785121949964\", \"event_type\":\"book\"}","received_at":"2026-07-27T03:12:29.878602Z","schema_version":"clob-market-ws.book.v1","sequence":null,"server_hash":"edd17142d998a7b2a5f4fe246058cfb2c1995c0e","server_timestamp":"1785121949964","session_id":"ff6d21c8283948938400a32613abec2c","source":"clob_market_ws"},"received_at":"2026-07-27T03:12:29.878602Z","record_id":"ad2063f2081c634a521bb71b8fa9c57c1d900a97b60269e46889654a8a29ceda","schema_fingerprint":"dc2caa1c89c6a7426e2e07ff925910cd4d0a8a223a515d4092d91d6d127aacb6","schema_version":"edge-lab-recorder.raw.v1","sequence":null,"source":"clob_market_ws"}
{"event_at":"2026-07-27T03:12:29.976000Z","event_fingerprint":"10512ec83d0c302bc3f9dc06fdb394bdfa79f24df3214e8217e3a672875c74da","payload":{"connection_id":"f95883f18d264834af91809e5f803e9f","event_at":"2026-07-27T03:12:29.976000Z","event_type":"price_change","frame_hash":"0d541b89ef1210bed9b9fe2078804e28cbd11d3058d78a6a979b56a5ee1fe5b1","frame_index":0,"kind":"data","monotonic_ns":223933219889500,"payload":{"event_type":"price_change","market":"0xf9d60bb033695053c4d1d8592e52171c1042f64b41a4b72e09dcc6f4852b6670","price_changes":[{"asset_id":"96283536366176669581486355171583722558858323126916278856549586825357358273536","best_ask":"0.4","best_bid":"0.39","hash":"436311e97516634186b17c1665d47b88dbcb3ac5","price":"0.36","side":"BUY","size":"60.89"},{"asset_id":"8698449539441374295770236407991735029336433231649246775082939325523552031992","best_ask":"0.61","best_bid":"0.6","hash":"0e2ea441d60480f4599aec802bb85d4e595f8fcd","price":"0.64","side":"SELL","size":"60.89"}],"timestamp":"1785121949976"},"payload_hash":"8d6ad24d4d7ead960935c10f09ece2b042bf76347cd5e1246fb9c49299821da8","raw_frame":"{\"market\":\"0xf9d60bb033695053c4d1d8592e52171c1042f64b41a4b72e09dcc6f4852b6670\", \"price_changes\":[{\"asset_id\":\"96283536366176669581486355171583722558858323126916278856549586825357358273536\", \"price\":\"0.36\", \"size\":\"60.89\", \"side\":\"BUY\", \"hash\":\"436311e97516634186b17c1665d47b88dbcb3ac5\", \"best_bid\":\"0.39\", \"best_ask\":\"0.4\"}, {\"asset_id\":\"8698449539441374295770236407991735029336433231649246775082939325523552031992\", \"price\":\"0.64\", \"size\":\"60.89\", \"side\":\"SELL\", \"hash\":\"0e2ea441d60480f4599aec802bb85d4e595f8fcd\", \"best_bid\":\"0.6\", \"best_ask\":\"0.61\"}], \"timestamp\":\"1785121949976\", \"event_type\":\"price_change\"}","received_at":"2026-07-27T03:12:29.888327Z","schema_version":"clob-market-ws.price_change.v1","sequence":null,"server_hash":null,"server_timestamp":"1785121949976","session_id":"ff6d21c8283948938400a32613abec2c","source":"clob_market_ws"},"received_at":"2026-07-27T03:12:29.888327Z","record_id":"33bde25e69cbfc919581879815cdc3b07a5fa1653930d212fd79b1f8c2ba191c","schema_fingerprint":"4aa3821a28b0b7c2400bc59aba4bcc0a76e971dadd19610d3ad38c768e124dc7","schema_version":"edge-lab-recorder.raw.v1","sequence":null,"source":"clob_market_ws"}
{"event_at":"2026-07-27T03:12:30.019000Z","event_fingerprint":"b8464bfbf4d092afe7aff49bfe5ab4ff63deaa200d3cad98a7be8144ee3b40cd","payload":{"connection_id":"f95883f18d264834af91809e5f803e9f","event_at":"2026-07-27T03:12:30.019000Z","event_type":"price_change","frame_hash":"856d87bf279e4006b9fdefa7e208a64f0d179c2d113e25bc85fb930d56aeab01","frame_index":0,"kind":"data","monotonic_ns":223933250386833,"payload":{"event_type":"price_change","market":"0xf9d60bb033695053c4d1d8592e52171c1042f64b41a4b72e09dcc6f4852b6670","price_changes":[{"asset_id":"96283536366176669581486355171583722558858323126916278856549586825357358273536","best_ask":"0.4","best_bid":"0.39","hash":"ebaa464ef7ae737051edeeb41c7d683aa6d22a0d","price":"0.01","side":"BUY","size":"8314.52"},{"asset_id":"8698449539441374295770236407991735029336433231649246775082939325523552031992","best_ask":"0.61","best_bid":"0.6","hash":"be885ee7a8306f74e7fb4b3952913b633f14e2f3","price":"0.99","side":"SELL","size":"8314.52"}],"timestamp":"1785121950019"},"payload_hash":"59589a9cfb221fd5b0bafa754e3dcd7d86e5b795fed65630059b80510bfd2cf0","raw_frame":"{\"market\":\"0xf9d60bb033695053c4d1d8592e52171c1042f64b41a4b72e09dcc6f4852b6670\", \"price_changes\":[{\"asset_id\":\"96283536366176669581486355171583722558858323126916278856549586825357358273536\", \"price\":\"0.01\", \"size\":\"8314.52\", \"side\":\"BUY\", \"hash\":\"ebaa464ef7ae737051edeeb41c7d683aa6d22a0d\", \"best_bid\":\"0.39\", \"best_ask\":\"0.4\"}, {\"asset_id\":\"8698449539441374295770236407991735029336433231649246775082939325523552031992\", \"price\":\"0.99\", \"size\":\"8314.52\", \"side\":\"SELL\", \"hash\":\"be885ee7a8306f74e7fb4b3952913b633f14e2f3\", \"best_bid\":\"0.6\", \"best_ask\":\"0.61\"}], \"timestamp\":\"1785121950019\", \"event_type\":\"price_change\"}","received_at":"2026-07-27T03:12:29.918821Z","schema_version":"clob-market-ws.price_change.v1","sequence":null,"server_hash":null,"server_timestamp":"1785121950019","session_id":"ff6d21c8283948938400a32613abec2c","source":"clob_market_ws"},"received_at":"2026-07-27T03:12:29.918821Z","record_id":"3fb3f731702e530ccf261948897b9c850dec339b7f2df9c63fd39e222b858f76","schema_fingerprint":"4aa3821a28b0b7c2400bc59aba4bcc0a76e971dadd19610d3ad38c768e124dc7","schema_version":"edge-lab-recorder.raw.v1","sequence":null,"source":"clob_market_ws"}
{"event_at":"2026-07-27T03:12:30.021000Z","event_fingerprint":"174a9d95a3fcc107f359a7f5a44998ee4ee52c387eb212e2b62f25a9feaac197","payload":{"connection_id":"f95883f18d264834af91809e5f803e9f","event_at":"2026-07-27T03:12:30.021000Z","event_type":"price_change","frame_hash":"1c328bcf44f3b34d905995c1b1a9ecdaf83d50e777e4006d0d64b67b2de5defc","frame_index":0,"kind":"data","monotonic_ns":223933252681000,"payload":{"event_type":"price_change","market":"0xf9d60bb033695053c4d1d8592e52171c1042f64b41a4b72e09dcc6f4852b6670","price_changes":[{"asset_id":"96283536366176669581486355171583722558858323126916278856549586825357358273536","best_ask":"0.4","best_bid":"0.39","hash":"d359a4d29d23b27cf336990f2f6d5edefc5c9037","price":"0.01","side":"BUY","size":"8319.52"},{"asset_id":"8698449539441374295770236407991735029336433231649246775082939325523552031992","best_ask":"0.61","best_bid":"0.6","hash":"802673c548cbbb25605a922c8e2b9c07bfb372bf","price":"0.99","side":"SELL","size":"8319.52"}],"timestamp":"1785121950021"},"payload_hash":"c8345f2d2160f9e81883b831fba31a85f60e8a8551d5548a8fe9f2c2259387cb","raw_frame":"{\"market\":\"0xf9d60bb033695053c4d1d8592e52171c1042f64b41a4b72e09dcc6f4852b6670\", \"price_changes\":[{\"asset_id\":\"96283536366176669581486355171583722558858323126916278856549586825357358273536\", \"price\":\"0.01\", \"size\":\"8319.52\", \"side\":\"BUY\", \"hash\":\"d359a4d29d23b27cf336990f2f6d5edefc5c9037\", \"best_bid\":\"0.39\", \"best_ask\":\"0.4\"}, {\"asset_id\":\"8698449539441374295770236407991735029336433231649246775082939325523552031992\", \"price\":\"0.99\", \"size\":\"8319.52\", \"side\":\"SELL\", \"hash\":\"802673c548cbbb25605a922c8e2b9c07bfb372bf\", \"best_bid\":\"0.6\", \"best_ask\":\"0.61\"}], \"timestamp\":\"1785121950021\", \"event_type\":\"price_change\"}","received_at":"2026-07-27T03:12:29.921116Z","schema_version":"clob-market-ws.price_change.v1","sequence":null,"server_hash":null,"server_timestamp":"1785121950021","session_id":"ff6d21c8283948938400a32613abec2c","source":"clob_market_ws"},"received_at":"2026-07-27T03:12:29.921116Z","record_id":"8f35f95f3610f0d798e68634c6a6fdce0d41fcba656cd3d397c2b4c2db446244","schema_fingerprint":"4aa3821a28b0b7c2400bc59aba4bcc0a76e971dadd19610d3ad38c768e124dc7","schema_version":"edge-lab-recorder.raw.v1","sequence":null,"source":"clob_market_ws"}
{"event_at":"2026-07-27T03:12:30.027000Z","event_fingerprint":"cd6280afac6a5c6710172bc681d9b4c76913292580074b329bc4d7d811df3d4d","payload":{"connection_id":"f95883f18d264834af91809e5f803e9f","event_at":"2026-07-27T03:12:30.027000Z","event_type":"price_change","frame_hash":"a9959c938ecd048155f9fb804ccaa4e48ac2384936e26049ba059888df8c0fdc","frame_index":0,"kind":"data","monotonic_ns":223933258715708,"payload":{"event_type":"price_change","market":"0xf9d60bb033695053c4d1d8592e52171c1042f64b41a4b72e09dcc6f4852b6670","price_changes":[{"asset_id":"8698449539441374295770236407991735029336433231649246775082939325523552031992","best_ask":"0.61","best_bid":"0.6","hash":"67b34e0a39a3d0edbf138f705b3fce2f7b88d057","price":"0.51","side":"BUY","size":"86"},{"asset_id":"96283536366176669581486355171583722558858323126916278856549586825357358273536","best_ask":"0.4","best_bid":"0.39","hash":"29b17bc1fd911d900380fa9cdaaf86203ce8f53b","price":"0.49","side":"SELL","size":"86"}],"timestamp":"1785121950027"},"payload_hash":"bab9c80a25c554ab59fd8e614bb16ac704c54598fc9dadcafe396dc02e457edc","raw_frame":"{\"market\":\"0xf9d60bb033695053c4d1d8592e52171c1042f64b41a4b72e09dcc6f4852b6670\", \"price_changes\":[{\"asset_id\":\"8698449539441374295770236407991735029336433231649246775082939325523552031992\", \"price\":\"0.51\", \"size\":\"86\", \"side\":\"BUY\", \"hash\":\"67b34e0a39a3d0edbf138f705b3fce2f7b88d057\", \"best_bid\":\"0.6\", \"best_ask\":\"0.61\"}, {\"asset_id\":\"96283536366176669581486355171583722558858323126916278856549586825357358273536\", \"price\":\"0.49\", \"size\":\"86\", \"side\":\"SELL\", \"hash\":\"29b17bc1fd911d900380fa9cdaaf86203ce8f53b\", \"best_bid\":\"0.39\", \"best_ask\":\"0.4\"}], \"timestamp\":\"1785121950027\", \"event_type\":\"price_change\"}","received_at":"2026-07-27T03:12:29.927152Z","schema_version":"clob-market-ws.price_change.v1","sequence":null,"server_hash":null,"server_timestamp":"1785121950027","session_id":"ff6d21c8283948938400a32613abec2c","source":"clob_market_ws"},"received_at":"2026-07-27T03:12:29.927152Z","record_id":"acbebbde70a15f68ea07ce70e2733a19f64e5ce311261303bea1585dad10a42b","schema_fingerprint":"4aa3821a28b0b7c2400bc59aba4bcc0a76e971dadd19610d3ad38c768e124dc7","schema_version":"edge-lab-recorder.raw.v1","sequence":null,"source":"clob_market_ws"}
{"event_at":"2026-07-27T03:12:30.027000Z","event_fingerprint":"b937947117dca77e64002f5bedc5a299838277b7dd4e4d769f2cb228fff45230","payload":{"connection_id":"f95883f18d264834af91809e5f803e9f","event_at":"2026-07-27T03:12:30.027000Z","event_type":"price_change","frame_hash":"13a090ea0e590c2c423d01d8d80873273371f0fe53061a4b99b931759ff8b409","frame_index":0,"kind":"data","monotonic_ns":223933260276500,"payload":{"event_type":"price_change","market":"0xf9d60bb033695053c4d1d8592e52171c1042f64b41a4b72e09dcc6f4852b6670","price_changes":[{"asset_id":"96283536366176669581486355171583722558858323126916278856549586825357358273536","best_ask":"0.4","best_bid":"0.39","hash":"29b17bc1fd911d900380fa9cdaaf86203ce8f53b","price":"0.35","side":"BUY","size":"31.1"},{"asset_id":"8698449539441374295770236407991735029336433231649246775082939325523552031992","best_ask":"0.61","best_bid":"0.6","hash":"67b34e0a39a3d0edbf138f705b3fce2f7b88d057","price":"0.65","side":"SELL","size":"31.1"}],"timestamp":"1785121950027"},"payload_hash":"62a9b684fbc4db5e88bf2a47d61b0085ed94e8df959e8f5ef99e907cad6f6fd9","raw_frame":"{\"market\":\"0xf9d60bb033695053c4d1d8592e52171c1042f64b41a4b72e09dcc6f4852b6670\", \"price_changes\":[{\"asset_id\":\"96283536366176669581486355171583722558858323126916278856549586825357358273536\", \"price\":\"0.35\", \"size\":\"31.1\", \"side\":\"BUY\", \"hash\":\"29b17bc1fd911d900380fa9cdaaf86203ce8f53b\", \"best_bid\":\"0.39\", \"best_ask\":\"0.4\"}, {\"asset_id\":\"8698449539441374295770236407991735029336433231649246775082939325523552031992\", \"price\":\"0.65\", \"size\":\"31.1\", \"side\":\"SELL\", \"hash\":\"67b34e0a39a3d0edbf138f705b3fce2f7b88d057\", \"best_bid\":\"0.6\", \"best_ask\":\"0.61\"}], \"timestamp\":\"1785121950027\", \"event_type\":\"price_change\"}","received_at":"2026-07-27T03:12:29.928715Z","schema_version":"clob-market-ws.price_change.v1","sequence":null,"server_hash":null,"server_timestamp":"1785121950027","session_id":"ff6d21c8283948938400a32613abec2c","source":"clob_market_ws"},"received_at":"2026-07-27T03:12:29.928715Z","record_id":"34c18908e700361632d0202ecbc9aa538f456e171f1c172959077a46952c8572","schema_fingerprint":"4aa3821a28b0b7c2400bc59aba4bcc0a76e971dadd19610d3ad38c768e124dc7","schema_version":"edge-lab-recorder.raw.v1","sequence":null,"source":"clob_market_ws"}
{"event_at":"2026-07-27T03:12:30.030000Z","event_fingerprint":"9e534519a8b79dbd5f224bc7910b5866d24a8b4b1b359bc7d9957738622e3ed8","payload":{"connection_id":"f95883f18d264834af91809e5f803e9f","event_at":"2026-07-27T03:12:30.030000Z","event_type":"price_change","frame_hash":"0a23a2de69b5395ce3b9682137f141aefca6ae45b47eb180138f5b2b0b35f2dd","frame_index":0,"kind":"data","monotonic_ns":223933262780875,"payload":{"event_type":"price_change","market":"0xf9d60bb033695053c4d1d8592e52171c1042f64b41a4b72e09dcc6f4852b6670","price_changes":[{"asset_id":"8698449539441374295770236407991735029336433231649246775082939325523552031992","best_ask":"0.61","best_bid":"0.6","hash":"4622d10ca6737df0f5f6466445a91f30ad535a89","price":"0.51","side":"BUY","size":"61"},{"asset_id":"96283536366176669581486355171583722558858323126916278856549586825357358273536","best_ask":"0.4","best_bid":"0.39","hash":"b3ba49be7c9524c506b400029f2e9caff659e4e7","price":"0.49","side":"SELL","size":"61"}],"timestamp":"1785121950030"},"payload_hash":"38323b191138263f4bffeb81706106b2269db47b0d220f9a7f51caf4406095f7","raw_frame":"{\"market\":\"0xf9d60bb033695053c4d1d8592e52171c1042f64b41a4b72e09dcc6f4852b6670\", \"price_changes\":[{\"asset_id\":\"8698449539441374295770236407991735029336433231649246775082939325523552031992\", \"price\":\"0.51\", \"size\":\"61\", \"side\":\"BUY\", \"hash\":\"4622d10ca6737df0f5f6466445a91f30ad535a89\", \"best_bid\":\"0.6\", \"best_ask\":\"0.61\"}, {\"asset_id\":\"96283536366176669581486355171583722558858323126916278856549586825357358273536\", \"price\":\"0.49\", \"size\":\"61\", \"side\":\"SELL\", \"hash\":\"b3ba49be7c9524c506b400029f2e9caff659e4e7\", \"best_bid\":\"0.39\", \"best_ask\":\"0.4\"}], \"timestamp\":\"1785121950030\", \"event_type\":\"price_change\"}","received_at":"2026-07-27T03:12:29.931214Z","schema_version":"clob-market-ws.price_change.v1","sequence":null,"server_hash":null,"server_timestamp":"1785121950030","session_id":"ff6d21c8283948938400a32613abec2c","source":"clob_market_ws"},"received_at":"2026-07-27T03:12:29.931214Z","record_id":"e7e080a08336e6fff908182fc377de124c115cc978e68eac9e6482df872d2084","schema_fingerprint":"4aa3821a28b0b7c2400bc59aba4bcc0a76e971dadd19610d3ad38c768e124dc7","schema_version":"edge-lab-recorder.raw.v1","sequence":null,"source":"clob_market_ws"}
{"event_at":"2026-07-27T03:12:30.030000Z","event_fingerprint":"b89ef3f4d5e6bb1ce8a103ffd75242cc7ec0d5d8a880252ceee7bd604f82d778","payload":{"connection_id":"f95883f18d264834af91809e5f803e9f","event_at":"2026-07-27T03:12:30.030000Z","event_type":"price_change","frame_hash":"5235e38261a97059ab6324e5b5b2c7edaf298fbbe9388f928060b6ccd2d24a11","frame_index":0,"kind":"data","monotonic_ns":223933264401958,"payload":{"event_type":"price_change","market":"0xf9d60bb033695053c4d1d8592e52171c1042f64b41a4b72e09dcc6f4852b6670","price_changes":[{"asset_id":"96283536366176669581486355171583722558858323126916278856549586825357358273536","best_ask":"0.4","best_bid":"0.39","hash":"b3ba49be7c9524c506b400029f2e9caff659e4e7","price":"0.34","side":"BUY","size":"38.39"},{"asset_id":"8698449539441374295770236407991735029336433231649246775082939325523552031992","best_ask":"0.61","best_bid":"0.6","hash":"4622d10ca6737df0f5f6466445a91f30ad535a89","price":"0.66","side":"SELL","size":"38.39"}],"timestamp":"1785121950030"},"payload_hash":"27e341c51a58ec9edb0492a7c32effd9f4a9ea9ed402bc1fab3e8405a974493a","raw_frame":"{\"market\":\"0xf9d60bb033695053c4d1d8592e52171c1042f64b41a4b72e09dcc6f4852b6670\", \"price_changes\":[{\"asset_id\":\"96283536366176669581486355171583722558858323126916278856549586825357358273536\", \"price\":\"0.34\", \"size\":\"38.39\", \"side\":\"BUY\", \"hash\":\"b3ba49be7c9524c506b400029f2e9caff659e4e7\", \"best_bid\":\"0.39\", \"best_ask\":\"0.4\"}, {\"asset_id\":\"8698449539441374295770236407991735029336433231649246775082939325523552031992\", \"price\":\"0.66\", \"size\":\"38.39\", \"side\":\"SELL\", \"hash\":\"4622d10ca6737df0f5f6466445a91f30ad535a89\", \"best_bid\":\"0.6\", \"best_ask\":\"0.61\"}], \"timestamp\":\"1785121950030\", \"event_type\":\"price_change\"}","received_at":"2026-07-27T03:12:29.932840Z","schema_version":"clob-market-ws.price_change.v1","sequence":null,"server_hash":null,"server_timestamp":"1785121950030","session_id":"ff6d21c8283948938400a32613abec2c","source":"clob_market_ws"},"received_at":"2026-07-27T03:12:29.932840Z","record_id":"3c34b580e5e1f5efac579ee34d1f241205ec1a26131469cdfa5a753b9bdddfb3","schema_fingerprint":"4aa3821a28b0b7c2400bc59aba4bcc0a76e971dadd19610d3ad38c768e124dc7","schema_version":"edge-lab-recorder.raw.v1","sequence":null,"source":"clob_market_ws"}
{"event_at":"2026-07-27T03:12:30.039000Z","event_fingerprint":"abaead349c06a3d2dde1f52f07336e75ce520977b19ba94bb3688586641b6aad","payload":{"connection_id":"f95883f18d264834af91809e5f803e9f","event_at":"2026-07-27T03:12:30.039000Z","event_type":"price_change","frame_hash":"53c187acc6a41f5ff5135d7285e48135f7d677737c5c0754190fe2e158340d46","frame_index":0,"kind":"data","monotonic_ns":223933272370041,"payload":{"event_type":"price_change","market":"0xf9d60bb033695053c4d1d8592e52171c1042f64b41a4b72e09dcc6f4852b6670","price_changes":[{"asset_id":"96283536366176669581486355171583722558858323126916278856549586825357358273536","best_ask":"0.4","best_bid":"0.39","hash":"be576ce6a5b2ff600a4e0cf70b16f3778caa3292","price":"0.01","side":"BUY","size":"8314.52"},{"asset_id":"8698449539441374295770236407991735029336433231649246775082939325523552031992","best_ask":"0.61","best_bid":"0.6","hash":"4e5217c9e0b89b614fd8f08a03bda40470e8d6c2","price":"0.99","side":"SELL","size":"8314.52"}],"timestamp":"1785121950039"},"payload_hash":"f6824b9da4332c0d90f4c8d0b8aa7c0cfa9fb5d4848bd672da6d381be0e8c9f1","raw_frame":"{\"market\":\"0xf9d60bb033695053c4d1d8592e52171c1042f64b41a4b72e09dcc6f4852b6670\", \"price_changes\":[{\"asset_id\":\"96283536366176669581486355171583722558858323126916278856549586825357358273536\", \"price\":\"0.01\", \"size\":\"8314.52\", \"side\":\"BUY\", \"hash\":\"be576ce6a5b2ff600a4e0cf70b16f3778caa3292\", \"best_bid\":\"0.39\", \"best_ask\":\"0.4\"}, {\"asset_id\":\"8698449539441374295770236407991735029336433231649246775082939325523552031992\", \"price\":\"0.99\", \"size\":\"8314.52\", \"side\":\"SELL\", \"hash\":\"4e5217c9e0b89b614fd8f08a03bda40470e8d6c2\", \"best_bid\":\"0.6\", \"best_ask\":\"0.61\"}], \"timestamp\":\"1785121950039\", \"event_type\":\"price_change\"}","received_at":"2026-07-27T03:12:29.940806Z","schema_version":"clob-market-ws.price_change.v1","sequence":null,"server_hash":null,"server_timestamp":"1785121950039","session_id":"ff6d21c8283948938400a32613abec2c","source":"clob_market_ws"},"received_at":"2026-07-27T03:12:29.940806Z","record_id":"8b70c8e35a7890810e3e3393fb91e54d28c7113231e59d7a3e5f698c7101a5e1","schema_fingerprint":"4aa3821a28b0b7c2400bc59aba4bcc0a76e971dadd19610d3ad38c768e124dc7","schema_version":"edge-lab-recorder.raw.v1","sequence":null,"source":"clob_market_ws"}
{"event_at":"2026-07-27T03:12:30.050000Z","event_fingerprint":"76f435b5ffdd0fabd3a7c4acc2e6ac84629911d17411a613d8a2550c61b2813e","payload":{"connection_id":"f95883f18d264834af91809e5f803e9f","event_at":"2026-07-27T03:12:30.050000Z","event_type":"price_change","frame_hash":"a6d77dda6da98b27f9de1dd12bca815a46659a799ac570260194977189b6cd77","frame_index":0,"kind":"data","monotonic_ns":223933283241625,"payload":{"event_type":"price_change","market":"0xf9d60bb033695053c4d1d8592e52171c1042f64b41a4b72e09dcc6f4852b6670","price_changes":[{"asset_id":"8698449539441374295770236407991735029336433231649246775082939325523552031992","best_ask":"0.61","best_bid":"0.6","hash":"f7d2a98e46327a4b98d709d7bdc781c8d7d74685","price":"0.01","side":"BUY","size":"7927.52"},{"asset_id":"96283536366176669581486355171583722558858323126916278856549586825357358273536","best_ask":"0.4","best_bid":"0.39","hash":"9e17c4adbd559125c9b7e4a8c247e928db4d5c58","price":"0.99","side":"SELL","size":"7927.52"}],"timestamp":"1785121950050"},"payload_hash":"74f0d2dcba7f3c0410785df2c2b130f9bc7ef9c84e0d3cf47b9548ed5c1e0eda","raw_frame":"{\"market\":\"0xf9d60bb033695053c4d1d8592e52171c1042f64b41a4b72e09dcc6f4852b6670\", \"price_changes\":[{\"asset_id\":\"8698449539441374295770236407991735029336433231649246775082939325523552031992\", \"price\":\"0.01\", \"size\":\"7927.52\", \"side\":\"BUY\", \"hash\":\"f7d2a98e46327a4b98d709d7bdc781c8d7d74685\", \"best_bid\":\"0.6\", \"best_ask\":\"0.61\"}, {\"asset_id\":\"96283536366176669581486355171583722558858323126916278856549586825357358273536\", \"price\":\"0.99\", \"size\":\"7927.52\", \"side\":\"SELL\", \"hash\":\"9e17c4adbd559125c9b7e4a8c247e928db4d5c58\", \"best_bid\":\"0.39\", \"best_ask\":\"0.4\"}], \"timestamp\":\"1785121950050\", \"event_type\":\"price_change\"}","received_at":"2026-07-27T03:12:29.951678Z","schema_version":"clob-market-ws.price_change.v1","sequence":null,"server_hash":null,"server_timestamp":"1785121950050","session_id":"ff6d21c8283948938400a32613abec2c","source":"clob_market_ws"},"received_at":"2026-07-27T03:12:29.951678Z","record_id":"e5de4f7f48632570827adee63e10f2809a873d5ddfa935f555043a5ac549edfe","schema_fingerprint":"4aa3821a28b0b7c2400bc59aba4bcc0a76e971dadd19610d3ad38c768e124dc7","schema_version":"edge-lab-recorder.raw.v1","sequence":null,"source":"clob_market_ws"}
{"event_at":"2026-07-27T03:12:30.060000Z","event_fingerprint":"a3865b53d94a84bee201a31f2544bbcb8154e1e8ef8c71550caf96e67c87ddde","payload":{"connection_id":"f95883f18d264834af91809e5f803e9f","event_at":"2026-07-27T03:12:30.060000Z","event_type":"last_trade_price","frame_hash":"e90b1528132f59feb5403812627c3f9832a7dd7f761a33ef6a8a7c7fc85bbf7a","frame_index":0,"kind":"data","monotonic_ns":223933296279916,"payload":{"asset_id":"96283536366176669581486355171583722558858323126916278856549586825357358273536","event_type":"last_trade_price","fee_rate_bps":"0","market":"0xf9d60bb033695053c4d1d8592e52171c1042f64b41a4b72e09dcc6f4852b6670","price":"0.4","side":"BUY","size":"4.2","timestamp":"1785121950060","transaction_hash":"0xd374a57536aeb76bedfeed6fab4c7db3b782c7d72ef2df794f4bb12d836ae6f6"},"payload_hash":"494df99d13cc5725bedb15a1e1834c1413b2d6857643f643281509c8afe7bcd1","raw_frame":"{\"market\":\"0xf9d60bb033695053c4d1d8592e52171c1042f64b41a4b72e09dcc6f4852b6670\", \"asset_id\":\"96283536366176669581486355171583722558858323126916278856549586825357358273536\", \"price\":\"0.4\", \"size\":\"4.2\", \"fee_rate_bps\":\"0\", \"side\":\"BUY\", \"timestamp\":\"1785121950060\", \"event_type\":\"last_trade_price\", \"transaction_hash\":\"0xd374a57536aeb76bedfeed6fab4c7db3b782c7d72ef2df794f4bb12d836ae6f6\"}","received_at":"2026-07-27T03:12:29.964714Z","schema_version":"clob-market-ws.last_trade_price.v1","sequence":null,"server_hash":null,"server_timestamp":"1785121950060","session_id":"ff6d21c8283948938400a32613abec2c","source":"clob_market_ws"},"received_at":"2026-07-27T03:12:29.964714Z","record_id":"9566ac4e8009ddb324010a30271cad220cbf2f5317e5adebdab625563ce052d9","schema_fingerprint":"95ad9be75a4b695cd99991e12b2592bc7346f3f5388a82d0000ba65bc0d9fd0a","schema_version":"edge-lab-recorder.raw.v1","sequence":null,"source":"clob_market_ws"}
{"event_at":"2026-07-27T03:12:30.068000Z","event_fingerprint":"636275e5d647d1d6ad26f8b179ca87bf99b3dbc3998b3e85caede482cea22454","payload":{"connection_id":"f95883f18d264834af91809e5f803e9f","event_at":"2026-07-27T03:12:30.068000Z","event_type":"price_change","frame_hash":"e758bae3e740e6bad783a3b74e19700de4c3985f9e26345a403cc873bc923a3a","frame_index":0,"kind":"data","monotonic_ns":223933299174250,"payload":{"event_type":"price_change","market":"0xf9d60bb033695053c4d1d8592e52171c1042f64b41a4b72e09dcc6f4852b6670","price_changes":[{"asset_id":"8698449539441374295770236407991735029336433231649246775082939325523552031992","best_ask":"0.61","best_bid":"0.6","hash":"20883f62e13e8bf82db8d46b8495ea93dcbd268d","price":"0.55","side":"BUY","size":"25"},{"asset_id":"96283536366176669581486355171583722558858323126916278856549586825357358273536","best_ask":"0.4","best_bid":"0.39","hash":"8c797a69b3b2df9e715c86bce019ba8e6f9b85ac","price":"0.45","side":"SELL","size":"25"}],"timestamp":"1785121950068"},"payload_hash":"0bcc188ae6a8bb4a57cae5a89403683f90cbd67758d4e9cd29f8fc24151667e5","raw_frame":"{\"market\":\"0xf9d60bb033695053c4d1d8592e52171c1042f64b41a4b72e09dcc6f4852b6670\", \"price_changes\":[{\"asset_id\":\"8698449539441374295770236407991735029336433231649246775082939325523552031992\", \"price\":\"0.55\", \"size\":\"25\", \"side\":\"BUY\", \"hash\":\"20883f62e13e8bf82db8d46b8495ea93dcbd268d\", \"best_bid\":\"0.6\", \"best_ask\":\"0.61\"}, {\"asset_id\":\"96283536366176669581486355171583722558858323126916278856549586825357358273536\", \"price\":\"0.45\", \"size\":\"25\", \"side\":\"SELL\", \"hash\":\"8c797a69b3b2df9e715c86bce019ba8e6f9b85ac\", \"best_bid\":\"0.39\", \"best_ask\":\"0.4\"}], \"timestamp\":\"1785121950068\", \"event_type\":\"price_change\"}","received_at":"2026-07-27T03:12:29.967617Z","schema_version":"clob-market-ws.price_change.v1","sequence":null,"server_hash":null,"server_timestamp":"1785121950068","session_id":"ff6d21c8283948938400a32613abec2c","source":"clob_market_ws"},"received_at":"2026-07-27T03:12:29.967617Z","record_id":"827572b1f0608d5b161c7804f34b53c4628fbaa25b520e03878765efd328ca5d","schema_fingerprint":"4aa3821a28b0b7c2400bc59aba4bcc0a76e971dadd19610d3ad38c768e124dc7","schema_version":"edge-lab-recorder.raw.v1","sequence":null,"source":"clob_market_ws"}
{"event_at":"2026-07-27T03:12:30.072000Z","event_fingerprint":"9a5150307415616a156127bc5451e94e3c0689624f6c430bfa27a7891710cd70","payload":{"connection_id":"f95883f18d264834af91809e5f803e9f","event_at":"2026-07-27T03:12:30.072000Z","event_type":"price_change","frame_hash":"cea981d226f18bffdd8dee303ec6645e5f0d12f1c60d5eb8ddc7fb983290f7d9","frame_index":0,"kind":"data","monotonic_ns":223933302152541,"payload":{"event_type":"price_change","market":"0xf9d60bb033695053c4d1d8592e52171c1042f64b41a4b72e09dcc6f4852b6670","price_changes":[{"asset_id":"8698449539441374295770236407991735029336433231649246775082939325523552031992","best_ask":"0.61","best_bid":"0.6","hash":"6fd400a455dfc697799726181ebaedf3af96e63e","price":"0.57","side":"BUY","size":"43.76"},{"asset_id":"96283536366176669581486355171583722558858323126916278856549586825357358273536","best_ask":"0.4","best_bid":"0.39","hash":"9319582eab731c25af1bbc711c783d23161aaebb","price":"0.43","side":"SELL","size":"43.76"}],"timestamp":"1785121950072"},"payload_hash":"3ff190dba68f041ed8c06a878d96a693db1c4fa009c0db710d35680bfd4b7a60","raw_frame":"{\"market\":\"0xf9d60bb033695053c4d1d8592e52171c1042f64b41a4b72e09dcc6f4852b6670\", \"price_changes\":[{\"asset_id\":\"8698449539441374295770236407991735029336433231649246775082939325523552031992\", \"price\":\"0.57\", \"size\":\"43.76\", \"side\":\"BUY\", \"hash\":\"6fd400a455dfc697799726181ebaedf3af96e63e\", \"best_bid\":\"0.6\", \"best_ask\":\"0.61\"}, {\"asset_id\":\"96283536366176669581486355171583722558858323126916278856549586825357358273536\", \"price\":\"0.43\", \"size\":\"43.76\", \"side\":\"SELL\", \"hash\":\"9319582eab731c25af1bbc711c783d23161aaebb\", \"best_bid\":\"0.39\", \"best_ask\":\"0.4\"}], \"timestamp\":\"1785121950072\", \"event_type\":\"price_change\"}","received_at":"2026-07-27T03:12:29.970596Z","schema_version":"clob-market-ws.price_change.v1","sequence":null,"server_hash":null,"server_timestamp":"1785121950072","session_id":"ff6d21c8283948938400a32613abec2c","source":"clob_market_ws"},"received_at":"2026-07-27T03:12:29.970596Z","record_id":"9e2dbf815a1ee22796e342d7e5970188ba21520e277df074962fc5f7016d4a17","schema_fingerprint":"4aa3821a28b0b7c2400bc59aba4bcc0a76e971dadd19610d3ad38c768e124dc7","schema_version":"edge-lab-recorder.raw.v1","sequence":null,"source":"clob_market_ws"}
{"event_at":"2026-07-27T03:12:30.082000Z","event_fingerprint":"eacf1ad02caa98d96eff097569cfd59f7673192ed344f1f110e0b7946dbc0de2","payload":{"connection_id":"f95883f18d264834af91809e5f803e9f","event_at":"2026-07-27T03:12:30.082000Z","event_type":"best_bid_ask","frame_hash":"9f795840278b6523ce4b4b794f3cda9a9b0bac6ddb0a374f2f5df83515d4a35f","frame_index":0,"kind":"data","monotonic_ns":223933315153041,"payload":{"asset_id":"8698449539441374295770236407991735029336433231649246775082939325523552031992","best_ask":"0.61","best_bid":"0.6","event_type":"best_bid_ask","market":"0xf9d60bb033695053c4d1d8592e52171c1042f64b41a4b72e09dcc6f4852b6670","spread":"0.01","timestamp":"1785121950082"},"payload_hash":"489f7d501dc8429c5cd75b83649c9e116b22ecc5a235170eadc4249e0feb4401","raw_frame":"{\"market\":\"0xf9d60bb033695053c4d1d8592e52171c1042f64b41a4b72e09dcc6f4852b6670\", \"asset_id\":\"8698449539441374295770236407991735029336433231649246775082939325523552031992\", \"best_bid\":\"0.6\", \"best_ask\":\"0.61\", \"spread\":\"0.01\", \"timestamp\":\"1785121950082\", \"event_type\":\"best_bid_ask\"}","received_at":"2026-07-27T03:12:29.983588Z","schema_version":"clob-market-ws.best_bid_ask.v1","sequence":null,"server_hash":null,"server_timestamp":"1785121950082","session_id":"ff6d21c8283948938400a32613abec2c","source":"clob_market_ws"},"received_at":"2026-07-27T03:12:29.983588Z","record_id":"064fcabef15c07903cba864032f55c46a361537267356a2c9493efb5e49a52d7","schema_fingerprint":"8488399f31b0337811b13b266be932db7062827c2470b78bd8e9e99bab51d17d","schema_version":"edge-lab-recorder.raw.v1","sequence":null,"source":"clob_market_ws"}
{"event_at":"2026-07-27T03:12:30.082000Z","event_fingerprint":"ffa730051de6a6c4039e0e2cbda03befb33a0dcfcfc9952f632fe26dbd690a1c","payload":{"connection_id":"f95883f18d264834af91809e5f803e9f","event_at":"2026-07-27T03:12:30.082000Z","event_type":"best_bid_ask","frame_hash":"af7e21dbd3c9d0ad15ae225443467bc4b2719fe537e82845e375b09ccf4d0363","frame_index":0,"kind":"data","monotonic_ns":223933316304583,"payload":{"asset_id":"96283536366176669581486355171583722558858323126916278856549586825357358273536","best_ask":"0.4","best_bid":"0.39","event_type":"best_bid_ask","market":"0xf9d60bb033695053c4d1d8592e52171c1042f64b41a4b72e09dcc6f4852b6670","spread":"0.01","timestamp":"1785121950082"},"payload_hash":"ccfb7de98a9e816d35319eaeeeee218e6cb2068d2927b6a8cb693c0b3c6ad6af","raw_frame":"{\"market\":\"0xf9d60bb033695053c4d1d8592e52171c1042f64b41a4b72e09dcc6f4852b6670\", \"asset_id\":\"96283536366176669581486355171583722558858323126916278856549586825357358273536\", \"best_bid\":\"0.39\", \"best_ask\":\"0.4\", \"spread\":\"0.01\", \"timestamp\":\"1785121950082\", \"event_type\":\"best_bid_ask\"}","received_at":"2026-07-27T03:12:29.984739Z","schema_version":"clob-market-ws.best_bid_ask.v1","sequence":null,"server_hash":null,"server_timestamp":"1785121950082","session_id":"ff6d21c8283948938400a32613abec2c","source":"clob_market_ws"},"received_at":"2026-07-27T03:12:29.984739Z","record_id":"054c0d229652c96e7eb940d5c41a0287157a1f10977e7972b4dd18b066934b9a","schema_fingerprint":"8488399f31b0337811b13b266be932db7062827c2470b78bd8e9e99bab51d17d","schema_version":"edge-lab-recorder.raw.v1","sequence":null,"source":"clob_market_ws"}
{"event_at":"2026-07-27T03:12:30.082000Z","event_fingerprint":"0a9630455167ba4bf82d86a17aa4291a444cc755b267ac370bd7b8ec8a87119c","payload":{"connection_id":"f95883f18d264834af91809e5f803e9f","event_at":"2026-07-27T03:12:30.082000Z","event_type":"price_change","frame_hash":"38f625ab501374068e2af2060084f198f37052e3a1af9959b549412389c053c8","frame_index":0,"kind":"data","monotonic_ns":223933318335541,"payload":{"event_type":"price_change","market":"0xf9d60bb033695053c4d1d8592e52171c1042f64b41a4b72e09dcc6f4852b6670","price_changes":[{"asset_id":"96283536366176669581486355171583722558858323126916278856549586825357358273536","best_ask":"0.4","best_bid":"0.39","hash":"567f4e8e317b7b07fec3c0fe31e20fd3e90efdad","price":"0.39","side":"BUY","size":"34.3"},{"asset_id":"8698449539441374295770236407991735029336433231649246775082939325523552031992","best_ask":"0.61","best_bid":"0.6","hash":"6b486e71fd137e2349e74f71212e0909efffcdb4","price":"0.61","side":"SELL","size":"34.3"}],"timestamp":"1785121950082"},"payload_hash":"2358fc12ab0cb89bbea8401dad53735d7e6a67c6d768cdf74c0cc78bf4152f06","raw_frame":"{\"market\":\"0xf9d60bb033695053c4d1d8592e52171c1042f64b41a4b72e09dcc6f4852b6670\", \"price_changes\":[{\"asset_id\":\"96283536366176669581486355171583722558858323126916278856549586825357358273536\", \"price\":\"0.39\", \"size\":\"34.3\", \"side\":\"BUY\", \"hash\":\"567f4e8e317b7b07fec3c0fe31e20fd3e90efdad\", \"best_bid\":\"0.39\", \"best_ask\":\"0.4\"}, {\"asset_id\":\"8698449539441374295770236407991735029336433231649246775082939325523552031992\", \"price\":\"0.61\", \"size\":\"34.3\", \"side\":\"SELL\", \"hash\":\"6b486e71fd137e2349e74f71212e0909efffcdb4\", \"best_bid\":\"0.6\", \"best_ask\":\"0.61\"}], \"timestamp\":\"1785121950082\", \"event_type\":\"price_change\"}","received_at":"2026-07-27T03:12:29.986769Z","schema_version":"clob-market-ws.price_change.v1","sequence":null,"server_hash":null,"server_timestamp":"1785121950082","session_id":"ff6d21c8283948938400a32613abec2c","source":"clob_market_ws"},"received_at":"2026-07-27T03:12:29.986769Z","record_id":"fae4c990cf8e7b0e4decf3bdb813c0536fa480757d45c10435dd5dbea0152e2a","schema_fingerprint":"4aa3821a28b0b7c2400bc59aba4bcc0a76e971dadd19610d3ad38c768e124dc7","schema_version":"edge-lab-recorder.raw.v1","sequence":null,"source":"clob_market_ws"}
{"event_at":"2026-07-27T03:12:30.082000Z","event_fingerprint":"39a87022d977e9e50fd82d4b52ffa5179e3c0efd0754564e6e48d8793aaf9705","payload":{"connection_id":"f95883f18d264834af91809e5f803e9f","event_at":"2026-07-27T03:12:30.082000Z","event_type":"book","frame_hash":"0b5e05ca3f4a8f275bde86bd5dfbdeb130c6073dbd019f1e000eab7a8acbf503","frame_index":0,"kind":"data","monotonic_ns":223933320195625,"payload":{"asks":[{"price":"0.99","size":"8314.52"},{"price":"0.98","size":"1345.79"},{"price":"0.97","size":"1154.13"},{"price":"0.96","size":"973.5"},{"price":"0.95","size":"921"},{"price":"0.94","size":"716.09"},{"price":"0.93","size":"661.2"},{"price":"0.92","size":"642.59"},{"price":"0.91","size":"658.1"},{"price":"0.9","size":"130.6"},{"price":"0.89","size":"120.29"},{"price":"0.88","size":"141.4"},{"price":"0.87","size":"103.9"},{"price":"0.86","size":"97.2"},{"price":"0.85","size":"122.39"},{"price":"0.84","size":"92.1"},{"price":"0.83","size":"83.29"},{"price":"0.82","size":"109.1"},{"price":"0.81","size":"76.19"},{"price":"0.8","size":"78.6"},{"price":"0.79","size":"115.82"},{"price":"0.78","size":"82.28"},{"price":"0.77","size":"79.99"},{"price":"0.76","size":"182.97"},{"price":"0.75","size":"69.93"},{"price":"0.74","size":"165.6"},{"price":"0.73","size":"164.3"},{"price":"0.72","size":"93"},{"price":"0.71","size":"66.88"},{"price":"0.7","size":"223"},{"price":"0.69","size":"146.1"},{"price":"0.68","size":"120.88"},{"price":"0.67","size":"96.1"},{"price":"0.66","size":"38.39"},{"price":"0.65","size":"31.1"},{"price":"0.64","size":"60.89"},{"price":"0.63","size":"40.7"},{"price":"0.62","size":"39.6"},{"price":"0.61","size":"34.3"}],"asset_id":"8698449539441374295770236407991735029336433231649246775082939325523552031992","bids":[{"price":"0.01","size":"7927.52"},{"price":"0.02","size":"1345.79"},{"price":"0.03","size":"1070.8"},{"price":"0.04","size":"1081.5"},{"price":"0.05","size":"987"},{"price":"0.06","size":"908.09"},{"price":"0.07","size":"456.2"},{"price":"0.08","size":"168.65"},{"price":"0.09","size":"343.1"},{"price":"0.1","size":"403.6"},{"price":"0.11","size":"120.29"},{"price":"0.12","size":"139.4"},{"price":"0.13","size":"133.9"},{"price":"0.14","size":"97.2"},{"price":"0.15","size":"116.39"},{"price":"0.16","size":"117.1"},{"price":"0.17","size":"104.29"},{"price":"0.18","size":"83.89"},{"price":"0.19","size":"106.19"},{"price":"0.2","size":"120.6"},{"price":"0.21","size":"71.3"},{"price":"0.22","size":"115.2"},{"price":"0.23","size":"71.3"},{"price":"0.24","size":"85.6"},{"price":"0.25","size":"93"},{"price":"0.26","size":"96.6"},{"price":"0.27","size":"59.3"},{"price":"0.28","size":"103"},{"price":"0.29","size":"56.88"},{"price":"0.3","size":"56"},{"price":"0.31","size":"99.1"},{"price":"0.32","size":"54.18"},{"price":"0.33","size":"53.5"},{"price":"0.34","size":"95.79"},{"price":"0.35","size":"51.1"},{"price":"0.36","size":"50.58"},{"price":"0.37","size":"80.1"},{"price":"0.38","size":"49.6"},{"price":"0.39","size":"49.09"},{"price":"0.4","size":"99.7"},{"price":"0.41","size":"150.3"},{"price":"0.42","size":"147.09"},{"price":"0.43","size":"164.8"},{"price":"0.44","size":"133.6"},{"price":"0.45","size":"133.5"},{"price":"0.46","size":"77.6"},{"price":"0.47","size":"47.5"},{"price":"0.48","size":"41.02"},{"price":"0.49","size":"71"},{"price":"0.5","size":"41"},{"price":"0.51","size":"61"},{"price":"0.52","size":"66"},{"price":"0.53","size":"64.15"},{"price":"0.54","size":"95"},{"price":"0.55","size":"25"},{"price":"0.57","size":"43.76"},{"price":"0.58","size":"90"},{"price":"0.59","size":"103.93"},{"price":"0.6","size":"50.57"}],"event_type":"book","hash":"6b486e71fd137e2349e74f71212e0909efffcdb4","market":"0xf9d60bb033695053c4d1d8592e52171c1042f64b41a4b72e09dcc6f4852b6670","timestamp":"1785121950082"},"payload_hash":"5bf9a5785080fc8d1d57e069fd879e9d6177d51362f0496319b6479a6cb8a008","raw_frame":"{\"market\":\"0xf9d60bb033695053c4d1d8592e52171c1042f64b41a4b72e09dcc6f4852b6670\", \"asset_id\":\"8698449539441374295770236407991735029336433231649246775082939325523552031992\", \"bids\":[{\"price\":\"0.01\", \"size\":\"7927.52\"}, {\"price\":\"0.02\", \"size\":\"1345.79\"}, {\"price\":\"0.03\", \"size\":\"1070.8\"}, {\"price\":\"0.04\", \"size\":\"1081.5\"}, {\"price\":\"0.05\", \"size\":\"987\"}, {\"price\":\"0.06\", \"size\":\"908.09\"}, {\"price\":\"0.07\", \"size\":\"456.2\"}, {\"price\":\"0.08\", \"size\":\"168.65\"}, {\"price\":\"0.09\", \"size\":\"343.1\"}, {\"price\":\"0.1\", \"size\":\"403.6\"}, {\"price\":\"0.11\", \"size\":\"120.29\"}, {\"price\":\"0.12\", \"size\":\"139.4\"}, {\"price\":\"0.13\", \"size\":\"133.9\"}, {\"price\":\"0.14\", \"size\":\"97.2\"}, {\"price\":\"0.15\", \"size\":\"116.39\"}, {\"price\":\"0.16\", \"size\":\"117.1\"}, {\"price\":\"0.17\", \"size\":\"104.29\"}, {\"price\":\"0.18\", \"size\":\"83.89\"}, {\"price\":\"0.19\", \"size\":\"106.19\"}, {\"price\":\"0.2\", \"size\":\"120.6\"}, {\"price\":\"0.21\", \"size\":\"71.3\"}, {\"price\":\"0.22\", \"size\":\"115.2\"}, {\"price\":\"0.23\", \"size\":\"71.3\"}, {\"price\":\"0.24\", \"size\":\"85.6\"}, {\"price\":\"0.25\", \"size\":\"93\"}, {\"price\":\"0.26\", \"size\":\"96.6\"}, {\"price\":\"0.27\", \"size\":\"59.3\"}, {\"price\":\"0.28\", \"size\":\"103\"}, {\"price\":\"0.29\", \"size\":\"56.88\"}, {\"price\":\"0.3\", \"size\":\"56\"}, {\"price\":\"0.31\", \"size\":\"99.1\"}, {\"price\":\"0.32\", \"size\":\"54.18\"}, {\"price\":\"0.33\", \"size\":\"53.5\"}, {\"price\":\"0.34\", \"size\":\"95.79\"}, {\"price\":\"0.35\", \"size\":\"51.1\"}, {\"price\":\"0.36\", \"size\":\"50.58\"}, {\"price\":\"0.37\", \"size\":\"80.1\"}, {\"price\":\"0.38\", \"size\":\"49.6\"}, {\"price\":\"0.39\", \"size\":\"49.09\"}, {\"price\":\"0.4\", \"size\":\"99.7\"}, {\"price\":\"0.41\", \"size\":\"150.3\"}, {\"price\":\"0.42\", \"size\":\"147.09\"}, {\"price\":\"0.43\", \"size\":\"164.8\"}, {\"price\":\"0.44\", \"size\":\"133.6\"}, {\"price\":\"0.45\", \"size\":\"133.5\"}, {\"price\":\"0.46\", \"size\":\"77.6\"}, {\"price\":\"0.47\", \"size\":\"47.5\"}, {\"price\":\"0.48\", \"size\":\"41.02\"}, {\"price\":\"0.49\", \"size\":\"71\"}, {\"price\":\"0.5\", \"size\":\"41\"}, {\"price\":\"0.51\", \"size\":\"61\"}, {\"price\":\"0.52\", \"size\":\"66\"}, {\"price\":\"0.53\", \"size\":\"64.15\"}, {\"price\":\"0.54\", \"size\":\"95\"}, {\"price\":\"0.55\", \"size\":\"25\"}, {\"price\":\"0.57\", \"size\":\"43.76\"}, {\"price\":\"0.58\", \"size\":\"90\"}, {\"price\":\"0.59\", \"size\":\"103.93\"}, {\"price\":\"0.6\", \"size\":\"50.57\"}], \"asks\":[{\"price\":\"0.99\", \"size\":\"8314.52\"}, {\"price\":\"0.98\", \"size\":\"1345.79\"}, {\"price\":\"0.97\", \"size\":\"1154.13\"}, {\"price\":\"0.96\", \"size\":\"973.5\"}, {\"price\":\"0.95\", \"size\":\"921\"}, {\"price\":\"0.94\", \"size\":\"716.09\"}, {\"price\":\"0.93\", \"size\":\"661.2\"}, {\"price\":\"0.92\", \"size\":\"642.59\"}, {\"price\":\"0.91\", \"size\":\"658.1\"}, {\"price\":\"0.9\", \"size\":\"130.6\"}, {\"price\":\"0.89\", \"size\":\"120.29\"}, {\"price\":\"0.88\", \"size\":\"141.4\"}, {\"price\":\"0.87\", \"size\":\"103.9\"}, {\"price\":\"0.86\", \"size\":\"97.2\"}, {\"price\":\"0.85\", \"size\":\"122.39\"}, {\"price\":\"0.84\", \"size\":\"92.1\"}, {\"price\":\"0.83\", \"size\":\"83.29\"}, {\"price\":\"0.82\", \"size\":\"109.1\"}, {\"price\":\"0.81\", \"size\":\"76.19\"}, {\"price\":\"0.8\", \"size\":\"78.6\"}, {\"price\":\"0.79\", \"size\":\"115.82\"}, {\"price\":\"0.78\", \"size\":\"82.28\"}, {\"price\":\"0.77\", \"size\":\"79.99\"}, {\"price\":\"0.76\", \"size\":\"182.97\"}, {\"price\":\"0.75\", \"size\":\"69.93\"}, {\"price\":\"0.74\", \"size\":\"165.6\"}, {\"price\":\"0.73\", \"size\":\"164.3\"}, {\"price\":\"0.72\", \"size\":\"93\"}, {\"price\":\"0.71\", \"size\":\"66.88\"}, {\"price\":\"0.7\", \"size\":\"223\"}, {\"price\":\"0.69\", \"size\":\"146.1\"}, {\"price\":\"0.68\", \"size\":\"120.88\"}, {\"price\":\"0.67\", \"size\":\"96.1\"}, {\"price\":\"0.66\", \"size\":\"38.39\"}, {\"price\":\"0.65\", \"size\":\"31.1\"}, {\"price\":\"0.64\", \"size\":\"60.89\"}, {\"price\":\"0.63\", \"size\":\"40.7\"}, {\"price\":\"0.62\", \"size\":\"39.6\"}, {\"price\":\"0.61\", \"size\":\"34.3\"}], \"hash\":\"6b486e71fd137e2349e74f71212e0909efffcdb4\", \"timestamp\":\"1785121950082\", \"event_type\":\"book\"}","received_at":"2026-07-27T03:12:29.988633Z","schema_version":"clob-market-ws.book.v1","sequence":null,"server_hash":"6b486e71fd137e2349e74f71212e0909efffcdb4","server_timestamp":"1785121950082","session_id":"ff6d21c8283948938400a32613abec2c","source":"clob_market_ws"},"received_at":"2026-07-27T03:12:29.988633Z","record_id":"98bf36bab7daf8babf1d924ef338e901ff2038603b08f8bcf087d3f2ed751146","schema_fingerprint":"dc2caa1c89c6a7426e2e07ff925910cd4d0a8a223a515d4092d91d6d127aacb6","schema_version":"edge-lab-recorder.raw.v1","sequence":null,"source":"clob_market_ws"}
{"event_at":"2026-07-27T03:12:30.082000Z","event_fingerprint":"802c40647dc64478d2ee72101330153588303d3f4cd26935f2e45bddb8f0bc43","payload":{"connection_id":"f95883f18d264834af91809e5f803e9f","event_at":"2026-07-27T03:12:30.082000Z","event_type":"book","frame_hash":"5e4206dd28f8d36504c16e43c61133b583f7ece497965fb1f7db981b0e065727","frame_index":0,"kind":"data","monotonic_ns":223933329130375,"payload":{"asks":[{"price":"0.99","size":"7927.52"},{"price":"0.98","size":"1345.79"},{"price":"0.97","size":"1070.8"},{"price":"0.96","size":"1081.5"},{"price":"0.95","size":"987"},{"price":"0.94","size":"908.09"},{"price":"0.93","size":"456.2"},{"price":"0.92","size":"168.65"},{"price":"0.91","size":"343.1"},{"price":"0.9","size":"403.6"},{"price":"0.89","size":"120.29"},{"price":"0.88","size":"139.4"},{"price":"0.87","size":"133.9"},{"price":"0.86","size":"97.2"},{"price":"0.85","size":"116.39"},{"price":"0.84","size":"117.1"},{"price":"0.83","size":"104.29"},{"price":"0.82","size":"83.89"},{"price":"0.81","size":"106.19"},{"price":"0.8","size":"120.6"},{"price":"0.79","size":"71.3"},{"price":"0.78","size":"115.2"},{"price":"0.77","size":"71.3"},{"price":"0.76","size":"85.6"},{"price":"0.75","size":"93"},{"price":"0.74","size":"96.6"},{"price":"0.73","size":"59.3"},{"price":"0.72","size":"103"},{"price":"0.71","size":"56.88"},{"price":"0.7","size":"56"},{"price":"0.69","size":"99.1"},{"price":"0.68","size":"54.18"},{"price":"0.67","size":"53.5"},{"price":"0.66","size":"95.79"},{"price":"0.65","size":"51.1"},{"price":"0.64","size":"50.58"},{"price":"0.63","size":"80.1"},{"price":"0.62","size":"49.6"},{"price":"0.61","size":"49.09"},{"price":"0.6","size":"99.7"},{"price":"0.59","size":"150.3"},{"price":"0.58","size":"147.09"},{"price":"0.57","size":"164.8"},{"price":"0.56","size":"133.6"},{"price":"0.55","size":"133.5"},{"price":"0.54","size":"77.6"},{"price":"0.53","size":"47.5"},{"price":"0.52","size":"41.02"},{"price":"0.51","size":"71"},{"price":"0.5","size":"41"},{"price":"0.49","size":"61"},{"price":"0.48","size":"66"},{"price":"0.47","size":"64.15"},{"price":"0.46","size":"95"},{"price":"0.45","size":"25"},{"price":"0.43","size":"43.76"},{"price":"0.42","size":"90"},{"price":"0.41","size":"103.93"},{"price":"0.4","size":"50.57"}],"asset_id":"96283536366176669581486355171583722558858323126916278856549586825357358273536","bids":[{"price":"0.01","size":"8314.52"},{"price":"0.02","size":"1345.79"},{"price":"0.03","size":"1154.13"},{"price":"0.04","size":"973.5"},{"price":"0.05","size":"921"},{"price":"0.06","size":"716.09"},{"price":"0.07","size":"661.2"},{"price":"0.08","size":"642.59"},{"price":"0.09","size":"658.1"},{"price":"0.1","size":"130.6"},{"price":"0.11","size":"120.29"},{"price":"0.12","size":"141.4"},{"price":"0.13","size":"103.9"},{"price":"0.14","size":"97.2"},{"price":"0.15","size":"122.39"},{"price":"0.16","size":"92.1"},{"price":"0.17","size":"83.29"},{"price":"0.18","size":"109.1"},{"price":"0.19","size":"76.19"},{"price":"0.2","size":"78.6"},{"price":"0.21","size":"115.82"},{"price":"0.22","size":"82.28"},{"price":"0.23","size":"79.99"},{"price":"0.24","size":"182.97"},{"price":"0.25","size":"69.93"},{"price":"0.26","size":"165.6"},{"price":"0.27","size":"164.3"},{"price":"0.28","size":"93"},{"price":"0.29","size":"66.88"},{"price":"0.3","size":"223"},{"price":"0.31","size":"146.1"},{"price":"0.32","size":"120.88"},{"price":"0.33","size":"96.1"},{"price":"0.34","size":"38.39"},{"price":"0.35","size":"31.1"},{"price":"0.36","size":"60.89"},{"price":"0.37","size":"40.7"},{"price":"0.38","size":"39.6"},{"price":"0.39","size":"34.3"}],"event_type":"book","hash":"567f4e8e317b7b07fec3c0fe31e20fd3e90efdad","market":"0xf9d60bb033695053c4d1d8592e52171c1042f64b41a4b72e09dcc6f4852b6670","timestamp":"1785121950082"},"payload_hash":"9bcc3f98fe9c09976c96665b0abb82c85893b599be941f67e366081bffbc06db","raw_frame":"{\"market\":\"0xf9d60bb033695053c4d1d8592e52171c1042f64b41a4b72e09dcc6f4852b6670\", \"asset_id\":\"96283536366176669581486355171583722558858323126916278856549586825357358273536\", \"bids\":[{\"price\":\"0.01\", \"size\":\"8314.52\"}, {\"price\":\"0.02\", \"size\":\"1345.79\"}, {\"price\":\"0.03\", \"size\":\"1154.13\"}, {\"price\":\"0.04\", \"size\":\"973.5\"}, {\"price\":\"0.05\", \"size\":\"921\"}, {\"price\":\"0.06\", \"size\":\"716.09\"}, {\"price\":\"0.07\", \"size\":\"661.2\"}, {\"price\":\"0.08\", \"size\":\"642.59\"}, {\"price\":\"0.09\", \"size\":\"658.1\"}, {\"price\":\"0.1\", \"size\":\"130.6\"}, {\"price\":\"0.11\", \"size\":\"120.29\"}, {\"price\":\"0.12\", \"size\":\"141.4\"}, {\"price\":\"0.13\", \"size\":\"103.9\"}, {\"price\":\"0.14\", \"size\":\"97.2\"}, {\"price\":\"0.15\", \"size\":\"122.39\"}, {\"price\":\"0.16\", \"size\":\"92.1\"}, {\"price\":\"0.17\", \"size\":\"83.29\"}, {\"price\":\"0.18\", \"size\":\"109.1\"}, {\"price\":\"0.19\", \"size\":\"76.19\"}, {\"price\":\"0.2\", \"size\":\"78.6\"}, {\"price\":\"0.21\", \"size\":\"115.82\"}, {\"price\":\"0.22\", \"size\":\"82.28\"}, {\"price\":\"0.23\", \"size\":\"79.99\"}, {\"price\":\"0.24\", \"size\":\"182.97\"}, {\"price\":\"0.25\", \"size\":\"69.93\"}, {\"price\":\"0.26\", \"size\":\"165.6\"}, {\"price\":\"0.27\", \"size\":\"164.3\"}, {\"price\":\"0.28\", \"size\":\"93\"}, {\"price\":\"0.29\", \"size\":\"66.88\"}, {\"price\":\"0.3\", \"size\":\"223\"}, {\"price\":\"0.31\", \"size\":\"146.1\"}, {\"price\":\"0.32\", \"size\":\"120.88\"}, {\"price\":\"0.33\", \"size\":\"96.1\"}, {\"price\":\"0.34\", \"size\":\"38.39\"}, {\"price\":\"0.35\", \"size\":\"31.1\"}, {\"price\":\"0.36\", \"size\":\"60.89\"}, {\"price\":\"0.37\", \"size\":\"40.7\"}, {\"price\":\"0.38\", \"size\":\"39.6\"}, {\"price\":\"0.39\", \"size\":\"34.3\"}], \"asks\":[{\"price\":\"0.99\", \"size\":\"7927.52\"}, {\"price\":\"0.98\", \"size\":\"1345.79\"}, {\"price\":\"0.97\", \"size\":\"1070.8\"}, {\"price\":\"0.96\", \"size\":\"1081.5\"}, {\"price\":\"0.95\", \"size\":\"987\"}, {\"price\":\"0.94\", \"size\":\"908.09\"}, {\"price\":\"0.93\", \"size\":\"456.2\"}, {\"price\":\"0.92\", \"size\":\"168.65\"}, {\"price\":\"0.91\", \"size\":\"343.1\"}, {\"price\":\"0.9\", \"size\":\"403.6\"}, {\"price\":\"0.89\", \"size\":\"120.29\"}, {\"price\":\"0.88\", \"size\":\"139.4\"}, {\"price\":\"0.87\", \"size\":\"133.9\"}, {\"price\":\"0.86\", \"size\":\"97.2\"}, {\"price\":\"0.85\", \"size\":\"116.39\"}, {\"price\":\"0.84\", \"size\":\"117.1\"}, {\"price\":\"0.83\", \"size\":\"104.29\"}, {\"price\":\"0.82\", \"size\":\"83.89\"}, {\"price\":\"0.81\", \"size\":\"106.19\"}, {\"price\":\"0.8\", \"size\":\"120.6\"}, {\"price\":\"0.79\", \"size\":\"71.3\"}, {\"price\":\"0.78\", \"size\":\"115.2\"}, {\"price\":\"0.77\", \"size\":\"71.3\"}, {\"price\":\"0.76\", \"size\":\"85.6\"}, {\"price\":\"0.75\", \"size\":\"93\"}, {\"price\":\"0.74\", \"size\":\"96.6\"}, {\"price\":\"0.73\", \"size\":\"59.3\"}, {\"price\":\"0.72\", \"size\":\"103\"}, {\"price\":\"0.71\", \"size\":\"56.88\"}, {\"price\":\"0.7\", \"size\":\"56\"}, {\"price\":\"0.69\", \"size\":\"99.1\"}, {\"price\":\"0.68\", \"size\":\"54.18\"}, {\"price\":\"0.67\", \"size\":\"53.5\"}, {\"price\":\"0.66\", \"size\":\"95.79\"}, {\"price\":\"0.65\", \"size\":\"51.1\"}, {\"price\":\"0.64\", \"size\":\"50.58\"}, {\"price\":\"0.63\", \"size\":\"80.1\"}, {\"price\":\"0.62\", \"size\":\"49.6\"}, {\"price\":\"0.61\", \"size\":\"49.09\"}, {\"price\":\"0.6\", \"size\":\"99.7\"}, {\"price\":\"0.59\", \"size\":\"150.3\"}, {\"price\":\"0.58\", \"size\":\"147.09\"}, {\"price\":\"0.57\", \"size\":\"164.8\"}, {\"price\":\"0.56\", \"size\":\"133.6\"}, {\"price\":\"0.55\", \"size\":\"133.5\"}, {\"price\":\"0.54\", \"size\":\"77.6\"}, {\"price\":\"0.53\", \"size\":\"47.5\"}, {\"price\":\"0.52\", \"size\":\"41.02\"}, {\"price\":\"0.51\", \"size\":\"71\"}, {\"price\":\"0.5\", \"size\":\"41\"}, {\"price\":\"0.49\", \"size\":\"61\"}, {\"price\":\"0.48\", \"size\":\"66\"}, {\"price\":\"0.47\", \"size\":\"64.15\"}, {\"price\":\"0.46\", \"size\":\"95\"}, {\"price\":\"0.45\", \"size\":\"25\"}, {\"price\":\"0.43\", \"size\":\"43.76\"}, {\"price\":\"0.42\", \"size\":\"90\"}, {\"price\":\"0.41\", \"size\":\"103.93\"}, {\"price\":\"0.4\", \"size\":\"50.57\"}], \"hash\":\"567f4e8e317b7b07fec3c0fe31e20fd3e90efdad\", \"timestamp\":\"1785121950082\", \"event_type\":\"book\"}","received_at":"2026-07-27T03:12:29.997571Z","schema_version":"clob-market-ws.book.v1","sequence":null,"server_hash":"567f4e8e317b7b07fec3c0fe31e20fd3e90efdad","server_timestamp":"1785121950082","session_id":"ff6d21c8283948938400a32613abec2c","source":"clob_market_ws"},"received_at":"2026-07-27T03:12:29.997571Z","record_id":"615f9f23f792694b6770aa61b09c2b769215c5a4dde942b1d1e7a82fd06b1e30","schema_fingerprint":"dc2caa1c89c6a7426e2e07ff925910cd4d0a8a223a515d4092d91d6d127aacb6","schema_version":"edge-lab-recorder.raw.v1","sequence":null,"source":"clob_market_ws"}
{"event_at":"2026-07-27T03:12:30.086000Z","event_fingerprint":"be8985311597b23acf234e982840d01645549db3793b9f7d1f4bf32ee114cbd0","payload":{"connection_id":"f95883f18d264834af91809e5f803e9f","event_at":"2026-07-27T03:12:30.086000Z","event_type":"price_change","frame_hash":"b0252f5f5081501e7b8cf8e6e7e66bb23125bb461b819efcc2697e6b303d85e8","frame_index":0,"kind":"data","monotonic_ns":223933335745666,"payload":{"event_type":"price_change","market":"0xf9d60bb033695053c4d1d8592e52171c1042f64b41a4b72e09dcc6f4852b6670","price_changes":[{"asset_id":"96283536366176669581486355171583722558858323126916278856549586825357358273536","best_ask":"0.4","best_bid":"0.39","hash":"3eedec2ed168e41605b8f990eb755d7ea1836c8a","price":"0.01","side":"BUY","size":"8309.52"},{"asset_id":"8698449539441374295770236407991735029336433231649246775082939325523552031992","best_ask":"0.61","best_bid":"0.6","hash":"d44d839ec125584ff1ec435f1827a26ddfcf9c6d","price":"0.99","side":"SELL","size":"8309.52"}],"timestamp":"1785121950086"},"payload_hash":"22829c029ffd4be2f1cf4f84884903e7b2bdbb2eb1dc4277488fbafa5dfe8efc","raw_frame":"{\"market\":\"0xf9d60bb033695053c4d1d8592e52171c1042f64b41a4b72e09dcc6f4852b6670\", \"price_changes\":[{\"asset_id\":\"96283536366176669581486355171583722558858323126916278856549586825357358273536\", \"price\":\"0.01\", \"size\":\"8309.52\", \"side\":\"BUY\", \"hash\":\"3eedec2ed168e41605b8f990eb755d7ea1836c8a\", \"best_bid\":\"0.39\", \"best_ask\":\"0.4\"}, {\"asset_id\":\"8698449539441374295770236407991735029336433231649246775082939325523552031992\", \"price\":\"0.99\", \"size\":\"8309.52\", \"side\":\"SELL\", \"hash\":\"d44d839ec125584ff1ec435f1827a26ddfcf9c6d\", \"best_bid\":\"0.6\", \"best_ask\":\"0.61\"}], \"timestamp\":\"1785121950086\", \"event_type\":\"price_change\"}","received_at":"2026-07-27T03:12:30.004181Z","schema_version":"clob-market-ws.price_change.v1","sequence":null,"server_hash":null,"server_timestamp":"1785121950086","session_id":"ff6d21c8283948938400a32613abec2c","source":"clob_market_ws"},"received_at":"2026-07-27T03:12:30.004181Z","record_id":"bdab2f79cf48f6f122eb7c6b0f1b7fc1ec55277e725d0a2aa9ff99c6a1e4919d","schema_fingerprint":"4aa3821a28b0b7c2400bc59aba4bcc0a76e971dadd19610d3ad38c768e124dc7","schema_version":"edge-lab-recorder.raw.v1","sequence":null,"source":"clob_market_ws"}
{"event_at":"2026-07-27T03:12:30.101000Z","event_fingerprint":"e21370914e2481521f5f70ef0bb3867dc225ef06d39f32f4c67267f585101197","payload":{"connection_id":"f95883f18d264834af91809e5f803e9f","event_at":"2026-07-27T03:12:30.101000Z","event_type":"price_change","frame_hash":"87f57438db5ef88a454f7b0bba5ec74baf222920164418bbaa1f819daf5089af","frame_index":0,"kind":"data","monotonic_ns":223933337388166,"payload":{"event_type":"price_change","market":"0xf9d60bb033695053c4d1d8592e52171c1042f64b41a4b72e09dcc6f4852b6670","price_changes":[{"asset_id":"8698449539441374295770236407991735029336433231649246775082939325523552031992","best_ask":"0.61","best_bid":"0.6","hash":"5fc80329cb5615122d36b80691decb0ee9a9b7d3","price":"0.58","side":"BUY","size":"85"},{"asset_id":"96283536366176669581486355171583722558858323126916278856549586825357358273536","best_ask":"0.4","best_bid":"0.39","hash":"bd882ee0879953bdfb0287ca1ccf6c7b94d05975","price":"0.42","side":"SELL","size":"85"}],"timestamp":"1785121950101"},"payload_hash":"f27cf6dba5101329495b7ef56153184d30de8e09cedab8135af569cfb9543793","raw_frame":"{\"market\":\"0xf9d60bb033695053c4d1d8592e52171c1042f64b41a4b72e09dcc6f4852b6670\", \"price_changes\":[{\"asset_id\":\"8698449539441374295770236407991735029336433231649246775082939325523552031992\", \"price\":\"0.58\", \"size\":\"85\", \"side\":\"BUY\", \"hash\":\"5fc80329cb5615122d36b80691decb0ee9a9b7d3\", \"best_bid\":\"0.6\", \"best_ask\":\"0.61\"}, {\"asset_id\":\"96283536366176669581486355171583722558858323126916278856549586825357358273536\", \"price\":\"0.42\", \"size\":\"85\", \"side\":\"SELL\", \"hash\":\"bd882ee0879953bdfb0287ca1ccf6c7b94d05975\", \"best_bid\":\"0.39\", \"best_ask\":\"0.4\"}], \"timestamp\":\"1785121950101\", \"event_type\":\"price_change\"}","received_at":"2026-07-27T03:12:30.005823Z","schema_version":"clob-market-ws.price_change.v1","sequence":null,"server_hash":null,"server_timestamp":"1785121950101","session_id":"ff6d21c8283948938400a32613abec2c","source":"clob_market_ws"},"received_at":"2026-07-27T03:12:30.005823Z","record_id":"8e9d285048cd48c2d05e67b321380863a1c813d93a2509f8b5f0dafda7101fe1","schema_fingerprint":"4aa3821a28b0b7c2400bc59aba4bcc0a76e971dadd19610d3ad38c768e124dc7","schema_version":"edge-lab-recorder.raw.v1","sequence":null,"source":"clob_market_ws"}
{"event_at":"2026-07-27T03:12:30.109000Z","event_fingerprint":"715bebe3dffb94ec1070c3897986f85a6c5d5ab5c1e8150fdfb88b5978343073","payload":{"connection_id":"f95883f18d264834af91809e5f803e9f","event_at":"2026-07-27T03:12:30.109000Z","event_type":"price_change","frame_hash":"832035a7e77dc0bbf16e657670b9b6804a236b6856ebba225c95519903002e72","frame_index":0,"kind":"data","monotonic_ns":223933340367791,"payload":{"event_type":"price_change","market":"0xf9d60bb033695053c4d1d8592e52171c1042f64b41a4b72e09dcc6f4852b6670","price_changes":[{"asset_id":"8698449539441374295770236407991735029336433231649246775082939325523552031992","best_ask":"0.61","best_bid":"0.6","hash":"1257f06369846c976d0f7d2213575ed7d77b4cac","price":"0.01","side":"BUY","size":"7922.52"},{"asset_id":"96283536366176669581486355171583722558858323126916278856549586825357358273536","best_ask":"0.4","best_bid":"0.39","hash":"2a54f0fedf6d19c9a4ea20b16af3c777e1cc05bc","price":"0.99","side":"SELL","size":"7922.52"}],"timestamp":"1785121950109"},"payload_hash":"f32f50112a40dc1d4164e4b1e29ecebaf3103ed3a1590a9a1e5e9a4ca4dd0650","raw_frame":"{\"market\":\"0xf9d60bb033695053c4d1d8592e52171c1042f64b41a4b72e09dcc6f4852b6670\", \"price_changes\":[{\"asset_id\":\"8698449539441374295770236407991735029336433231649246775082939325523552031992\", \"price\":\"0.01\", \"size\":\"7922.52\", \"side\":\"BUY\", \"hash\":\"1257f06369846c976d0f7d2213575ed7d77b4cac\", \"best_bid\":\"0.6\", \"best_ask\":\"0.61\"}, {\"asset_id\":\"96283536366176669581486355171583722558858323126916278856549586825357358273536\", \"price\":\"0.99\", \"size\":\"7922.52\", \"side\":\"SELL\", \"hash\":\"2a54f0fedf6d19c9a4ea20b16af3c777e1cc05bc\", \"best_bid\":\"0.39\", \"best_ask\":\"0.4\"}], \"timestamp\":\"1785121950109\", \"event_type\":\"price_change\"}","received_at":"2026-07-27T03:12:30.008806Z","schema_version":"clob-market-ws.price_change.v1","sequence":null,"server_hash":null,"server_timestamp":"1785121950109","session_id":"ff6d21c8283948938400a32613abec2c","source":"clob_market_ws"},"received_at":"2026-07-27T03:12:30.008806Z","record_id":"83a891efc0eda27eb0a31ab2c769c5a6778a31f1758c8741f9cc1428650565d0","schema_fingerprint":"4aa3821a28b0b7c2400bc59aba4bcc0a76e971dadd19610d3ad38c768e124dc7","schema_version":"edge-lab-recorder.raw.v1","sequence":null,"source":"clob_market_ws"}
{"event_at":"2026-07-27T03:12:30.111000Z","event_fingerprint":"06d4114b32cd185bc86c1c166a8761a0c92690c6f9982bd25c9f80d8807aed44","payload":{"connection_id":"f95883f18d264834af91809e5f803e9f","event_at":"2026-07-27T03:12:30.111000Z","event_type":"price_change","frame_hash":"f29af4b9e82083b3fd807449e3a92d15f36e51850c5c4f70fed3f6c16865b48f","frame_index":0,"kind":"data","monotonic_ns":223933343122333,"payload":{"event_type":"price_change","market":"0xf9d60bb033695053c4d1d8592e52171c1042f64b41a4b72e09dcc6f4852b6670","price_changes":[{"asset_id":"96283536366176669581486355171583722558858323126916278856549586825357358273536","best_ask":"0.4","best_bid":"0.39","hash":"4d78d5de7a802baa6e85335a6384b00fa62e02e1","price":"0.32","side":"BUY","size":"102.49"},{"asset_id":"8698449539441374295770236407991735029336433231649246775082939325523552031992","best_ask":"0.61","best_bid":"0.6","hash":"ddc6cfe1808ddd5202f69f3fdd0ef145a412a91d","price":"0.68","side":"SELL","size":"102.49"}],"timestamp":"1785121950111"},"payload_hash":"47948a3472849b931b81ba7ccb5b4afe230891765bcecc37e79db2b3bb69e2f0","raw_frame":"{\"market\":\"0xf9d60bb033695053c4d1d8592e52171c1042f64b41a4b72e09dcc6f4852b6670\", \"price_changes\":[{\"asset_id\":\"96283536366176669581486355171583722558858323126916278856549586825357358273536\", \"price\":\"0.32\", \"size\":\"102.49\", \"side\":\"BUY\", \"hash\":\"4d78d5de7a802baa6e85335a6384b00fa62e02e1\", \"best_bid\":\"0.39\", \"best_ask\":\"0.4\"}, {\"asset_id\":\"8698449539441374295770236407991735029336433231649246775082939325523552031992\", \"price\":\"0.68\", \"size\":\"102.49\", \"side\":\"SELL\", \"hash\":\"ddc6cfe1808ddd5202f69f3fdd0ef145a412a91d\", \"best_bid\":\"0.6\", \"best_ask\":\"0.61\"}], \"timestamp\":\"1785121950111\", \"event_type\":\"price_change\"}","received_at":"2026-07-27T03:12:30.011564Z","schema_version":"clob-market-ws.price_change.v1","sequence":null,"server_hash":null,"server_timestamp":"1785121950111","session_id":"ff6d21c8283948938400a32613abec2c","source":"clob_market_ws"},"received_at":"2026-07-27T03:12:30.011564Z","record_id":"1e7e2888d7aed1a8ddced8b5385747cc6130c201aa0cfcb93e658492c1c4a42f","schema_fingerprint":"4aa3821a28b0b7c2400bc59aba4bcc0a76e971dadd19610d3ad38c768e124dc7","schema_version":"edge-lab-recorder.raw.v1","sequence":null,"source":"clob_market_ws"}
{"event_at":"2026-07-27T03:12:30.129000Z","event_fingerprint":"80dbebdcc417c8ccb1cad467bea7d7b4c59cfbf174182b296e0c7b6cd4fa5666","payload":{"connection_id":"f95883f18d264834af91809e5f803e9f","event_at":"2026-07-27T03:12:30.129000Z","event_type":"price_change","frame_hash":"18c33d00b21bffc5a677c1e70d7d3203aa01e74c391c661ecbf311e6ae88ea42","frame_index":0,"kind":"data","monotonic_ns":223933360944500,"payload":{"event_type":"price_change","market":"0xf9d60bb033695053c4d1d8592e52171c1042f64b41a4b72e09dcc6f4852b6670","price_changes":[{"asset_id":"8698449539441374295770236407991735029336433231649246775082939325523552031992","best_ask":"0.61","best_bid":"0.6","hash":"2eee4cc199448b8c10e8c03e1795a9a9d4fbd921","price":"0.51","side":"BUY","size":"66"},{"asset_id":"96283536366176669581486355171583722558858323126916278856549586825357358273536","best_ask":"0.4","best_bid":"0.39","hash":"f1363620f1fa87cbcf48e0e505e0c9bb6ce551bc","price":"0.49","side":"SELL","size":"66"}],"timestamp":"1785121950129"},"payload_hash":"a488ec419876490fb9c3546f840015dbe5ce014e0dfaed6778556a784165fb81","raw_frame":"{\"market\":\"0xf9d60bb033695053c4d1d8592e52171c1042f64b41a4b72e09dcc6f4852b6670\", \"price_changes\":[{\"asset_id\":\"8698449539441374295770236407991735029336433231649246775082939325523552031992\", \"price\":\"0.51\", \"size\":\"66\", \"side\":\"BUY\", \"hash\":\"2eee4cc199448b8c10e8c03e1795a9a9d4fbd921\", \"best_bid\":\"0.6\", \"best_ask\":\"0.61\"}, {\"asset_id\":\"96283536366176669581486355171583722558858323126916278856549586825357358273536\", \"price\":\"0.49\", \"size\":\"66\", \"side\":\"SELL\", \"hash\":\"f1363620f1fa87cbcf48e0e505e0c9bb6ce551bc\", \"best_bid\":\"0.39\", \"best_ask\":\"0.4\"}], \"timestamp\":\"1785121950129\", \"event_type\":\"price_change\"}","received_at":"2026-07-27T03:12:30.029376Z","schema_version":"clob-market-ws.price_change.v1","sequence":null,"server_hash":null,"server_timestamp":"1785121950129","session_id":"ff6d21c8283948938400a32613abec2c","source":"clob_market_ws"},"received_at":"2026-07-27T03:12:30.029376Z","record_id":"442cfa5c640bf9f8b1ddaa85256728a83d6eaa5cacc929d80e3dd02573045e27","schema_fingerprint":"4aa3821a28b0b7c2400bc59aba4bcc0a76e971dadd19610d3ad38c768e124dc7","schema_version":"edge-lab-recorder.raw.v1","sequence":null,"source":"clob_market_ws"}
{"event_at":"2026-07-27T03:12:30.131000Z","event_fingerprint":"dba7acf0e3c1129d89ba65dd8a1c09fc25cc7f5df876e31287aea7145eac9966","payload":{"connection_id":"f95883f18d264834af91809e5f803e9f","event_at":"2026-07-27T03:12:30.131000Z","event_type":"price_change","frame_hash":"418f210c93f69c64cfda567ddf0f68a18105a4c4eaced3d94f340469cb31701a","frame_index":0,"kind":"data","monotonic_ns":223933364119500,"payload":{"event_type":"price_change","market":"0xf9d60bb033695053c4d1d8592e52171c1042f64b41a4b72e09dcc6f4852b6670","price_changes":[{"asset_id":"96283536366176669581486355171583722558858323126916278856549586825357358273536","best_ask":"0.4","best_bid":"0.39","hash":"0e7122a2d73624de512876575a302943cd471482","price":"0.31","side":"BUY","size":"71.1"},{"asset_id":"8698449539441374295770236407991735029336433231649246775082939325523552031992","best_ask":"0.61","best_bid":"0.6","hash":"32e0c75127819a30e9beb6bd6311da7f84c379fa","price":"0.69","side":"SELL","size":"71.1"}],"timestamp":"1785121950131"},"payload_hash":"aa72b82ba35fa970141d92d6b985bfaf5c2fbb1bbfb141b523394122996769b1","raw_frame":"{\"market\":\"0xf9d60bb033695053c4d1d8592e52171c1042f64b41a4b72e09dcc6f4852b6670\", \"price_changes\":[{\"asset_id\":\"96283536366176669581486355171583722558858323126916278856549586825357358273536\", \"price\":\"0.31\", \"size\":\"71.1\", \"side\":\"BUY\", \"hash\":\"0e7122a2d73624de512876575a302943cd471482\", \"best_bid\":\"0.39\", \"best_ask\":\"0.4\"}, {\"asset_id\":\"8698449539441374295770236407991735029336433231649246775082939325523552031992\", \"price\":\"0.69\", \"size\":\"71.1\", \"side\":\"SELL\", \"hash\":\"32e0c75127819a30e9beb6bd6311da7f84c379fa\", \"best_bid\":\"0.6\", \"best_ask\":\"0.61\"}], \"timestamp\":\"1785121950131\", \"event_type\":\"price_change\"}","received_at":"2026-07-27T03:12:30.032562Z","schema_version":"clob-market-ws.price_change.v1","sequence":null,"server_hash":null,"server_timestamp":"1785121950131","session_id":"ff6d21c8283948938400a32613abec2c","source":"clob_market_ws"},"received_at":"2026-07-27T03:12:30.032562Z","record_id":"e769e6ddeddc5b2f471a638d09836bc5fe2d8b959d2c5241c32aaf3e0be8bb8c","schema_fingerprint":"4aa3821a28b0b7c2400bc59aba4bcc0a76e971dadd19610d3ad38c768e124dc7","schema_version":"edge-lab-recorder.raw.v1","sequence":null,"source":"clob_market_ws"}
{"event_at":"2026-07-27T03:12:30.131000Z","event_fingerprint":"a8648d8315ea48f6cd8020fb25baff65e1b1f9ec4bc269b4e751f721eac55e2f","payload":{"connection_id":"f95883f18d264834af91809e5f803e9f","event_at":"2026-07-27T03:12:30.131000Z","event_type":"price_change","frame_hash":"0e0a9efd8f1c40b56d192f4435da3fc58564b109261f6f89ad4a49f74187f64a","frame_index":0,"kind":"data","monotonic_ns":223933364691875,"payload":{"event_type":"price_change","market":"0xf9d60bb033695053c4d1d8592e52171c1042f64b41a4b72e09dcc6f4852b6670","price_changes":[{"asset_id":"96283536366176669581486355171583722558858323126916278856549586825357358273536","best_ask":"0.4","best_bid":"0.39","hash":"0e7122a2d73624de512876575a302943cd471482","price":"0.3","side":"BUY","size":"148"},{"asset_id":"8698449539441374295770236407991735029336433231649246775082939325523552031992","best_ask":"0.61","best_bid":"0.6","hash":"32e0c75127819a30e9beb6bd6311da7f84c379fa","price":"0.7","side":"SELL","size":"148"}],"timestamp":"1785121950131"},"payload_hash":"ea5d30647325be0c391a8b7429da0cff7ca99e948cc496bc460472ed21a62319","raw_frame":"{\"market\":\"0xf9d60bb033695053c4d1d8592e52171c1042f64b41a4b72e09dcc6f4852b6670\", \"price_changes\":[{\"asset_id\":\"96283536366176669581486355171583722558858323126916278856549586825357358273536\", \"price\":\"0.3\", \"size\":\"148\", \"side\":\"BUY\", \"hash\":\"0e7122a2d73624de512876575a302943cd471482\", \"best_bid\":\"0.39\", \"best_ask\":\"0.4\"}, {\"asset_id\":\"8698449539441374295770236407991735029336433231649246775082939325523552031992\", \"price\":\"0.7\", \"size\":\"148\", \"side\":\"SELL\", \"hash\":\"32e0c75127819a30e9beb6bd6311da7f84c379fa\", \"best_bid\":\"0.6\", \"best_ask\":\"0.61\"}], \"timestamp\":\"1785121950131\", \"event_type\":\"price_change\"}","received_at":"2026-07-27T03:12:30.033135Z","schema_version":"clob-market-ws.price_change.v1","sequence":null,"server_hash":null,"server_timestamp":"1785121950131","session_id":"ff6d21c8283948938400a32613abec2c","source":"clob_market_ws"},"received_at":"2026-07-27T03:12:30.033135Z","record_id":"581eea58d0c6cc0ea32d1e9d646ac5e66f397e78cc8e298c4b4343695867b92e","schema_fingerprint":"4aa3821a28b0b7c2400bc59aba4bcc0a76e971dadd19610d3ad38c768e124dc7","schema_version":"edge-lab-recorder.raw.v1","sequence":null,"source":"clob_market_ws"}
{"event_at":"2026-07-27T03:12:30.132000Z","event_fingerprint":"9948fe59c30f6b1e5b9f6d6f48d22b667f987f77a35d77c2493c74b20ed1a552","payload":{"connection_id":"f95883f18d264834af91809e5f803e9f","event_at":"2026-07-27T03:12:30.132000Z","event_type":"price_change","frame_hash":"92a997552358f239967fe863057e8c90e77fc33e2c69bf985d67d238c1ea4fcf","frame_index":0,"kind":"data","monotonic_ns":223933365306875,"payload":{"event_type":"price_change","market":"0xf9d60bb033695053c4d1d8592e52171c1042f64b41a4b72e09dcc6f4852b6670","price_changes":[{"asset_id":"96283536366176669581486355171583722558858323126916278856549586825357358273536","best_ask":"0.4","best_bid":"0.39","hash":"8488936db3af629b103dc95bb47f49731be02fa5","price":"0.4","side":"SELL","size":"55.57"},{"asset_id":"8698449539441374295770236407991735029336433231649246775082939325523552031992","best_ask":"0.61","best_bid":"0.6","hash":"915a6003d6427a973af62be0ce7eb901f163a6a1","price":"0.6","side":"BUY","size":"55.57"}],"timestamp":"1785121950132"},"payload_hash":"7cbee8ab0f9a9d826ead39ccd32142e2fadcffcbfd7dc5ffe84ce2bda76e550e","raw_frame":"{\"market\":\"0xf9d60bb033695053c4d1d8592e52171c1042f64b41a4b72e09dcc6f4852b6670\", \"price_changes\":[{\"asset_id\":\"96283536366176669581486355171583722558858323126916278856549586825357358273536\", \"price\":\"0.4\", \"size\":\"55.57\", \"side\":\"SELL\", \"hash\":\"8488936db3af629b103dc95bb47f49731be02fa5\", \"best_bid\":\"0.39\", \"best_ask\":\"0.4\"}, {\"asset_id\":\"8698449539441374295770236407991735029336433231649246775082939325523552031992\", \"price\":\"0.6\", \"size\":\"55.57\", \"side\":\"BUY\", \"hash\":\"915a6003d6427a973af62be0ce7eb901f163a6a1\", \"best_bid\":\"0.6\", \"best_ask\":\"0.61\"}], \"timestamp\":\"1785121950132\", \"event_type\":\"price_change\"}","received_at":"2026-07-27T03:12:30.033743Z","schema_version":"clob-market-ws.price_change.v1","sequence":null,"server_hash":null,"server_timestamp":"1785121950132","session_id":"ff6d21c8283948938400a32613abec2c","source":"clob_market_ws"},"received_at":"2026-07-27T03:12:30.033743Z","record_id":"8623bd697a3feae64c617f57b91e3a4e50f5e8db4a8e933e836dc70d5dd057a5","schema_fingerprint":"4aa3821a28b0b7c2400bc59aba4bcc0a76e971dadd19610d3ad38c768e124dc7","schema_version":"edge-lab-recorder.raw.v1","sequence":null,"source":"clob_market_ws"}
{"event_at":"2026-07-27T03:12:30.180000Z","event_fingerprint":"b820a8a31150c82d09b7b1493da31233612d27591f3c2ef19e2cad67c47b95a1","payload":{"connection_id":"f95883f18d264834af91809e5f803e9f","event_at":"2026-07-27T03:12:30.180000Z","event_type":"price_change","frame_hash":"f08cebe0229d3c9d64b28761dd9f9efd1ec88f94b171d57271229612a56d15ef","frame_index":0,"kind":"data","monotonic_ns":223933411146000,"payload":{"event_type":"price_change","market":"0xf9d60bb033695053c4d1d8592e52171c1042f64b41a4b72e09dcc6f4852b6670","price_changes":[{"asset_id":"8698449539441374295770236407991735029336433231649246775082939325523552031992","best_ask":"0.61","best_bid":"0.6","hash":"eb5073fd1abeafb08ce0cd8edcdd7ac0ce372070","price":"0.01","side":"BUY","size":"7927.52"},{"asset_id":"96283536366176669581486355171583722558858323126916278856549586825357358273536","best_ask":"0.4","best_bid":"0.39","hash":"53ed46336a6504bdb06e15975bd2111f1153be20","price":"0.99","side":"SELL","size":"7927.52"}],"timestamp":"1785121950180"},"payload_hash":"c2cc669d5f0fb46936dc669c9d2329436ed343b156f25ee13e106ee5bbdec214","raw_frame":"{\"market\":\"0xf9d60bb033695053c4d1d8592e52171c1042f64b41a4b72e09dcc6f4852b6670\", \"price_changes\":[{\"asset_id\":\"8698449539441374295770236407991735029336433231649246775082939325523552031992\", \"price\":\"0.01\", \"size\":\"7927.52\", \"side\":\"BUY\", \"hash\":\"eb5073fd1abeafb08ce0cd8edcdd7ac0ce372070\", \"best_bid\":\"0.6\", \"best_ask\":\"0.61\"}, {\"asset_id\":\"96283536366176669581486355171583722558858323126916278856549586825357358273536\", \"price\":\"0.99\", \"size\":\"7927.52\", \"side\":\"SELL\", \"hash\":\"53ed46336a6504bdb06e15975bd2111f1153be20\", \"best_bid\":\"0.39\", \"best_ask\":\"0.4\"}], \"timestamp\":\"1785121950180\", \"event_type\":\"price_change\"}","received_at":"2026-07-27T03:12:30.079573Z","schema_version":"clob-market-ws.price_change.v1","sequence":null,"server_hash":null,"server_timestamp":"1785121950180","session_id":"ff6d21c8283948938400a32613abec2c","source":"clob_market_ws"},"received_at":"2026-07-27T03:12:30.079573Z","record_id":"6f26fc62d958b31211df1eb755adf1758ba17c8c6ab97fd1e03b0993d9b48338","schema_fingerprint":"4aa3821a28b0b7c2400bc59aba4bcc0a76e971dadd19610d3ad38c768e124dc7","schema_version":"edge-lab-recorder.raw.v1","sequence":null,"source":"clob_market_ws"}
{"event_at":"2026-07-27T03:12:30.190000Z","event_fingerprint":"5fdfb9f1a8c5a561b43ed63becd266bb1144445510ab65e6c5ef6af6f72bd9e8","payload":{"connection_id":"f95883f18d264834af91809e5f803e9f","event_at":"2026-07-27T03:12:30.190000Z","event_type":"price_change","frame_hash":"93f4cbd3675f417fb2af4895bb7e4cc90a6f7320e5d750fc749388163af51e29","frame_index":0,"kind":"data","monotonic_ns":223933423637458,"payload":{"event_type":"price_change","market":"0xf9d60bb033695053c4d1d8592e52171c1042f64b41a4b72e09dcc6f4852b6670","price_changes":[{"asset_id":"8698449539441374295770236407991735029336433231649246775082939325523552031992","best_ask":"0.61","best_bid":"0.6","hash":"9bdd073742b11ab75101b43838cb53a48003b7cc","price":"0.01","side":"BUY","size":"7932.52"},{"asset_id":"96283536366176669581486355171583722558858323126916278856549586825357358273536","best_ask":"0.4","best_bid":"0.39","hash":"7406d9cfa54436eddff2dc1b471bcf0d417cacb0","price":"0.99","side":"SELL","size":"7932.52"}],"timestamp":"1785121950190"},"payload_hash":"73b31a459bd118d2486f724f4090b93244fa1181b621969453654d26b1c5bfd0","raw_frame":"{\"market\":\"0xf9d60bb033695053c4d1d8592e52171c1042f64b41a4b72e09dcc6f4852b6670\", \"price_changes\":[{\"asset_id\":\"8698449539441374295770236407991735029336433231649246775082939325523552031992\", \"price\":\"0.01\", \"size\":\"7932.52\", \"side\":\"BUY\", \"hash\":\"9bdd073742b11ab75101b43838cb53a48003b7cc\", \"best_bid\":\"0.6\", \"best_ask\":\"0.61\"}, {\"asset_id\":\"96283536366176669581486355171583722558858323126916278856549586825357358273536\", \"price\":\"0.99\", \"size\":\"7932.52\", \"side\":\"SELL\", \"hash\":\"7406d9cfa54436eddff2dc1b471bcf0d417cacb0\", \"best_bid\":\"0.39\", \"best_ask\":\"0.4\"}], \"timestamp\":\"1785121950190\", \"event_type\":\"price_change\"}","received_at":"2026-07-27T03:12:30.092072Z","schema_version":"clob-market-ws.price_change.v1","sequence":null,"server_hash":null,"server_timestamp":"1785121950190","session_id":"ff6d21c8283948938400a32613abec2c","source":"clob_market_ws"},"received_at":"2026-07-27T03:12:30.092072Z","record_id":"3da861f50989aadc3aa1ac64477b6c822ddee18c3e658a911e9a1d64e8f05bed","schema_fingerprint":"4aa3821a28b0b7c2400bc59aba4bcc0a76e971dadd19610d3ad38c768e124dc7","schema_version":"edge-lab-recorder.raw.v1","sequence":null,"source":"clob_market_ws"}
{"event_at":"2026-07-27T03:12:30.193000Z","event_fingerprint":"3a95e899865b6661f3dc3f8f84222004bfa8f8dbdb4e70b564dcefe937fd2e65","payload":{"connection_id":"f95883f18d264834af91809e5f803e9f","event_at":"2026-07-27T03:12:30.193000Z","event_type":"price_change","frame_hash":"67098d995d857b8da2f1e903b4be086f12cbf1c01d2c90e5a407b12426e1fd16","frame_index":0,"kind":"data","monotonic_ns":223933425599125,"payload":{"event_type":"price_change","market":"0xf9d60bb033695053c4d1d8592e52171c1042f64b41a4b72e09dcc6f4852b6670","price_changes":[{"asset_id":"8698449539441374295770236407991735029336433231649246775082939325523552031992","best_ask":"0.61","best_bid":"0.6","hash":"48d3df5c4225a2ccab136a838ad6480015bfc9cc","price":"0.57","side":"BUY","size":"10.71"},{"asset_id":"96283536366176669581486355171583722558858323126916278856549586825357358273536","best_ask":"0.4","best_bid":"0.39","hash":"202a6ce1042f04f485ee276d7ff8461f532c5629","price":"0.43","side":"SELL","size":"10.71"}],"timestamp":"1785121950193"},"payload_hash":"883f582d390f72cdb3ce55804089a9775202a781f46d58a3928c43d3e534c89a","raw_frame":"{\"market\":\"0xf9d60bb033695053c4d1d8592e52171c1042f64b41a4b72e09dcc6f4852b6670\", \"price_changes\":[{\"asset_id\":\"8698449539441374295770236407991735029336433231649246775082939325523552031992\", \"price\":\"0.57\", \"size\":\"10.71\", \"side\":\"BUY\", \"hash\":\"48d3df5c4225a2ccab136a838ad6480015bfc9cc\", \"best_bid\":\"0.6\", \"best_ask\":\"0.61\"}, {\"asset_id\":\"96283536366176669581486355171583722558858323126916278856549586825357358273536\", \"price\":\"0.43\", \"size\":\"10.71\", \"side\":\"SELL\", \"hash\":\"202a6ce1042f04f485ee276d7ff8461f532c5629\", \"best_bid\":\"0.39\", \"best_ask\":\"0.4\"}], \"timestamp\":\"1785121950193\", \"event_type\":\"price_change\"}","received_at":"2026-07-27T03:12:30.094033Z","schema_version":"clob-market-ws.price_change.v1","sequence":null,"server_hash":null,"server_timestamp":"1785121950193","session_id":"ff6d21c8283948938400a32613abec2c","source":"clob_market_ws"},"received_at":"2026-07-27T03:12:30.094033Z","record_id":"1f20e302ac1c1599df962e2b7108224f796b20a17870867d044c89f541424055","schema_fingerprint":"4aa3821a28b0b7c2400bc59aba4bcc0a76e971dadd19610d3ad38c768e124dc7","schema_version":"edge-lab-recorder.raw.v1","sequence":null,"source":"clob_market_ws"}
{"event_at":"2026-07-27T03:12:30.193000Z","event_fingerprint":"d6120a7afc36146160dd9d1f83f70535da7dbdc57ea548b75087f306b82a2989","payload":{"connection_id":"f95883f18d264834af91809e5f803e9f","event_at":"2026-07-27T03:12:30.193000Z","event_type":"price_change","frame_hash":"4ca20b7d5311bb21c2b490079808631b118ce1c6d4b5333864b47b08b135c742","frame_index":0,"kind":"data","monotonic_ns":223933427302625,"payload":{"event_type":"price_change","market":"0xf9d60bb033695053c4d1d8592e52171c1042f64b41a4b72e09dcc6f4852b6670","price_changes":[{"asset_id":"96283536366176669581486355171583722558858323126916278856549586825357358273536","best_ask":"0.4","best_bid":"0.39","hash":"f814886e69fdcdf54f394f22e5d8dab0f698aeeb","price":"0.01","side":"BUY","size":"8006.52"},{"asset_id":"8698449539441374295770236407991735029336433231649246775082939325523552031992","best_ask":"0.61","best_bid":"0.6","hash":"b112a1530825ceedeed8afae5c5ee914016c57a0","price":"0.99","side":"SELL","size":"8006.52"}],"timestamp":"1785121950193"},"payload_hash":"26c8273ddd93545c37d8c4ececc0decc6f7efca416e24067de0962891462288d","raw_frame":"{\"market\":\"0xf9d60bb033695053c4d1d8592e52171c1042f64b41a4b72e09dcc6f4852b6670\", \"price_changes\":[{\"asset_id\":\"96283536366176669581486355171583722558858323126916278856549586825357358273536\", \"price\":\"0.01\", \"size\":\"8006.52\", \"side\":\"BUY\", \"hash\":\"f814886e69fdcdf54f394f22e5d8dab0f698aeeb\", \"best_bid\":\"0.39\", \"best_ask\":\"0.4\"}, {\"asset_id\":\"8698449539441374295770236407991735029336433231649246775082939325523552031992\", \"price\":\"0.99\", \"size\":\"8006.52\", \"side\":\"SELL\", \"hash\":\"b112a1530825ceedeed8afae5c5ee914016c57a0\", \"best_bid\":\"0.6\", \"best_ask\":\"0.61\"}], \"timestamp\":\"1785121950193\", \"event_type\":\"price_change\"}","received_at":"2026-07-27T03:12:30.095739Z","schema_version":"clob-market-ws.price_change.v1","sequence":null,"server_hash":null,"server_timestamp":"1785121950193","session_id":"ff6d21c8283948938400a32613abec2c","source":"clob_market_ws"},"received_at":"2026-07-27T03:12:30.095739Z","record_id":"d90361dab5ab3b40e3985c796578c9a3bea3f762b14cef9831f8f4dc78071aad","schema_fingerprint":"4aa3821a28b0b7c2400bc59aba4bcc0a76e971dadd19610d3ad38c768e124dc7","schema_version":"edge-lab-recorder.raw.v1","sequence":null,"source":"clob_market_ws"}
{"event_at":"2026-07-27T03:12:30.197000Z","event_fingerprint":"3f23626892c9a0308557dc7ae219a396565b185f81023e48dabab7e33dc8767f","payload":{"connection_id":"f95883f18d264834af91809e5f803e9f","event_at":"2026-07-27T03:12:30.197000Z","event_type":"price_change","frame_hash":"e11d228b26124b42a7588c3a2fbae29db9d48af28bcb5af9486220c0a9c06ddc","frame_index":0,"kind":"data","monotonic_ns":223933428948791,"payload":{"event_type":"price_change","market":"0xf9d60bb033695053c4d1d8592e52171c1042f64b41a4b72e09dcc6f4852b6670","price_changes":[{"asset_id":"8698449539441374295770236407991735029336433231649246775082939325523552031992","best_ask":"0.61","best_bid":"0.6","hash":"56723bc40758506c601289b0873114208e18f148","price":"0.56","side":"BUY","size":"34.05"},{"asset_id":"96283536366176669581486355171583722558858323126916278856549586825357358273536","best_ask":"0.4","best_bid":"0.39","hash":"1f290579d7746eaeefb3910bb35a533d455f7aca","price":"0.44","side":"SELL","size":"34.05"}],"timestamp":"1785121950197"},"payload_hash":"e835f73fe05c1c7add2b2f315f79344e3721623625101d741d06c24dc2f55527","raw_frame":"{\"market\":\"0xf9d60bb033695053c4d1d8592e52171c1042f64b41a4b72e09dcc6f4852b6670\", \"price_changes\":[{\"asset_id\":\"8698449539441374295770236407991735029336433231649246775082939325523552031992\", \"price\":\"0.56\", \"size\":\"34.05\", \"side\":\"BUY\", \"hash\":\"56723bc40758506c601289b0873114208e18f148\", \"best_bid\":\"0.6\", \"best_ask\":\"0.61\"}, {\"asset_id\":\"96283536366176669581486355171583722558858323126916278856549586825357358273536\", \"price\":\"0.44\", \"size\":\"34.05\", \"side\":\"SELL\", \"hash\":\"1f290579d7746eaeefb3910bb35a533d455f7aca\", \"best_bid\":\"0.39\", \"best_ask\":\"0.4\"}], \"timestamp\":\"1785121950197\", \"event_type\":\"price_change\"}","received_at":"2026-07-27T03:12:30.097391Z","schema_version":"clob-market-ws.price_change.v1","sequence":null,"server_hash":null,"server_timestamp":"1785121950197","session_id":"ff6d21c8283948938400a32613abec2c","source":"clob_market_ws"},"received_at":"2026-07-27T03:12:30.097391Z","record_id":"c463e9f425c84abb1b1ecee8d641df42334af462a8e019baca5f97c8d31c0012","schema_fingerprint":"4aa3821a28b0b7c2400bc59aba4bcc0a76e971dadd19610d3ad38c768e124dc7","schema_version":"edge-lab-recorder.raw.v1","sequence":null,"source":"clob_market_ws"}
{"event_at":"2026-07-27T03:12:30.204000Z","event_fingerprint":"49743efaa5eb07599909e405251aa0e97ac122a02e9bb40b1c6694e8fe08d56a","payload":{"connection_id":"f95883f18d264834af91809e5f803e9f","event_at":"2026-07-27T03:12:30.204000Z","event_type":"price_change","frame_hash":"ace038f28030d179dc6f275c5d767f56c19c3376c7dee5e64bb06a5bfc0ac534","frame_index":0,"kind":"data","monotonic_ns":223933435031166,"payload":{"event_type":"price_change","market":"0xf9d60bb033695053c4d1d8592e52171c1042f64b41a4b72e09dcc6f4852b6670","price_changes":[{"asset_id":"96283536366176669581486355171583722558858323126916278856549586825357358273536","best_ask":"0.4","best_bid":"0.39","hash":"8f3e7e81c7d59be6f8d30ef658110d4b65f867d1","price":"0.36","side":"BUY","size":"55.89"},{"asset_id":"8698449539441374295770236407991735029336433231649246775082939325523552031992","best_ask":"0.61","best_bid":"0.6","hash":"03ccdfba71837643a8438eea24f2ab2411697073","price":"0.64","side":"SELL","size":"55.89"}],"timestamp":"1785121950204"},"payload_hash":"9e6c7aaee627f3238f06125142904081a48f73c0236a0d188b9c3e1c1e4ce64c","raw_frame":"{\"market\":\"0xf9d60bb033695053c4d1d8592e52171c1042f64b41a4b72e09dcc6f4852b6670\", \"price_changes\":[{\"asset_id\":\"96283536366176669581486355171583722558858323126916278856549586825357358273536\", \"price\":\"0.36\", \"size\":\"55.89\", \"side\":\"BUY\", \"hash\":\"8f3e7e81c7d59be6f8d30ef658110d4b65f867d1\", \"best_bid\":\"0.39\", \"best_ask\":\"0.4\"}, {\"asset_id\":\"8698449539441374295770236407991735029336433231649246775082939325523552031992\", \"price\":\"0.64\", \"size\":\"55.89\", \"side\":\"SELL\", \"hash\":\"03ccdfba71837643a8438eea24f2ab2411697073\", \"best_bid\":\"0.6\", \"best_ask\":\"0.61\"}], \"timestamp\":\"1785121950204\", \"event_type\":\"price_change\"}","received_at":"2026-07-27T03:12:30.103460Z","schema_version":"clob-market-ws.price_change.v1","sequence":null,"server_hash":null,"server_timestamp":"1785121950204","session_id":"ff6d21c8283948938400a32613abec2c","source":"clob_market_ws"},"received_at":"2026-07-27T03:12:30.103460Z","record_id":"3b3ec608dc187fdb423cc54611b1ebd5857b9873cf385e96a61e48118eff11ce","schema_fingerprint":"4aa3821a28b0b7c2400bc59aba4bcc0a76e971dadd19610d3ad38c768e124dc7","schema_version":"edge-lab-recorder.raw.v1","sequence":null,"source":"clob_market_ws"}
{"event_at":"2026-07-27T03:12:30.204000Z","event_fingerprint":"c5a8f6e432d033b09920dcf603a481c41789caa82a8e8c258af378e2bdad3c41","payload":{"connection_id":"f95883f18d264834af91809e5f803e9f","event_at":"2026-07-27T03:12:30.204000Z","event_type":"price_change","frame_hash":"5db1fdb8fdc57c24aaf9ce7b3f2c7cfe4518e1aee0dab569da366641b7017162","frame_index":0,"kind":"data","monotonic_ns":223933436727541,"payload":{"event_type":"price_change","market":"0xf9d60bb033695053c4d1d8592e52171c1042f64b41a4b72e09dcc6f4852b6670","price_changes":[{"asset_id":"8698449539441374295770236407991735029336433231649246775082939325523552031992","best_ask":"0.61","best_bid":"0.6","hash":"03ccdfba71837643a8438eea24f2ab2411697073","price":"0.58","side":"BUY","size":"75"},{"asset_id":"96283536366176669581486355171583722558858323126916278856549586825357358273536","best_ask":"0.4","best_bid":"0.39","hash":"8f3e7e81c7d59be6f8d30ef658110d4b65f867d1","price":"0.42","side":"SELL","size":"75"}],"timestamp":"1785121950204"},"payload_hash":"b4c720274daf8c33fc4f6cda79e48add2bc87479c977fdf278dbd639d4c79a51","raw_frame":"{\"market\":\"0xf9d60bb033695053c4d1d8592e52171c1042f64b41a4b72e09dcc6f4852b6670\", \"price_changes\":[{\"asset_id\":\"8698449539441374295770236407991735029336433231649246775082939325523552031992\", \"price\":\"0.58\", \"size\":\"75\", \"side\":\"BUY\", \"hash\":\"03ccdfba71837643a8438eea24f2ab2411697073\", \"best_bid\":\"0.6\", \"best_ask\":\"0.61\"}, {\"asset_id\":\"96283536366176669581486355171583722558858323126916278856549586825357358273536\", \"price\":\"0.42\", \"size\":\"75\", \"side\":\"SELL\", \"hash\":\"8f3e7e81c7d59be6f8d30ef658110d4b65f867d1\", \"best_bid\":\"0.39\", \"best_ask\":\"0.4\"}], \"timestamp\":\"1785121950204\", \"event_type\":\"price_change\"}","received_at":"2026-07-27T03:12:30.105163Z","schema_version":"clob-market-ws.price_change.v1","sequence":null,"server_hash":null,"server_timestamp":"1785121950204","session_id":"ff6d21c8283948938400a32613abec2c","source":"clob_market_ws"},"received_at":"2026-07-27T03:12:30.105163Z","record_id":"ffb3b6e16aaaed6100dc82d420b1fb3aee0e3abd7ef4ae6a51ef89c3dabf65c1","schema_fingerprint":"4aa3821a28b0b7c2400bc59aba4bcc0a76e971dadd19610d3ad38c768e124dc7","schema_version":"edge-lab-recorder.raw.v1","sequence":null,"source":"clob_market_ws"}
{"event_at":"2026-07-27T03:12:30.205000Z","event_fingerprint":"ee88e26fd31fc0cb01f5d81fb83854ba42ccc13f583db4c76f3e764c5a98346e","payload":{"connection_id":"f95883f18d264834af91809e5f803e9f","event_at":"2026-07-27T03:12:30.205000Z","event_type":"price_change","frame_hash":"00dc2aadccf0e30c21e267a63a44973b5283903cdeee4261299a22a5c5b354f1","frame_index":0,"kind":"data","monotonic_ns":223933438402750,"payload":{"event_type":"price_change","market":"0xf9d60bb033695053c4d1d8592e52171c1042f64b41a4b72e09dcc6f4852b6670","price_changes":[{"asset_id":"8698449539441374295770236407991735029336433231649246775082939325523552031992","best_ask":"0.61","best_bid":"0.6","hash":"cc426d2427fccd868c7a831c669338dece220424","price":"0.01","side":"BUY","size":"7927.52"},{"asset_id":"96283536366176669581486355171583722558858323126916278856549586825357358273536","best_ask":"0.4","best_bid":"0.39","hash":"4ddd5e3856c95b35cd7b9e6fb61966840b43f5e2","price":"0.99","side":"SELL","size":"7927.52"}],"timestamp":"1785121950205"},"payload_hash":"c81f9b20f65bbd8467f9296bd005fd6bac44e4e4b56a4108053d1a937efde3a4","raw_frame":"{\"market\":\"0xf9d60bb033695053c4d1d8592e52171c1042f64b41a4b72e09dcc6f4852b6670\", \"price_changes\":[{\"asset_id\":\"8698449539441374295770236407991735029336433231649246775082939325523552031992\", \"price\":\"0.01\", \"size\":\"7927.52\", \"side\":\"BUY\", \"hash\":\"cc426d2427fccd868c7a831c669338dece220424\", \"best_bid\":\"0.6\", \"best_ask\":\"0.61\"}, {\"asset_id\":\"96283536366176669581486355171583722558858323126916278856549586825357358273536\", \"price\":\"0.99\", \"size\":\"7927.52\", \"side\":\"SELL\", \"hash\":\"4ddd5e3856c95b35cd7b9e6fb61966840b43f5e2\", \"best_bid\":\"0.39\", \"best_ask\":\"0.4\"}], \"timestamp\":\"1785121950205\", \"event_type\":\"price_change\"}","received_at":"2026-07-27T03:12:30.106838Z","schema_version":"clob-market-ws.price_change.v1","sequence":null,"server_hash":null,"server_timestamp":"1785121950205","session_id":"ff6d21c8283948938400a32613abec2c","source":"clob_market_ws"},"received_at":"2026-07-27T03:12:30.106838Z","record_id":"21cceed033dab01d4d3e36715d8e1e30fe291b751e34e25da72b13576ecaacef","schema_fingerprint":"4aa3821a28b0b7c2400bc59aba4bcc0a76e971dadd19610d3ad38c768e124dc7","schema_version":"edge-lab-recorder.raw.v1","sequence":null,"source":"clob_market_ws"}
{"event_at":"2026-07-27T03:12:30.204000Z","event_fingerprint":"db9798f7496b7e65d9307c9de589a97bd23596972fa32156b819f9949e8561d9","payload":{"connection_id":"f95883f18d264834af91809e5f803e9f","event_at":"2026-07-27T03:12:30.204000Z","event_type":"last_trade_price","frame_hash":"0593fb1bea9fb6c11ba61b80d76769b87c2a8b0938ecc3128a501290ce3db98e","frame_index":0,"kind":"data","monotonic_ns":223933440093166,"payload":{"asset_id":"8698449539441374295770236407991735029336433231649246775082939325523552031992","event_type":"last_trade_price","fee_rate_bps":"0","market":"0xf9d60bb033695053c4d1d8592e52171c1042f64b41a4b72e09dcc6f4852b6670","price":"0.61","side":"BUY","size":"8.7","timestamp":"1785121950204","transaction_hash":"0xebbbfdaff902ed8db0baf28b1af0dc1155aa4b2a4ae42cc2d3bb3685173b2a67"},"payload_hash":"6b40c058c7ba3844fb82033f3778ffb026f7894b76a52c0c80a3e3fc8e3dce82","raw_frame":"{\"market\":\"0xf9d60bb033695053c4d1d8592e52171c1042f64b41a4b72e09dcc6f4852b6670\", \"asset_id\":\"8698449539441374295770236407991735029336433231649246775082939325523552031992\", \"price\":\"0.61\", \"size\":\"8.7\", \"fee_rate_bps\":\"0\", \"side\":\"BUY\", \"timestamp\":\"1785121950204\", \"event_type\":\"last_trade_price\", \"transaction_hash\":\"0xebbbfdaff902ed8db0baf28b1af0dc1155aa4b2a4ae42cc2d3bb3685173b2a67\"}","received_at":"2026-07-27T03:12:30.108529Z","schema_version":"clob-market-ws.last_trade_price.v1","sequence":null,"server_hash":null,"server_timestamp":"1785121950204","session_id":"ff6d21c8283948938400a32613abec2c","source":"clob_market_ws"},"received_at":"2026-07-27T03:12:30.108529Z","record_id":"285d88be713e7c99979ca25a390ece5c95203b7f8921508631783acab92fb0dc","schema_fingerprint":"95ad9be75a4b695cd99991e12b2592bc7346f3f5388a82d0000ba65bc0d9fd0a","schema_version":"edge-lab-recorder.raw.v1","sequence":null,"source":"clob_market_ws"}
{"event_at":"2026-07-27T03:12:30.210000Z","event_fingerprint":"d8907198f3878c08184f9b06beb3c78d9f9ccf44d5f14e5569d53e9edd06440b","payload":{"connection_id":"f95883f18d264834af91809e5f803e9f","event_at":"2026-07-27T03:12:30.210000Z","event_type":"price_change","frame_hash":"b7ee7137513ca48672524f35873ed877b307bcbde03a452dff346ee6893dd17f","frame_index":0,"kind":"data","monotonic_ns":223933442611625,"payload":{"event_type":"price_change","market":"0xf9d60bb033695053c4d1d8592e52171c1042f64b41a4b72e09dcc6f4852b6670","price_changes":[{"asset_id":"8698449539441374295770236407991735029336433231649246775082939325523552031992","best_ask":"0.61","best_bid":"0.6","hash":"5968b3a2f087175886d9f25571c6490b40deb16e","price":"0.02","side":"BUY","size":"1350.79"},{"asset_id":"96283536366176669581486355171583722558858323126916278856549586825357358273536","best_ask":"0.4","best_bid":"0.39","hash":"3eca629e8ce1afdffe9c1c711463794d6accc0c3","price":"0.98","side":"SELL","size":"1350.79"}],"timestamp":"1785121950210"},"payload_hash":"1cbf813e6177b67030149a1a3febc1f77f9fe040c097e2310e0fb3f663ee6532","raw_frame":"{\"market\":\"0xf9d60bb033695053c4d1d8592e52171c1042f64b41a4b72e09dcc6f4852b6670\", \"price_changes\":[{\"asset_id\":\"8698449539441374295770236407991735029336433231649246775082939325523552031992\", \"price\":\"0.02\", \"size\":\"1350.79\", \"side\":\"BUY\", \"hash\":\"5968b3a2f087175886d9f25571c6490b40deb16e\", \"best_bid\":\"0.6\", \"best_ask\":\"0.61\"}, {\"asset_id\":\"96283536366176669581486355171583722558858323126916278856549586825357358273536\", \"price\":\"0.98\", \"size\":\"1350.79\", \"side\":\"SELL\", \"hash\":\"3eca629e8ce1afdffe9c1c711463794d6accc0c3\", \"best_bid\":\"0.39\", \"best_ask\":\"0.4\"}], \"timestamp\":\"1785121950210\", \"event_type\":\"price_change\"}","received_at":"2026-07-27T03:12:30.111046Z","schema_version":"clob-market-ws.price_change.v1","sequence":null,"server_hash":null,"server_timestamp":"1785121950210","session_id":"ff6d21c8283948938400a32613abec2c","source":"clob_market_ws"},"received_at":"2026-07-27T03:12:30.111046Z","record_id":"ec57fa83fe781aaf075fac9fca439e2bce399f40055a50508572d134ad122b65","schema_fingerprint":"4aa3821a28b0b7c2400bc59aba4bcc0a76e971dadd19610d3ad38c768e124dc7","schema_version":"edge-lab-recorder.raw.v1","sequence":null,"source":"clob_market_ws"}
{"event_at":"2026-07-27T03:12:30.211000Z","event_fingerprint":"76d703e8deb46a1ec3ce6da73744dc3acacb8ace375d49be6d815f87c87e60f1","payload":{"connection_id":"f95883f18d264834af91809e5f803e9f","event_at":"2026-07-27T03:12:30.211000Z","event_type":"price_change","frame_hash":"fd0e94b3de96e23565d184a5c8395ebb1fb9b4f3ec059149595a1fa439efc53f","frame_index":0,"kind":"data","monotonic_ns":223933444244708,"payload":{"event_type":"price_change","market":"0xf9d60bb033695053c4d1d8592e52171c1042f64b41a4b72e09dcc6f4852b6670","price_changes":[{"asset_id":"8698449539441374295770236407991735029336433231649246775082939325523552031992","best_ask":"0.61","best_bid":"0.6","hash":"cd139dbcd084fad140794f3aebe7ca78528083c8","price":"0.01","side":"BUY","size":"7922.52"},{"asset_id":"96283536366176669581486355171583722558858323126916278856549586825357358273536","best_ask":"0.4","best_bid":"0.39","hash":"d415224647725358e8230c0fb3cec81f084b9eed","price":"0.99","side":"SELL","size":"7922.52"}],"timestamp":"1785121950211"},"payload_hash":"bbbf70758c6fe923f3951902abb51b0096d5d390b5ed71283ea449d4e3f49057","raw_frame":"{\"market\":\"0xf9d60bb033695053c4d1d8592e52171c1042f64b41a4b72e09dcc6f4852b6670\", \"price_changes\":[{\"asset_id\":\"8698449539441374295770236407991735029336433231649246775082939325523552031992\", \"price\":\"0.01\", \"size\":\"7922.52\", \"side\":\"BUY\", \"hash\":\"cd139dbcd084fad140794f3aebe7ca78528083c8\", \"best_bid\":\"0.6\", \"best_ask\":\"0.61\"}, {\"asset_id\":\"96283536366176669581486355171583722558858323126916278856549586825357358273536\", \"price\":\"0.99\", \"size\":\"7922.52\", \"side\":\"SELL\", \"hash\":\"d415224647725358e8230c0fb3cec81f084b9eed\", \"best_bid\":\"0.39\", \"best_ask\":\"0.4\"}], \"timestamp\":\"1785121950211\", \"event_type\":\"price_change\"}","received_at":"2026-07-27T03:12:30.112687Z","schema_version":"clob-market-ws.price_change.v1","sequence":null,"server_hash":null,"server_timestamp":"1785121950211","session_id":"ff6d21c8283948938400a32613abec2c","source":"clob_market_ws"},"received_at":"2026-07-27T03:12:30.112687Z","record_id":"dce01feee4c618333d11c5123e0f529ecec7de952b0359248e9bc9b6e5c570ad","schema_fingerprint":"4aa3821a28b0b7c2400bc59aba4bcc0a76e971dadd19610d3ad38c768e124dc7","schema_version":"edge-lab-recorder.raw.v1","sequence":null,"source":"clob_market_ws"}
{"event_at":"2026-07-27T03:12:30.219000Z","event_fingerprint":"9be8c97a5b108d3ee8013ff06daf47ec7e309c752f14430e9366e7efdc72730a","payload":{"connection_id":"f95883f18d264834af91809e5f803e9f","event_at":"2026-07-27T03:12:30.219000Z","event_type":"price_change","frame_hash":"334e305300c3d55b521775f80f56e5d4cee649370e6d02561443bfc054e25a1e","frame_index":0,"kind":"data","monotonic_ns":223933451129208,"payload":{"event_type":"price_change","market":"0xf9d60bb033695053c4d1d8592e52171c1042f64b41a4b72e09dcc6f4852b6670","price_changes":[{"asset_id":"8698449539441374295770236407991735029336433231649246775082939325523552031992","best_ask":"0.61","best_bid":"0.6","hash":"6be94da74b641de0ee098f571045ee35968a7bf1","price":"0.56","side":"BUY","size":"0"},{"asset_id":"96283536366176669581486355171583722558858323126916278856549586825357358273536","best_ask":"0.4","best_bid":"0.39","hash":"a74dc5435973943b805a41c5a0f2d1eb44426aab","price":"0.44","side":"SELL","size":"0"}],"timestamp":"1785121950219"},"payload_hash":"78904662d07b4842c8ca3353bb52b13d9e669efd0b116a18977676e62dc9456a","raw_frame":"{\"market\":\"0xf9d60bb033695053c4d1d8592e52171c1042f64b41a4b72e09dcc6f4852b6670\", \"price_changes\":[{\"asset_id\":\"8698449539441374295770236407991735029336433231649246775082939325523552031992\", \"price\":\"0.56\", \"size\":\"0\", \"side\":\"BUY\", \"hash\":\"6be94da74b641de0ee098f571045ee35968a7bf1\", \"best_bid\":\"0.6\", \"best_ask\":\"0.61\"}, {\"asset_id\":\"96283536366176669581486355171583722558858323126916278856549586825357358273536\", \"price\":\"0.44\", \"size\":\"0\", \"side\":\"SELL\", \"hash\":\"a74dc5435973943b805a41c5a0f2d1eb44426aab\", \"best_bid\":\"0.39\", \"best_ask\":\"0.4\"}], \"timestamp\":\"1785121950219\", \"event_type\":\"price_change\"}","received_at":"2026-07-27T03:12:30.119559Z","schema_version":"clob-market-ws.price_change.v1","sequence":null,"server_hash":null,"server_timestamp":"1785121950219","session_id":"ff6d21c8283948938400a32613abec2c","source":"clob_market_ws"},"received_at":"2026-07-27T03:12:30.119559Z","record_id":"3e7d0c85a8f5647fe3587f55497a6dfe8f8492d4adb158c67215bcda9d1ac140","schema_fingerprint":"4aa3821a28b0b7c2400bc59aba4bcc0a76e971dadd19610d3ad38c768e124dc7","schema_version":"edge-lab-recorder.raw.v1","sequence":null,"source":"clob_market_ws"}
{"event_at":"2026-07-27T03:12:30.221000Z","event_fingerprint":"94128b5d8e81ce7de479722b9a00f724ca808ba9056aac9e9e0da73b2028f3fc","payload":{"connection_id":"f95883f18d264834af91809e5f803e9f","event_at":"2026-07-27T03:12:30.221000Z","event_type":"price_change","frame_hash":"8cccef7f24339028ab114b64e147dfda40de7d1abdef200b10660283565b47b9","frame_index":0,"kind":"data","monotonic_ns":223933452825625,"payload":{"event_type":"price_change","market":"0xf9d60bb033695053c4d1d8592e52171c1042f64b41a4b72e09dcc6f4852b6670","price_changes":[{"asset_id":"8698449539441374295770236407991735029336433231649246775082939325523552031992","best_ask":"0.61","best_bid":"0.6","hash":"cc3f99690fdc9dedfdf7ced302f87607de519ce0","price":"0.54","side":"BUY","size":"70"},{"asset_id":"96283536366176669581486355171583722558858323126916278856549586825357358273536","best_ask":"0.4","best_bid":"0.39","hash":"8d2dce35223d87489b0f7698360a7ee73408e49a","price":"0.46","side":"SELL","size":"70"}],"timestamp":"1785121950221"},"payload_hash":"0002d7c6a57e31c87d31762e30eaf7292f894523b85959e0f0eb3ed39a8919dc","raw_frame":"{\"market\":\"0xf9d60bb033695053c4d1d8592e52171c1042f64b41a4b72e09dcc6f4852b6670\", \"price_changes\":[{\"asset_id\":\"8698449539441374295770236407991735029336433231649246775082939325523552031992\", \"price\":\"0.54\", \"size\":\"70\", \"side\":\"BUY\", \"hash\":\"cc3f99690fdc9dedfdf7ced302f87607de519ce0\", \"best_bid\":\"0.6\", \"best_ask\":\"0.61\"}, {\"asset_id\":\"96283536366176669581486355171583722558858323126916278856549586825357358273536\", \"price\":\"0.46\", \"size\":\"70\", \"side\":\"SELL\", \"hash\":\"8d2dce35223d87489b0f7698360a7ee73408e49a\", \"best_bid\":\"0.39\", \"best_ask\":\"0.4\"}], \"timestamp\":\"1785121950221\", \"event_type\":\"price_change\"}","received_at":"2026-07-27T03:12:30.121265Z","schema_version":"clob-market-ws.price_change.v1","sequence":null,"server_hash":null,"server_timestamp":"1785121950221","session_id":"ff6d21c8283948938400a32613abec2c","source":"clob_market_ws"},"received_at":"2026-07-27T03:12:30.121265Z","record_id":"4610f734c9545e3928eaa1cf9aa028d63674693ba999e9ad4816f3fab90b185d","schema_fingerprint":"4aa3821a28b0b7c2400bc59aba4bcc0a76e971dadd19610d3ad38c768e124dc7","schema_version":"edge-lab-recorder.raw.v1","sequence":null,"source":"clob_market_ws"}
{"event_at":"2026-07-27T03:12:30.222000Z","event_fingerprint":"8cdff36b000662345ed3aa99444f2fa3cc73c81598ec098e0a19c184768c7140","payload":{"connection_id":"f95883f18d264834af91809e5f803e9f","event_at":"2026-07-27T03:12:30.222000Z","event_type":"price_change","frame_hash":"86e486668137494be470a644623f2a9f9a63a0043e7dd5b1fb495c7edef4c9f2","frame_index":0,"kind":"data","monotonic_ns":223933453791291,"payload":{"event_type":"price_change","market":"0xf9d60bb033695053c4d1d8592e52171c1042f64b41a4b72e09dcc6f4852b6670","price_changes":[{"asset_id":"96283536366176669581486355171583722558858323126916278856549586825357358273536","best_ask":"0.4","best_bid":"0.39","hash":"1f8a787d44408074c2c4fa0f136f6dcb590cf087","price":"0.39","side":"BUY","size":"23"},{"asset_id":"8698449539441374295770236407991735029336433231649246775082939325523552031992","best_ask":"0.61","best_bid":"0.6","hash":"06eab40437c293c8d6d5cb77a167a5e1b836913a","price":"0.61","side":"SELL","size":"23"}],"timestamp":"1785121950222"},"payload_hash":"9a4e7df78fcfcbfbabb67a90a2f271f803c9eeac8c67d1f70f359c875a926de8","raw_frame":"{\"market\":\"0xf9d60bb033695053c4d1d8592e52171c1042f64b41a4b72e09dcc6f4852b6670\", \"price_changes\":[{\"asset_id\":\"96283536366176669581486355171583722558858323126916278856549586825357358273536\", \"price\":\"0.39\", \"size\":\"23\", \"side\":\"BUY\", \"hash\":\"1f8a787d44408074c2c4fa0f136f6dcb590cf087\", \"best_bid\":\"0.39\", \"best_ask\":\"0.4\"}, {\"asset_id\":\"8698449539441374295770236407991735029336433231649246775082939325523552031992\", \"price\":\"0.61\", \"size\":\"23\", \"side\":\"SELL\", \"hash\":\"06eab40437c293c8d6d5cb77a167a5e1b836913a\", \"best_bid\":\"0.6\", \"best_ask\":\"0.61\"}], \"timestamp\":\"1785121950222\", \"event_type\":\"price_change\"}","received_at":"2026-07-27T03:12:30.122230Z","schema_version":"clob-market-ws.price_change.v1","sequence":null,"server_hash":null,"server_timestamp":"1785121950222","session_id":"ff6d21c8283948938400a32613abec2c","source":"clob_market_ws"},"received_at":"2026-07-27T03:12:30.122230Z","record_id":"6ebea754e81108cf34b16ba14b44a15d3b5fe6535ea007dd4345c7b423fbb70e","schema_fingerprint":"4aa3821a28b0b7c2400bc59aba4bcc0a76e971dadd19610d3ad38c768e124dc7","schema_version":"edge-lab-recorder.raw.v1","sequence":null,"source":"clob_market_ws"}
{"event_at":"2026-07-27T03:12:30.222000Z","event_fingerprint":"76fcab3b23bba7a918c369b1d58c96093205f0e4f67e31ab855f6e0e60a7bd0c","payload":{"connection_id":"f95883f18d264834af91809e5f803e9f","event_at":"2026-07-27T03:12:30.222000Z","event_type":"price_change","frame_hash":"5e9dc1e2362d0fa52195f335f294bca98c778e0f5d3257b7118fe2238a3f6f43","frame_index":0,"kind":"data","monotonic_ns":223933455139125,"payload":{"event_type":"price_change","market":"0xf9d60bb033695053c4d1d8592e52171c1042f64b41a4b72e09dcc6f4852b6670","price_changes":[{"asset_id":"8698449539441374295770236407991735029336433231649246775082939325523552031992","best_ask":"0.61","best_bid":"0.6","hash":"b33a15d14623d282130199c20892c31fc34385f7","price":"0.57","side":"BUY","size":"43.76"},{"asset_id":"96283536366176669581486355171583722558858323126916278856549586825357358273536","best_ask":"0.4","best_bid":"0.39","hash":"c23ec673124ed03b5b55ef85c0cce28a43185f5a","price":"0.43","side":"SELL","size":"43.76"}],"timestamp":"1785121950222"},"payload_hash":"1f861fae8b27f8866a1a9930040fc842a526b9441e1ca8baf6d26128ed0a368d","raw_frame":"{\"market\":\"0xf9d60bb033695053c4d1d8592e52171c1042f64b41a4b72e09dcc6f4852b6670\", \"price_changes\":[{\"asset_id\":\"8698449539441374295770236407991735029336433231649246775082939325523552031992\", \"price\":\"0.57\", \"size\":\"43.76\", \"side\":\"BUY\", \"hash\":\"b33a15d14623d282130199c20892c31fc34385f7\", \"best_bid\":\"0.6\", \"best_ask\":\"0.61\"}, {\"asset_id\":\"96283536366176669581486355171583722558858323126916278856549586825357358273536\", \"price\":\"0.43\", \"size\":\"43.76\", \"side\":\"SELL\", \"hash\":\"c23ec673124ed03b5b55ef85c0cce28a43185f5a\", \"best_bid\":\"0.39\", \"best_ask\":\"0.4\"}], \"timestamp\":\"1785121950222\", \"event_type\":\"price_change\"}","received_at":"2026-07-27T03:12:30.123578Z","schema_version":"clob-market-ws.price_change.v1","sequence":null,"server_hash":null,"server_timestamp":"1785121950222","session_id":"ff6d21c8283948938400a32613abec2c","source":"clob_market_ws"},"received_at":"2026-07-27T03:12:30.123578Z","record_id":"04aaa9c81ddf16694657b8aaccf0fe61427ae512562a1f8e49952b4c7102873b","schema_fingerprint":"4aa3821a28b0b7c2400bc59aba4bcc0a76e971dadd19610d3ad38c768e124dc7","schema_version":"edge-lab-recorder.raw.v1","sequence":null,"source":"clob_market_ws"}
